Workbook

Sheet VISN Totals
A1: Blood Gases and Cylinder Rentals
A3: Station | B3: Base | C3: OY1 | D3: OY2 | E3: OY3 | F3: OY4 | G3: Total
A4: 436 | B4: ='436'!I33 -> 0 | C4: ='436'!M33 -> 0 | D4: ='436'!Q33 -> 0 | E4: ='436'!U33 -> 0 | F4: ='436'!Y33 -> 0 | G4: =SUM(B4:F4) -> 0
A5: 442 | B5: ='442'!I28 -> 0 | C5: ='442'!M28 -> 0 | D5: ='442'!Q28 -> 0 | E5: ='442'!U28 -> 0 | F5: ='442'!Y28 -> 0 | G5: =SUM(B5:F5) -> 0
A6: 554 | B6: ='554'!I27 -> 0 | C6: ='554'!M27 -> 0 | D6: ='554'!Q27 -> 0 | E6: ='554'!U27 -> 0 | F6: ='554'!Y27 -> 0 | G6: =SUM(B6:F6) -> 0
A7: 623 - MUS | B7: ='623'!I25 -> 0 | C7: ='623'!M25 -> 0 | D7: ='623'!Q25 -> 0 | E7: ='623'!U25 -> 0 | F7: ='623'!Y25 -> 0 | G7: =SUM(B7:F7) -> 0
A8: 635 | B8: ='635'!I34 -> 0 | C8: ='635'!M34 -> 0 | D8: ='635'!Q34 -> 0 | E8: ='635'!U34 -> 0 | F8: ='635'!Y34 -> 0 | G8: =SUM(B8:F8) -> 0
A9: 660 | B9: ='660'!I70 -> 0 | C9: ='660'!M70 -> 0 | D9: ='660'!Q70 -> 0 | E9: ='660'!U70 -> 0 | F9: ='660'!Y70 -> 0 | G9: =SUM(B9:F9) -> 0
A10: 666 | B10: ='666'!I28 -> 0 | C10: ='666'!M28 -> 0 | D10: ='666'!Q28 -> 0 | E10: ='666'!U28 -> 0 | F10: ='666'!Y28 -> 0 | G10: =SUM(B10:F10) -> 0
A11: VISN 19 Total POP $ | B11: =SUM(B4:B10) -> 0 | C11: =SUM(C4:C10) -> 0 | D11: =SUM(D4:D10) -> 0 | E11: =SUM(E4:E10) -> 0 | F11: =SUM(F4:F10) -> 0 | G11: =SUM(G4:G10) -> 0
A12: VISN 19 Total Base + Option Years

Sheet 436
F1: BASE | J1: OY1 | N1: OY2 | R1: OY3 | V1: OY4
A2: DESCRIPTION | B2: SIZE | C2: Estimated Annual CONTRACTOR FURNISHED TANKS (C) | D2: Estimated Annual #VA FURNISHED TANKS (G) | E2: UNIT Cylinder or Each | F2: Estimated Fill Price | G2: Estimated Total Fill Price [(Column C + Column D) * Column F] | H2: Estimated Monthly Cylinder Rental Fee | I2: Estimated Total Cylinder Rental Fee [(Column C + Column D) * Column H] | J2: Estimated Fill Price | K2: Estimated Total Fill Price [(Column C + Column D) * Column J] | L2: Estimated Monthly Cylinder Rental Fee | M2: Estimated Total Cylinder Rental Fee [(Column C + Column D) * Column L] | N2: Estimated Fill Price | O2: Estimated Total Fill Price [(Column C + Column D) * Column N] | P2: Estimated Monthly Cylinder Rental Fee | Q2: Estimated Total Cylinder Rental Fee [(Column C + Column D) * Column P] | R2: Estimated Fill Price | S2: Estimated Total Fill Price [(Column C + Column D) * Column R] | T2: Estimated Monthly Cylinder Rental Fee | U2: Estimated Total Cylinder Rental Fee [(Column C + Column D) * Column T] | V2: Estimated Fill Price | W2: Estimated Total Fill Price [(Column C + Column D) * Column V] | X2: Estimated Monthly Cylinder Rental Fee | Y2: Estimated Total Cylinder Rental Fee [(Column C + Column D) * Column X]
A3: 25% Carbon Dioxide Balance Argon Industrial Shielding Gas Mixture | B3: 80 | C3: 4 | E3: CY
A4: 4% Carbon Dioxide, 16% O2, Balance N2 | B4: E | C4: 3 | E4: CY
A5: 5% CO2, 12%OX, BAL N2+OR-02 | B5: E | C5: 2 | E5: CY
A6: Acetylene | B6: #4 | C6: 2 | E6: CY
A7: Acetylene | B7: B | C7: 2 | E7: CY
A8: Acetylene | B8: MC | C8: 4 | E8: CY
A9: Air, Compressed | B9: K | C9: 20 | E9: CY
A10: Air, Compressed, CGA Type 1, Medical | B10: E | C10: 48 | E10: CY
A11: Argon | B11: K | C11: 2 | E11: CY
A12: Argon 4.8 High Purity | B12: K | C12: 2 | E12: CY
A13: Carbon Dioxide Industrial | B13: 50# | C13: 2 | E13: CY
A14: Carbon Dioxide, Medicinal, Grade A / CD USPE | B14: E | C14: 18 | E14: CY
A15: Carbon Dioxide, USP | B15: 50 lb | C15: 16 | E15: CY
A16: LD 0.3% CARBON MONOXIDE 0.3% (H) METHANE 21% OXYGEN BALANCE NITROGEN LUNG DIFFUSION CGA 500 | B16: 200 liters | C16: 12 | E16: CY
A17: Nitrogen Medical Grade | B17: 200 | C17: 8 | E17: CY
A18: Nitrogen NF Liq 180LT 22PSI | B18: 180 LT | C18: 8 | E18: CY
A19: Nitrogen UHP 300 | B19: 300 | C19: 12 | E19: CY
A20: Nitrous Oxide | B20: G | C20: 12 | E20: CY
A21: Oxygen Medical Grade Walkabout | B21: E | C21: 100 | E21: CY
A22: Oxygen w/ Built-In Regulator | B22: "E" 25CF | C22: 3800 | E22: CY
A23: Oxygen, Industrial | B23: K | C23: 16 | E23: CY
A24: Oxygen, Medical | B24: D | C24: 24 | E24: CY
A25: Oxygen, Medical | B25: H | C25: 26 | E25: CY
A26: Oxygen, Medical | B26: K | C26: 57 | E26: CY
A27: Annual Loss of Use Inventory | C27: 1 | E27: Each
A28: Loss of Use CLIN (Unpriced CLIN for LOU if needed) | C28: 1 | E28: YR
A29: Valve Replacement | C29: 12 | E29: Each
A30: Emergency | C30: 12 | E30: Each
A31: Hydrostatic Testing | C31: 12 | E31: Each
E32: Subtotals
E33: Total Fill + Total Rental
X34: Total Package (Base+Option Years)
W36: Month+I1:I294

Sheet 442
F1: BASE | J1: OY1 | N1: OY2 | R1: OY3 | V1: OY4
A2: DESCRIPTION | B2: SIZE | C2: Estimated Annual CONTRACTOR FURNISHED TANKS (C) | D2: Estimated Annual #VA FURNISHED TANKS (G) | E2: UNIT Cylinder or Each | F2: Estimated Fill Price | G2: Estimated Total Fill Price [(Column C + Column D) * Column F] | H2: Estimated Monthly Cylinder Rental Fee | I2: Estimated Total Cylinder Rental Fee [(Column C + Column D) * Column H] | J2: Estimated Fill Price | K2: Estimated Total Fill Price [(Column C + Column D) * Column J] | L2: Estimated Monthly Cylinder Rental Fee | M2: Estimated Total Cylinder Rental Fee [(Column C + Column D) * Column L] | N2: Estimated Fill Price | O2: Estimated Total Fill Price [(Column C + Column D) * Column N] | P2: Estimated Monthly Cylinder Rental Fee | Q2: Estimated Total Cylinder Rental Fee [(Column C + Column D) * Column P] | R2: Estimated Fill Price | S2: Estimated Total Fill Price [(Column C + Column D) * Column R] | T2: Estimated Monthly Cylinder Rental Fee | U2: Estimated Total Cylinder Rental Fee [(Column C + Column D) * Column T] | V2: Estimated Fill Price | W2: Estimated Total Fill Price [(Column C + Column D) * Column V] | X2: Estimated Monthly Cylinder Rental Fee | Y2: Estimated Total Cylinder Rental Fee [(Column C + Column D) * Column X]
A3: USP Carbon Dioxide, Size H 50# | B3: H | C3: 13 | E3: CY
A4: Argon UHP 35 CGA 580 | C4: 4 | E4: CY
A5: Carbon Dioxide, Medicinal, Grade A / CD USPE | B5: E | C5: 13 | E5: CY
A6: USP Carbon Dioxide, Aluminum(G), Size E 6,7 | B6: E | C6: 4 | E6: CY
A7: Compressed Air, 310 CF | B7: CF | C7: 2 | E7: CY
A8: Oxygen w/ Built-In Regulator | B8: "E" 25CF | C8: 6600 | E8: CY
A9: Lung Diffusion: 0.3% Carbon Monoxide, 0.3% Methane, 21% Oxygen, Balance Nitrogen | B9: H175 | C9: 2 | E9: CY
A10: Lung Diffusion: 0.3% Carbon Monoxide, 21% Oxygen, Balance NI | B10: E | C10: 1 | E10: CY
A11: PF 9% Helium/21% OX/Bal NI | B11: E | C11: 1 | E11: CY
A12: Liquid Nitrogen per 10 Liter | B12: 10L | D12: 6 | E12: L
A13: Nitrogen Medical, NF, Size #1 304CF | B13: 1 | C13: 12 | E13: CY
A14: CB 5% CD/12% OX/Bal I | B14: E | C14: 2 | E14: CY
A15: Nitrous Oxide/NS USP56 | B15: G | C15: 12 | E15: CY
A16: Nitrous Oxide Medical 6.7#, Size E USPEA (Aluminum) | B16: E | C16: 1 | E16: CY
A17: Oxygen Medical Grade, Size E | B17: E | C17: 48 | E17: CY
A18: Oxygen Medical Grade, Size H/200 | B18: H | C18: 1 | E18: CY
A19: Oxygen Medical Grade, Size T/300 | B19: T | C19: 7 | E19: CY
A20: Oxygen, Medical (TO2TE WITH BUILT IN REGULATOR) | B20: E | C20: 277 | E20: CY
A21: Walk-O2-Bout Oxygen, MRI Compatible, Aluminum | B21: E | C21: 708 | E21: CY
A22: Valve Replacement | C22: 12 | E22: Each
A23: Annual Loss of Use Inventory | C23: 1 | E23: Each
A24: Loss of Use CLIN (Unpriced CLIN for LOU if needed) | C24: 1 | E24: YR
A25: HYDROSTATIC TESTING OF GFE | C25: 12 | E25: Each
A26: EMERGENCY DELIVERY | C26: 4 | E26: Each
E27: Subtotals
E28: Total Fill + Total Rental
X29: Total Package (Base+Option Years)
W31: Month+I1:I294
A37: Lodging | B37: =6*(153+26) -> 1074
A38: Air | B38: 1000
A39: Rental Car | B39: =6*75 -> 450
A40: Mileage (Gas) | B40: =6*(0.58*15) -> 52.2
A41: Meals & Incidentals | B41: =6*79 -> 474
B42: =SUM(B37:B41) -> 3050.2

Sheet 554
F1: BASE | J1: OY1 | N1: OY2 | R1: OY3 | V1: OY4
A2: DESCRIPTION | B2: SIZE | C2: Estimated Annual CONTRACTOR FURNISHED TANKS (C) | D2: Estimated Annual #VA FURNISHED TANKS (G) | E2: UNIT Cylinder or Each | F2: Estimated Fill Price | G2: Estimated Total Fill Price [(Column C + Column D) * Column F] | H2: Estimated Monthly Cylinder Rental Fee | I2: Estimated Total Cylinder Rental Fee [(Column C + Column D) * Column H] | J2: Estimated Fill Price | K2: Estimated Total Fill Price [(Column C + Column D) * Column J] | L2: Estimated Monthly Cylinder Rental Fee | M2: Estimated Total Cylinder Rental Fee [(Column C + Column D) * Column L] | N2: Estimated Fill Price | O2: Estimated Total Fill Price [(Column C + Column D) * Column N] | P2: Estimated Monthly Cylinder Rental Fee | Q2: Estimated Total Cylinder Rental Fee [(Column C + Column D) * Column P] | R2: Estimated Fill Price | S2: Estimated Total Fill Price [(Column C + Column D) * Column R] | T2: Estimated Monthly Cylinder Rental Fee | U2: Estimated Total Cylinder Rental Fee [(Column C + Column D) * Column T] | V2: Estimated Fill Price | W2: Estimated Total Fill Price [(Column C + Column D) * Column V] | X2: Estimated Monthly Cylinder Rental Fee | Y2: Estimated Total Cylinder Rental Fee [(Column C + Column D) * Column X]
A3: 0.3% Carbon Monoxide, 10% Helium, 21% Oxygen, Balance Nitrogen | B3: K | C3: 6 | E3: CY
A4: 0.3% Carbon Monoxide, 21% Oxygen, 10% Helium, Balance Nitrogen | B4: H 224 | C4: 1 | E4: CY
A5: 100% Carbon Dioxide | B5: G 428 | C5: 100 | E5: CY
A6: Anaerobic Mix (5-10% CO2/5-10%H2/BAL N2-A #200 44 1C) | B6: 200 liters | C6: 12 | E6: CY
A7: Argon | B7: K | C7: 12 | E7: CY
A8: Argon 4.8 High Purity | B8: K | C8: 2 | E8: CY
A9: Argon 99.999% Purity | B9: G | C9: 12 | E9: CY
A10: Carbon Dioxide | B10: E | C10: 12 | E10: CY
A11: Carbon Dioxide, 50 lb | B11: H | C11: 120 | E11: CY
A12: Carbon Dioxide, USP | B12: 50 lb | C12: 120 | E12: CY
A13: Dry Ice | B13: lb | C13: 12635 | E13: Lbs
A14: Liquid Nitrogen | B14: 30 liter | C14: 349 | E14: L
A15: Lung Diffusion .3% CO, .3% CH4, 21% O2, Balance N2 | B15: H | C15: 12 | E15: CY
A16: Lung Diffusion .3% CO, .3% CH4, 21% O2, Balance N2 | B16: E | C16: 6
A17: Lung Diffusion: 0.3% Methane, 0.3% Carbon Monoxide, 21% Oxygen, Balance Nitrogen all mixed to Primary Standards | B17: K | C17: 12 | E17: CY
A18: Oxygen Medical | B18: E | C18: 152 | E18: CY
A19: Oxygen Medical Grade Walkabout | B19: E | C19: 17000 | E19: CY
A20: Oxygen w/ Built-In Regulator | B20: "E" 25CF | C20: 4100 | E20: CY
A21: Annual Loss of Use Inventory | E21: Each
A22: Loss of Use CLIN (Unpriced CLIN for LOU if needed) | C22: 1 | E22: YR
A23: Valve Replacement | C23: 12 | E23: Each
A24: HYDROSTATIC TESTING OF GFE | C24: 12 | E24: Each
A25: EMERGENCY DELIVERY | C25: 4 | E25: Each
E26: Subtotals
E27: Total Fill + Total Rental
X28: Total Package (Base+Option Years)
W30: Month+I1:I294

Sheet 623
F1: BASE | J1: OY1 | N1: OY2 | R1: OY3 | V1: OY4
A2: DESCRIPTION | B2: SIZE | C2: Estimated Annual #CONTRACTOR FURNISHED TANKS (C) | D2: Estimated Annual #VA FURNISHED TANKS (G) | E2: UNIT Cylinder or Each | F2: Estimated Fill Price | G2: Estimated Total Fill Price [(Column C + Column D) * Column F] | H2: Estimated Monthly Cylinder Rental Fee | I2: Estimated Total Cylinder Rental Fee [(Column C + Column D) * Column H] | J2: Estimated Fill Price | K2: Estimated Total Fill Price [(Column C + Column D) * Column J] | L2: Estimated Monthly Cylinder Rental Fee | M2: Estimated Total Cylinder Rental Fee [(Column C + Column D) * Column L] | N2: Estimated Fill Price | O2: Estimated Total Fill Price [(Column C + Column D) * Column N] | P2: Estimated Monthly Cylinder Rental Fee | Q2: Estimated Total Cylinder Rental Fee [(Column C + Column D) * Column P] | R2: Estimated Fill Price | S2: Estimated Total Fill Price [(Column C + Column D) * Column R] | T2: Estimated Monthly Cylinder Rental Fee | U2: Estimated Total Cylinder Rental Fee [(Column C + Column D) * Column T] | V2: Estimated Fill Price | W2: Estimated Total Fill Price [(Column C + Column D) * Column V] | X2: Estimated Monthly Cylinder Rental Fee | Y2: Estimated Total Cylinder Rental Fee [(Column C + Column D) * Column X]
A3: Argon, Industrial 40 CGA | B3: H | C3: 24 | E3: CY
A4: Carbon Dioxide | B4: E | C4: 96 | E4: CY
A5: Carbon Dioxide, USP | B5: 50 LB | C5: 50 | E5: CY
A6: Oxygen w/ Built-In Regulator MRI Tank | B6: E | C6: 15 | E6: CY
A7: Lung Diffusion: 0.3% Carbon Monoxide, 0.3% Methane, 21% Oxygen, Balance Nitrogen | B7: H175 | C7: 48 | E7: CY
A8: Liquid Nitrogen, Liquid 20L Dewar | B8: 20L | C8: 0 | D8: 175 | E8: L
A9: Liquid Nitrogen, Liquid 30L Dewar | B9: 30L | C9: 0 | D9: 30 | E9: L
A10: Nitrogen Medical, NF, Size #1 304CF | B10: 1 | C10: 60 | E10: CY
A11: Nitrogen Gaseous | B11: H | C11: 24
A12: Nitrous Oxide/NS USP56 | B12: G | C12: 24 | E12: CY
A13: Oxygen USP200 | B13: H | C13: 120 | E13: CY
A14: Oxygen USP (OX USPEA), Size E (Aluminum - Post Valve) | B14: 7 | C14: 75 | E14: CY
A15: Oxygen Medical Grade, Size H/200 | B15: H | C15: 12 | E15: CY
A16: Oxygen Medical Grade, Size T/300 | B16: T | C16: 12 | E16: CY
A17: Oxygen USP (OX USPEAWBDS), Size EA with Walk-O2-About Reg Integrated | B17: E | C17: 1900 | E17: CY
A18: Oxygen USP (OX USPEAWBPlus), Size EA with Walk-O2-About Reg Integrated | B18: E | C18: 5 | E18: CY
A19: Annual Loss of Use Inventory | C19: 1 | E19: Each
A20: Loss of Use CLIN (Unpriced CLIN for LOU if needed) | C20: 1 | E20: YR
A21: Valve Replacement | C21: 12 | E21: Each
A22: HYDROSTATIC TESTING OF GFE | C22: 12 | E22: Each
A23: EMERGENCY DELIVERY | C23: 4 | E23: Each
E24: Subtotals
E25: Total Fill + Total Rental
X26: Total Package (Base+Option Years)

Sheet 635
F1: BASE | J1: OY1 | N1: OY2 | R1: OY3 | V1: OY4
A2: DESCRIPTION | B2: SIZE | C2: Estimated Annual CONTRACTOR FURNISHED TANKS (C) | D2: Estimated Annual #VA FURNISHED TANKS (G) | E2: UNIT Cylinder or Each | F2: Estimated Fill Price | G2: Estimated Total Fill Price [(Column C + Column D) * Column F] | H2: Estimated Monthly Cylinder Rental Fee | I2: Estimated Total Cylinder Rental Fee [(Column C + Column D) * Column H] | J2: Estimated Fill Price | K2: Estimated Total Fill Price [(Column C + Column D) * Column J] | L2: Estimated Monthly Cylinder Rental Fee | M2: Estimated Total Cylinder Rental Fee [(Column C + Column D) * Column L] | N2: Estimated Fill Price | O2: Estimated Total Fill Price [(Column C + Column D) * Column N] | P2: Estimated Monthly Cylinder Rental Fee | Q2: Estimated Total Cylinder Rental Fee [(Column C + Column D) * Column P] | R2: Estimated Fill Price | S2: Estimated Total Fill Price [(Column C + Column D) * Column R] | T2: Estimated Monthly Cylinder Rental Fee | U2: Estimated Total Cylinder Rental Fee [(Column C + Column D) * Column T] | V2: Estimated Fill Price | W2: Estimated Total Fill Price [(Column C + Column D) * Column V] | X2: Estimated Monthly Cylinder Rental Fee | Y2: Estimated Total Cylinder Rental Fee [(Column C + Column D) * Column X]
A3: Air, Compressed, Medicinal Grade, Size E | B3: E | C3: 42 | E3: CYL
A4: Ar UHP 6KPSI 99.998% CGA 677 | B4: H | C4: 4 | E4: CYL
A5: Argon Prepurified 35 CGA 580 C/O | B5: 35 CU | C5: 3 | E5: CYL
A6: Argon (AR UHP300) UHP 300 | B6: 3 | C6: 5 | E6: CYL
A7: Argon Size D (UHP35) | B7: D | C7: 2 | E7: CYL
A8: Carbon Dioxide Industrial, Size 50# CGA320 | B8: 50# | C8: 41 | E8: CYL
A9: Carbon Dioxide, Medicinal, Grade A / CD USP50 | B9: G | C9: 33 | E9: CYL
A10: Carbon Dioxide, Medicinal, Grade A / CD USPE | B10: E | C10: 322 | E10: CYL
A11: Carbon Dioxide Medical Grade, Size 50LBS w/Siphno (CD USP50S) | B11: 50# | C11: 6 | E11: CYL
A12: Carbon Dioxide Industrial 50LBS Siphon CGA 320 | B12: E | C12: 9 | E12: CYL
A13: Helium Industrial 200 (HE 200) | B13: H | C13: 2 | E13: CYL
A14: Heliox Mix: 70% USP Helium, 30% USP Oxygen, Size 200 (Z02HE7012003041) | B14: 200 | C14: 4 | E14: CYL
A15: Heliox Mix: 20% Oxygen, 80% Helium, Size 200 (Z02HE8012003042) | B15: H | C15: 4 | E15: CYL
A16: LD 0.3% CARBON MONOXIDE 0.3% (H) METHANE 21% OXYGEN BALANCE NITROGEN LUNG DIFFUSION CGA 500 | B16: 200 liters | C16: 4 | E16: CYL
A17: Liquid Nitrogen (PSI-22) | B17: 160 Liters | C17: 2 | E17: CYL
A18: Liquid Nitrogen (PSI-22) | B18: 180 Liter | C18: 24 | E18: CYL
A19: (GFE) Liquid Nitrogen, Size 25 Liters (NI GMPDEWARFILL25L) | B19: 25L | C19: 16 | E19: CYL
A20: NITROGEN, GASEOUS NI NF200 | B20: H | C20: 65 | E20: CYL
A21: Nitrous Oxide USP, Size E (Steel) NS USPE | B21: E | C21: 28 | E21: CYL
A22: Oxygen USP, Size EA (Walk-O2-bout) / OX USPEAWBDS | B22: E | C22: 2373 | E22: CYL
A23: Oxygen USP, Size E (Walk-O2-About) w/Integrated Reg (OX USPEAWBPlus) | B23: E | C23: 200 | E23: CYL
A24: Oxygen USP 200, (OX USP200), Size H | B24: H | C24: 25 | E24: CYL
A25: Oxygen USP, Size E (Aluminum) OX USPEA | B25: E | C25: 15 | E25: CYL
A26: Oxygen USP, Size E (Steel) OX USPEA | B26: E | C26: 15 | E26: CYL
A27: Oxygen Industrial Grade, Size 300 | B27: 300 | C27: 15 | E27: CYL
A28: Annual Loss of Use Inventory | C28: 1 | E28: YR
A29: Loss of Use CLIN (Unpriced CLIN for LOU if needed) | C29: 1 | E29: YR
A30: Valve Replacement | C30: 12 | E30: Each
A31: HYDROSTATIC TESTING OF GFE | C31: 12 | E31: Each
A32: EMERGENCY DELIVERY | C32: 15 | E32: Each
E33: Subtotals
E34: Total Fill + Total Rental
X35: Total Package (Base+Option Years)
W37: Month+I1:I294

Sheet 660
F1: BASE | J1: OY1 | N1: OY2 | R1: OY3 | V1: OY4
A2: DESCRIPTION | B2: SIZE | C2: Estimated Annual CONTRACTOR FURNISHED TANKS (C) | D2: Estimated Annual #VA FURNISHED TANKS (G) | E2: UNIT Cylinder or Each | F2: Estimated Fill Price | G2: Estimated Total Fill Price [(Column C + Column D) * Column F] | H2: Estimated Monthly Cylinder Rental Fee | I2: Estimated Total Cylinder Rental Fee [(Column C + Column D) * Column H] | J2: Estimated Fill Price | K2: Estimated Total Fill Price [(Column C + Column D) * Column J] | L2: Estimated Monthly Cylinder Rental Fee | M2: Estimated Total Cylinder Rental Fee [(Column C + Column D) * Column L] | N2: Estimated Fill Price | O2: Estimated Total Fill Price [(Column C + Column D) * Column N] | P2: Estimated Monthly Cylinder Rental Fee | Q2: Estimated Total Cylinder Rental Fee [(Column C + Column D) * Column P] | R2: Estimated Fill Price | S2: Estimated Total Fill Price [(Column C + Column D) * Column R] | T2: Estimated Monthly Cylinder Rental Fee | U2: Estimated Total Cylinder Rental Fee [(Column C + Column D) * Column T] | V2: Estimated Fill Price | W2: Estimated Total Fill Price [(Column C + Column D) * Column V] | X2: Estimated Monthly Cylinder Rental Fee | Y2: Estimated Total Cylinder Rental Fee [(Column C + Column D) * Column X]
A3: (GFE) Liquid Nitrogen, Size 25 LTRS (NI GMPDEWARFILL25L) | B3: 25L | C3: 100 | E3: CY
A4: 5% C02/ 10%H2/ BAL N2-A,Size#200 44 1C ANAEROBIC FLAMMABLE (Z03NI9032000041) | B4: 200 | C4: 50 | E4: CY
A5: Air Compressed | B5: H | C5: 23 | E5: CY
A6: AIR USP (AIR USPE) Size E (Steel) | B6: E | C6: 20 | E6: CY
A7: Air USP EA CGA 950 C/O MRI | B7: E | C7: 3
A8: AIR USP, Size 200 (AI USP 200) | B8: 200 | C8: 200 | E8: CY
A9: AIR USP, Size 300 (AI USP 300) | B9: 300 | C9: 200 | E9: CY
A10: Argon UHP , Size 6K (AR UHP6K) | B10: 6K | C10: 20 | E10: CY
A11: Carbon Dioxide | B11: E | C11: 38
A12: Carbon Dioxide 50lbs Siphon CGA 320 | B12: H | C12: 16
A13: Carbon Dioxide USP (CD USP20), Size 20LB | B13: 20LB | C13: 100 | E13: CY
A14: Carbon Dioxide USP E CGA 940 | B14: E | C14: 135 | E14: CY
A15: Carbon Dioxide, Medicinal, Grade A | B15: 50 LB | C15: 12 | E15: CY
A16: Carbon Dioxide, Medicinal, Grade A | B16: H | C16: 22 | E16: CY
A17: Carbon Dioxide, Medicinal, Grade A / CD USPE | B17: E | C17: 126 | E17: CY
A18: CERTIFIED BLOOD GAS: 1%O2/ 5% CD/ BAL NI | B18: 200 | C18: 3 | E18: CY
A19: Comp Air Breathing 310 CF | B19: CF | C19: 17 | E19: CY
A20: Cyl Nitrogen Medical NF 80 CGA 580 | B20: Q | C20: 33
A21: Helium | B21: E | C21: 3 | E21: CY
A22: Helium USP, (HE USP200), Size 200 | B22: 200 | C22: 200 | E22: CY
A23: Helium USP, (HE USP200), Size E (Steel) | B23: E | C23: 50 | E23: CY
A24: Helium, 99.999% Purity 6000PSI | B24: 6K | C24: 1 | E24: CY
A25: Liquid Nitrogen | B25: 5 Liters | C25: 8 | E25: L
A26: Liquid Nitrogen (PSI-22) | B26: 180 Liter | C26: 28 | E26: L
A27: LIQUID NITROGEN Dewar | B27: 50L | C27: 33 | E27: L
A28: Liquid Nitrogen Medical Grade - 10L DEWAR | B28: 10 L | C28: 8 | E28: L
A29: Liquid Nitrogen per Liter | B29: L | D29: 6 | E29: L
A30: Liquid Nitrogen, Dewar Fill, 10 liters | B30: 10 L | C30: 1 | E30: L
A31: Liquid Nitrogen, Dewar Fill, 20 liters | B31: 20 L | C31: 64 | E31: L
A32: Liquid Nitrogen, Medical Grade, 180 liter, 350PSI | B32: 180 L | C32: 27 | E32: L
A33: Lung Diffusion 0.3% CO/ 0.5% NE/ 21% o2/ BAL NI, (Z04NI7852003012), Size 200 | B33: 200 | C33: 50 | E33: CY
A34: Lung Diffusion: 3% Carbon Monoxide, 3% Methane, 21% Oxygen, Balance Nitrogen | B34: H 175 | C34: 6 | E34: CY
A35: Nitrogen (NI 125), Size 125 | B35: 125 | C35: 20 | E35: CY
A36: Nitrogen Medical Grade | B36: 200 | C36: 18 | E36: CY
A37: Nitrogen NF (NI NF200LT22), Size 200-LT 22PSI | B37: 200LT | C37: 20 | E37: CY
A38: Nitrogen NF (NI NF300), Size 300 | B38: 300 | C38: 20 | E38: CY
A39: Nitrogen NF Liq 180LT 22PSI | B39: 180 LT | C39: 12 | E39: CY
A40: Nitrogen UHP 200 | B40: 200 | C40: 8 | E40: CY
...

Sheet 666
F1: BASE | J1: OY1 | N1: OY2 | R1: OY3 | V1: OY4
A2: DESCRIPTION | B2: SIZE | C2: Estimated Annual CONTRACTOR FURNISHED TANKS (C) | D2: Estimated Annual #VA FURNISHED TANKS (G) | E2: UNIT Cylinder or Each | F2: Estimated Fill Price | G2: Estimated Total Fill Price [(Column C + Column D) * Column F] | H2: Estimated Monthly Cylinder Rental Fee | I2: Estimated Total Cylinder Rental Fee [(Column C + Column D) * Column H] | J2: Estimated Fill Price | K2: Estimated Total Fill Price [(Column C + Column D) * Column J] | L2: Estimated Monthly Cylinder Rental Fee | M2: Estimated Total Cylinder Rental Fee [(Column C + Column D) * Column L] | N2: Estimated Fill Price | O2: Estimated Total Fill Price [(Column C + Column D) * Column N] | P2: Estimated Monthly Cylinder Rental Fee | Q2: Estimated Total Cylinder Rental Fee [(Column C + Column D) * Column P] | R2: Estimated Fill Price | S2: Estimated Total Fill Price [(Column C + Column D) * Column R] | T2: Estimated Monthly Cylinder Rental Fee | U2: Estimated Total Cylinder Rental Fee [(Column C + Column D) * Column T] | V2: Estimated Fill Price | W2: Estimated Total Fill Price[(Column C + Column D) * Column V] | X2: Estimated Monthly Cylinder Rental Fee | Y2: Estimated Total Cylinder Rental Fee [(Column C + Column D) * Column X]
A3: USP Carbon Dioxide, Size H 50# | B3: H | C3: 1 | D3: 12 | E3: CY
A4: Argon UHP 35 CGA 580 | C4: 4 | E4: CY
A5: Carbon Dioxide, Medicinal, Grade A / CD USPE | B5: E | C5: 13 | E5: CY
A6: USP Carbon Dioxide, Aluminum(G), Size E 6,7 | B6: E | C6: 4 | E6: CY
A7: Compressed Air, 310 CF | B7: CF | C7: 2 | E7: CY
A8: Oxygen w/ Built-In Regulator | B8: "E" 25CF | C8: 6600 | E8: CY
A9: Lung Diffusion: 0.3% Carbon Monoxide, 0.3% Methane, 21% Oxygen, Balance Nitrogen | B9: H175 | C9: 2 | E9: CY
A10: Lung Diffusion: 0.3% Carbon Monoxide, 21% Oxygen, Balance NI | B10: E | C10: 1 | E10: CY
A11: PF 9% Helium/21% OX/Bal NI | B11: E | C11: 1 | E11: CY
A12: Liquid Nitrogen per Liter | B12: LI | D12: 6 | E12: L
A13: Nitrogen Medical, NF, Size #1 304CF | B13: 1 | C13: 12 | E13: CY
A14: CB 5% CD/12% OX/Bal I | B14: E | C14: 2 | E14: CY
A15: Nitrous Oxide/NS USP56 | B15: G | C15: 12 | E15: CY
A16: Nitrous Oxide Medical 6.7#, Size E USPEA (Aluminum) | B16: E | C16: 1 | E16: CY
A17: Oxygen Medical Grade, Size E | B17: E | C17: 48 | E17: CY
A18: Oxygen Medical Grade, Size H/200 | B18: H | C18: 1 | E18: CY
A19: Oxygen Medical Grade, Size T/300 | B19: T | C19: 7 | E19: CY
A20: Oxygen, Medical (TO2TE WITH BUILT IN REGULATOR) | B20: E | C20: 277 | E20: CY
A21: Walk-O2-Bout Oxygen, MRI Compatible, Aluminum | B21: E | C21: 708 | E21: CY
A22: Valve Replacement | C22: 12 | E22: Each
A23: Annual Loss of Use Inventory | C23: 1 | E23: YR
A24: Loss of Use CLIN (Unpriced CLIN for LOU if needed) | C24: 1 | E24: YR
A25: HYDROSTATIC TESTING OF GFE | C25: 12 | E25: Each
A26: EMERGENCY DELIVERY | C26: 4 | E26: Each
E27: Subtotals
E28: Total Fill + Total Rental
X29: Total Package (Base+Option Years)
W31: Month+I1:I294

Sheet Types of Gas
A1: Type of Gas | B1: Size
A2: 0.3% Carbon Dioxide, 10% Helium, 21% Oxygen, Balance Nitrogen | B2: K
A3: 0.3% Carbon Monoxide, 21% Oxygen, 10% Helium, Balance Nitrogen | B3: H 224
A4: 100% Carbon Dioxide | B4: G 428
A5: 25% Carbon Dioxide Balance Argon Industrial Shielding Gas Mixture | B5: 80
A6: 4% Carbon Dioxide, 16% O2, Balance N2 | B6: E
A7: 5% CO2, 12%OX, BAL N2+OR-02 | B7: E
A8: Acetylene | B8: #4
A9: Acetylene | B9: B
A10: Acetylene | B10: MC
A11: Air Compressed | B11: H
A12: Air Compressed | B12: K
A13: Air Compressed, CGA Type 1, Medical | B13: E
A14: Air USP EA CGA 950 C/O MRI | B14: E
A15: Anaerobic Mix | B15: 200 L
A16: Ar UHP 6KPSI 99.998% CGA 677 | B16: H
A17: Argon | B17: K
... A20: Argon Prepurified 35 CGA 580 C/O | B20: 35 CU
A21: Argon UHP 35 CGA 580 | B21: 300
A22: Argon UHP GR 5.0 Size 6 | B22: 6K
A23: Argon, Industrial 40 CGA | B23: H
A24: Carbon Dioxide | B24: E
A25: Carbon Dioxide Industrial | B25: 50#
A26: Carbon Dioxide Industrial 50LBS Siphon CGA 320 | B26: E
A27: Carbon Dioxide Industrial CGA320 | B27: 50#
A28: Carbon Dioxide Medical Grade A | B28: 50 lb.
A29: Carbon Dioxide Medical Grade A | B29: G
A30: Carbon Dioxide Medical Grade A | B30: H
A31: Carbon Dioxide USP E CGA 940 | B31: E
A32: Carbon Dioxide, Medicinal, Grade A / CD USPE | B32: E
A33: CB 5% CD/12% OX/Bal I | B33: E
A34: CERTIFIED BLOOD GAS: 1%O2/5% CD/BAL NI | B34: 200
A35: Comp Air Breathing 310 CF | B35: CF
A36: Cyl Nitrogen Medical NF 80 CGA 580 | B36: Q
A37: Dry Ice | B37: lb
A38: Helium | B38: E
A39: Helium Industrial 200 | B39: H
A40: Helium, 99.999% Purity 6000PSI | B40: 6K
A41: Liquid Nitrogen (PSI-22) | B41: 180 L
A42: Liquid Nitrogen, Medical Grade | B42: L
...
