Workbook
Name AwardFee: #REF!
Name CLIN_Pd_SH: #REF!
Name Esc: #REF!
Name FY: #REF!
Name Indirect_Rates: #REF!
Name Labor_Category: #REF!
Name Location: #REF!
Name Prime_Sub?: #REF!
Name Type_of_Subk: #REF!
Name WBS_Description: #REF!
Name Work_Site: #REF!

Sheet Exhibit 1A-1
B2: Proposing Entity:
B3: Offeror Name [ ] Prime ________________________________________________________
B4: EXHIBIT 1A [PRIME OFFEROR]
E5: Composite IDIQ Rate Development by Year
G7: Prime Only
B8: Identify Prime Offeror Loadings Applied to Subcontractor FBL Rates: e.g. G&A, handling, profit
B9: Prime Offeror Load (burdens) on Subcontractors | I9: Note: The Offeror shall provide a fully burdened labor rate for each labor category.
F10: meta
B11: NOTE: This percentage should be consistent with what is provided in Tab B and Tab I | O11: =B12 -> Contract Year 1
B12: Contract Year 1 | D12: Prime Offeror | F12: Subcontractor (Dummy sub1) | I12: Subcontractor (Dummy 2) | L12: Subcontractor (Insert Name) | O12: TOTAL COMPOSITE
D13: Prime FBL Rate* | E13: Percent of Effort | F13: Sub 1 FBL Rate | G13: Sub FBL Rate with Prime Load | H13: Percent of Effort | I13: Sub 2 FBL Rate | J13: Sub FBL Rate with Prime Load | K13: Percent of Effort | L13: Sub 3 FBL Rate | M13: Sub FBL Rate with Prime Load | N13: Percent of Effort | O13: Composite IDIQ FBL Rate | P13: Percent of Effort | Q13: Total Hours | R13: Total Direct Labor Costs
B14: Example | D14: 39.67 | E14: 0.5 | F14: 42 | G14: =F14*(1+$D$9) -> 42 | H14: 0.5 | I14: 45 | J14: =I14*(1+$D$9) -> 45 | L14: 38 | M14: =L14*(1+$D$9) -> 38 | O14: =(D14*E14)+(G14*H14)+(J14*K14)+(M14*N14) -> 40.835 | P14: =N14+K14+H14+E14 -> 1 | Q14: 1920 | R14: =O14*Q14 -> 78403.2
B15: GSFC (Goddard Space Flight Center) / HQ (Headquarters) | C15: GSFC/HQ
B16: LOW ACCOUNTING SPECIALIST | C16: GSFC/HQ | E16: 1 | G16: =F16*(1+$D$9) -> 0 | J16: =I16*(1+$D$9) -> 0 | M16: =L16*(1+$D$9) -> 0 | O16: =(D16*E16)+(G16*H16)+(J16*K16)+(M16*N16) -> 0 | P16: =N16+K16+H16+E16 -> 1 | Q16: 1878 | R16: =O16*Q16 -> 0
B17: SENIOR 1 ACCOUNTING SPECIALIST | C17: GSFC/HQ | E17: 1 | G17: =F17*(1+$D$9) -> 0 | J17: =I17*(1+$D$9) -> 0 | M17: =L17*(1+$D$9) -> 0 | O17: =(D17*E17)+(G17*H17)+(J17*K17)+(M17*N17) -> 0 | P17: =N17+K17+H17+E17 -> 1 | Q17: 1878 | R17: =O17*Q17 -> 0
B18: SENIOR 2 ACCOUNTING SPECIALIST | C18: GSFC/HQ | E18: 1 | G18: =F18*(1+$D$9) -> 0 | J18: =I18*(1+$D$9) -> 0 | M18: =L18*(1+$D$9) -> 0 | O18: =(D18*E18)+(G18*H18)+(J18*K18)+(M18*N18) -> 0 | P18: =N18+K18+H18+E18 -> 1 | Q18: 3756 | R18: =O18*Q18 -> 0
B19: INTERMEDIATE CM SPECIALIST | C19: GSFC/HQ | E19: 1 | G19: =F19*(1+$D$9) -> 0 | J19: =I19*(1+$D$9) -> 0 | M19: =L19*(1+$D$9) -> 0 | O19: =(D19*E19)+(G19*H19)+(J19*K19)+(M19*N19) -> 0 | P19: =N19+K19+H19+E19 -> 1 | Q19: 28170 | R19: =O19*Q19 -> 0
B20: HIGH CM SPECIALIST | C20: GSFC/HQ | E20: 1 | G20: =F20*(1+$D$9) -> 0 | J20: =I20*(1+$D$9) -> 0 | M20: =L20*(1+$D$9) -> 0 | O20: =(D20*E20)+(G20*H20)+(J20*K20)+(M20*N20) -> 0 | P20: =N20+K20+H20+E20 -> 1 | Q20: 16902 | R20: =O20*Q20 -> 0
B21: SENIOR 1 CM SPECIALIST | C21: GSFC/HQ | E21: 1 | G21: =F21*(1+$D$9) -> 0 | J21: =I21*(1+$D$9) -> 0 | M21: =L21*(1+$D$9) -> 0 | O21: =(D21*E21)+(G21*H21)+(J21*K21)+(M21*N21) -> 0 | P21: =N21+K21+H21+E21 -> 1 | Q21: 13146 | R21: =O21*Q21 -> 0
B22: SENIOR 2 CM SPECIALIST | C22: GSFC/HQ | E22: 1 | G22: =F22*(1+$D$9) -> 0 | J22: =I22*(1+$D$9) -> 0 | M22: =L22*(1+$D$9) -> 0 | O22: =(D22*E22)+(G22*H22)+(J22*K22)+(M22*N22) -> 0 | P22: =N22+K22+H22+E22 -> 1 | Q22: 7512 | R22: =O22*Q22 -> 0
B23: SENIOR 3 CM SPECIALIST | C23: GSFC/HQ | E23: 1 | G23: =F23*(1+$D$9) -> 0 | J23: =I23*(1+$D$9) -> 0 | M23: =L23*(1+$D$9) -> 0 | O23: =(D23*E23)+(G23*H23)+(J23*K23)+(M23*N23) -> 0 | P23: =N23+K23+H23+E23 -> 1 | Q23: 31926 | R23: =O23*Q23 -> 0
B24: INTERMEDIATE DOCUMENTATION SPECIALIST | C24: GSFC/HQ | E24: 1 | G24: =F24*(1+$D$9) -> 0 | J24: =I24*(1+$D$9) -> 0 | M24: =L24*(1+$D$9) -> 0 | O24: =(D24*E24)+(G24*H24)+(J24*K24)+(M24*N24) -> 0 | P24: =N24+K24+H24+E24 -> 1 | Q24: 3756 | R24: =O24*Q24 -> 0
B25: HIGH DOCUMENTATION SPECIALIST | C25: GSFC/HQ | E25: 1 | G25: =F25*(1+$D$9) -> 0 | J25: =I25*(1+$D$9) -> 0 | M25: =L25*(1+$D$9) -> 0 | O25: =(D25*E25)+(G25*H25)+(J25*K25)+(M25*N25) -> 0 | P25: =N25+K25+H25+E25 -> 1 | Q25: 1878 | R25: =O25*Q25 -> 0
B26: SENIOR 1 DOCUMENTAION SPECIALIST | C26: GSFC/HQ | E26: 1 | G26: =F26*(1+$D$9) -> 0 | J26: =I26*(1+$D$9) -> 0 | M26: =L26*(1+$D$9) -> 0 | O26: =(D26*E26)+(G26*H26)+(J26*K26)+(M26*N26) -> 0 | P26: =N26+K26+H26+E26 -> 1 | Q26: 9390 | R26: =O26*Q26 -> 0
B27: SENIOR 2 DOCUMENTATION SPECIALIST | C27: GSFC/HQ | E27: 1 | G27: =F27*(1+$D$9) -> 0 | J27: =I27*(1+$D$9) -> 0 | M27: =L27*(1+$D$9) -> 0 | O27: =(D27*E27)+(G27*H27)+(J27*K27)+(M27*N27) -> 0 | P27: =N27+K27+H27+E27 -> 1 | Q27: 7512 | R27: =O27*Q27 -> 0
... B60: ASSOCIATE II | C60: GSFC/HQ | E60: 1 | G60: =F60*(1+$D$9) -> 0 | J60: =I60*(1+$D$9) -> 0 | M60: =L60*(1+$D$9) -> 0 | O60: =(D60*E60)+(G60*H60)+(J60*K60)+(M60*N60) -> 0 | P60: =N60+K60+H60+E60 -> 1 | Q60: 11865 | R60: =O60*Q60 -> 0
B61: WFF(Wallops Flight Facility) / LaRC (Langley Research Center) | C61: WFF/LaRC | R61: =SUM(R16:R60) -> 0
B62: SENIOR 2 ACCOUNTING SPECIALIST | C62: WFF/LaRC | E62: 1 | G62: =F62*(1+$D$9) -> 0 | J62: =I62*(1+$D$9) -> 0 | M62: =L62*(1+$D$9) -> 0 | O62: =(D62*E62)+(G62*H62)+(J62*K62)+(M62*N62) -> 0 | P62: =N62+K62+H62+E62 -> 1 | Q62: 5634 | R62: =O62*Q62 -> 0
B63: LOW CM SPECIALIST | C63: WFF/LaRC | E63: 1 | G63: =F63*(1+$D$9) -> 0 | J63: =I63*(1+$D$9) -> 0 | M63: =L63*(1+$D$9) -> 0 | O63: =(D63*E63)+(G63*H63)+(J63*K63)+(M63*N63) -> 0 | P63: =N63+K63+H63+E63 -> 1 | Q63: 1878 | R63: =O63*Q63 -> 0
B64: INTERMEDIATE CM SPECIALIST | C64: WFF/LaRC | E64: 1 | G64: =F64*(1+$D$9) -> 0 | J64: =I64*(1+$D$9) -> 0 | M64: =L64*(1+$D$9) -> 0 | O64: =(D64*E64)+(G64*H64)+(J64*K64)+(M64*N64) -> 0 | P64: =N64+K64+H64+E64 -> 1 | Q64: 7512 | R64: =O64*Q64 -> 0
B65: HIGH CM SPECIALIST | C65: WFF/LaRC | E65: 1 | G65: =F65*(1+$D$9) -> 0 | J65: =I65*(1+$D$9) -> 0 | M65: =L65*(1+$D$9) -> 0 | O65: =(D65*E65)+(G65*H65)+(J65*K65)+(M65*N65) -> 0 | P65: =N65+K65+H65+E65 -> 1 | Q65: 1878 | R65: =O65*Q65 -> 0
B66: SENIOR 1 CM SPECIALIST | C66: WFF/LaRC | E66: 1 | G66: =F66*(1+$D$9) -> 0 | J66: =I66*(1+$D$9) -> 0 | M66: =L66*(1+$D$9) -> 0 | O66: =(D66*E66)+(G66*H66)+(J66*K66)+(M66*N66) -> 0 | P66: =N66+K66+H66+E66 -> 1 | Q66: 1878 | R66: =O66*Q66 -> 0
B67: SENIOR 3 DOCUMENTATION SPECIALIST | C67: WFF/LaRC | E67: 1 | G67: =F67*(1+$D$9) -> 0 | J67: =I67*(1+$D$9) -> 0 | M67: =L67*(1+$D$9) -> 0 | O67: =(D67*E67)+(G67*H67)+(J67*K67)+(M67*N67) -> 0 | P67: =N67+K67+H67+E67 -> 1 | Q67: 1878 | R67: =O67*Q67 -> 0
B68: INTERMEDIATE GENERAL BUSINESS SPECIALIST | C68: WFF/LaRC | E68: 1 | G68: =F68*(1+$D$9) -> 0 | J68: =I68*(1+$D$9) -> 0 | M68: =L68*(1+$D$9) -> 0 | O68: =(D68*E68)+(G68*H68)+(J68*K68)+(M68*N68) -> 0 | P68: =N68+K68+H68+E68 -> 1 | Q68: 7512 | R68: =O68*Q68 -> 0
B69: HIGH GENERAL BUSINESS SPECIALIST | C69: WFF/LaRC | E69: 1 | G69: =F69*(1+$D$9) -> 0 | J69: =I69*(1+$D$9) -> 0 | M69: =L69*(1+$D$9) -> 0 | O69: =(D69*E69)+(G69*H69)+(J69*K69)+(M69*N69) -> 0 | P69: =N69+K69+H69+E69 -> 1 | Q69: 9390 | R69: =O69*Q69 -> 0
B70: SENIOR 2 GENERAL BUSINESS SPECIALIST | C70: WFF/LaRC | E70: 1 | G70: =F70*(1+$D$9) -> 0 | J70: =I70*(1+$D$9) -> 0 | M70: =L70*(1+$D$9) -> 0 | O70: =(D70*E70)+(G70*H70)+(J70*K70)+(M70*N70) -> 0 | P70: =N70+K70+H70+E70 -> 1 | Q70: 1878 | R70: =O70*Q70 -> 0
B71: SENIOR 3 GENERAL BUSINESS SPECIALIST | C71: WFF/LaRC | E71: 1 | G71: =F71*(1+$D$9) -> 0 | J71: =I71*(1+$D$9) -> 0 | M71: =L71*(1+$D$9) -> 0 | O71: =(D71*E71)+(G71*H71)+(J71*K71)+(M71*N71) -> 0 | P71: =N71+K71+H71+E71 -> 1 | Q71: 1878 | R71: =O71*Q71 -> 0
B72: JUNIOR SCHEDULING SPECIALIST | C72: WFF/LaRC | E72: 1 | G72: =F72*(1+$D$9) -> 0 | J72: =I72*(1+$D$9) -> 0 | M72: =L72*(1+$D$9) -> 0 | O72: =(D72*E72)+(G72*H72)+(J72*K72)+(M72*N72) -> 0 | P72: =N72+K72+H72+E72 -> 1 | Q72: 1878 | R72: =O72*Q72 -> 0
B73: LOW SCHEDULING SPECIALIST | C73: WFF/LaRC | E73: 1 | G73: =F73*(1+$D$9) -> 0 | J73: =I73*(1+$D$9) -> 0 | M73: =L73*(1+$D$9) -> 0 | O73: =(D73*E73)+(G73*H73)+(J73*K73)+(M73*N73) -> 0 | P73: =N73+K73+H73+E73 -> 1 | Q73: 5634 | R73: =O73*Q73 -> 0
... B78: SENIOR 3 SCHEDULING SPECIALIST | C78: WFF/LaRC | E78: 1 | G78: =F78*(1+$D$9) -> 0 | J78: =I78*(1+$D$9) -> 0 | M78: =L78*(1+$D$9) -> 0 | O78: =(D78*E78)+(G78*H78)+(J78*K78)+(M78*N78) -> 0 | P78: =N78+K78+H78+E78 -> 1 | Q78: 15024 | R78: =O78*Q78 -> 0
...

Sheet Exhibit 1A-2
B2: Proposing Entity:
B3: Offeror Name [ ] Prime ________________________________________________________
B4: EXHIBIT 1A [PRIME OFFEROR]
E5: Composite IDIQ Rate Development by Year
G7: Prime Only
B8: Identify Prime Offeror Loadings Applied to Subcontractor FBL Rates: e.g. G&A, handling, profit
B9: Prime Offeror Load (burdens) on Subcontractors | I9: Note: The Offeror shall provide a fully burdened labor rate for each labor category.
B11: NOTE: This percentage should be consistent with what is provided in Tab B and Tab I | O11: =B12 -> Contract Year 2
B12: Contract Year 2 | D12: Prime Offeror | F12: Subcontractor (Dummy sub1) | I12: Subcontractor (Dummy 2) | L12: Subcontractor (Insert Name) | O12: TOTAL COMPOSITE
D13: Prime FBL Rate* | E13: Percent of Effort | F13: Sub 1 FBL Rate | G13: Sub FBL Rate with Prime Load | H13: Percent of Effort | I13: Sub 2 FBL Rate | J13: Sub FBL Rate with Prime Load | K13: Percent of Effort | L13: Sub 3 FBL Rate | M13: Sub FBL Rate with Prime Load | N13: Percent of Effort | O13: Composite IDIQ FBL Rate | P13: Percent of Effort | Q13: Total Hours | R13: Total Direct Labor Costs
B14: Example | D14: 39.67 | E14: 0.5 | F14: 42 | G14: =F14*(1+$D$9) -> 42 | H14: 0.5 | I14: 45 | J14: =I14*(1+$D$9) -> 45 | L14: 38 | M14: =L14*(1+$D$9) -> 38 | O14: =(D14*E14)+(G14*H14)+(J14*K14)+(M14*N14) -> 40.835 | P14: =N14+K14+H14+E14 -> 1 | Q14: 1920 | R14: =O14*Q14 -> 78403.2
B15: GSFC (Goddard Space Flight Center) / HQ (Headquarters) | C15: GSFC/HQ
B16: LOW ACCOUNTING SPECIALIST | C16: GSFC/HQ | E16: 1 | G16: =F16*(1+$E$9) -> 0 | J16: =I16*(1+$E$9) -> 0 | M16: =L16*(1+$E$9) -> 0 | O16: =(D16*E16)+(G16*H16)+(J16*K16)+(M16*N16) -> 0 | P16: =N16+K16+H16+E16 -> 1 | Q16: 1878 | R16: =O16*Q16 -> 0
B17: SENIOR 1 ACCOUNTING SPECIALIST | C17: GSFC/HQ | E17: 1 | G17: =F17*(1+$E$9) -> 0 | J17: =I17*(1+$E$9) -> 0 | M17: =L17*(1+$E$9) -> 0 | O17: =(D17*E17)+(G17*H17)+(J17*K17)+(M17*N17) -> 0 | P17: =N17+K17+H17+E17 -> 1 | Q17: 1878 | R17: =O17*Q17 -> 0
B18: SENIOR 2 ACCOUNTING SPECIALIST | C18: GSFC/HQ | E18: 1 | G18: =F18*(1+$E$9) -> 0 | J18: =I18*(1+$E$9) -> 0 | M18: =L18*(1+$E$9) -> 0 | O18: =(D18*E18)+(G18*H18)+(J18*K18)+(M18*N18) -> 0 | P18: =N18+K18+H18+E18 -> 1 | Q18: 3756 | R18: =O18*Q18 -> 0
B19: INTERMEDIATE CM SPECIALIST | C19: GSFC/HQ | E19: 1 | G19: =F19*(1+$E$9) -> 0 | J19: =I19*(1+$E$9) -> 0 | M19: =L19*(1+$E$9) -> 0 | O19: =(D19*E19)+(G19*H19)+(J19*K19)+(M19*N19) -> 0 | P19: =N19+K19+H19+E19 -> 1 | Q19: 28170 | R19: =O19*Q19 -> 0
B20: HIGH CM SPECIALIST | C20: GSFC/HQ | E20: 1 | G20: =F20*(1+$E$9) -> 0 | J20: =I20*(1+$E$9) -> 0 | M20: =L20*(1+$E$9) -> 0 | O20: =(D20*E20)+(G20*H20)+(J20*K20)+(M20*N20) -> 0 | P20: =N20+K20+H20+E20 -> 1 | Q20: 16902 | R20: =O20*Q20 -> 0
B21: SENIOR 1 CM SPECIALIST | C21: GSFC/HQ | E21: 1 | G21: =F21*(1+$E$9) -> 0 | J21: =I21*(1+$E$9) -> 0 | M21: =L21*(1+$E$9) -> 0 | O21: =(D21*E21)+(G21*H21)+(J21*K21)+(M21*N21) -> 0 | P21: =N21+K21+H21+E21 -> 1 | Q21: 13146 | R21: =O21*Q21 -> 0
B22: SENIOR 2 CM SPECIALIST | C22: GSFC/HQ | E22: 1 | G22: =F22*(1+$E$9) -> 0 | J22: =I22*(1+$E$9) -> 0 | M22: =L22*(1+$E$9) -> 0 | O22: =(D22*E22)+(G22*H22)+(J22*K22)+(M22*N22) -> 0 | P22: =N22+K22+H22+E22 -> 1 | Q22: 7512 | R22: =O22*Q22 -> 0
B23: SENIOR 3 CM SPECIALIST | C23: GSFC/HQ | E23: 1 | G23: =F23*(1+$E$9) -> 0 | J23: =I23*(1+$E$9) -> 0 | M23: =L23*(1+$E$9) -> 0 | O23: =(D23*E23)+(G23*H23)+(J23*K23)+(M23*N23) -> 0 | P23: =N23+K23+H23+E23 -> 1 | Q23: 31926 | R23: =O23*Q23 -> 0
B24: INTERMEDIATE DOCUMENTATION SPECIALIST | C24: GSFC/HQ | E24: 1 | G24: =F24*(1+$E$9) -> 0 | J24: =I24*(1+$E$9) -> 0 | M24: =L24*(1+$E$9) -> 0 | O24: =(D24*E24)+(G24*H24)+(J24*K24)+(M24*N24) -> 0 | P24: =N24+K24+H24+E24 -> 1 | Q24: 3756 | R24: =O24*Q24 -> 0
B25: HIGH DOCUMENTATION SPECIALIST | C25: GSFC/HQ | E25: 1 | G25: =F25*(1+$E$9) -> 0 | J25: =I25*(1+$E$9) -> 0 | M25: =L25*(1+$E$9) -> 0 | O25: =(D25*E25)+(G25*H25)+(J25*K25)+(M25*N25) -> 0 | P25: =N25+K25+H25+E25 -> 1 | Q25: 1878 | R25: =O25*Q25 -> 0
B26: SENIOR 1 DOCUMENTAION SPECIALIST | C26: GSFC/HQ | E26: 1 | G26: =F26*(1+$E$9) -> 0 | J26: =I26*(1+$E$9) -> 0 | M26: =L26*(1+$E$9) -> 0 | O26: =(D26*E26)+(G26*H26)+(J26*K26)+(M26*N26) -> 0 | P26: =N26+K26+H26+E26 -> 1 | Q26: 9390 | R26: =O26*Q26 -> 0
B27: SENIOR 2 DOCUMENTATION SPECIALIST | C27: GSFC/HQ | E27: 1 | G27: =F27*(1+$E$9) -> 0 | J27: =I27*(1+$E$9) -> 0 | M27: =L27*(1+$E$9) -> 0 | O27: =(D27*E27)+(G27*H27)+(J27*K27)+(M27*N27) -> 0 | P27: =N27+K27+H27+E27 -> 1 | Q27: 7512 | R27: =O27*Q27 -> 0
... B60: ASSOCIATE II | C60: GSFC/HQ | E60: 1 | G60: =F60*(1+$E$9) -> 0 | J60: =I60*(1+$E$9) -> 0 | M60: =L60*(1+$E$9) -> 0 | O60: =(D60*E60)+(G60*H60)+(J60*K60)+(M60*N60) -> 0 | P60: =N60+K60+H60+E60 -> 1 | Q60: 11865 | R60: =O60*Q60 -> 0
B61: WFF(Wallops / LaRC (Langley | C61: WFF/LaRC | R61: =SUM(R16:R60) -> 0
B62: SENIOR 2 ACCOUNTING SPECIALIST | C62: WFF/LaRC | E62: 1 | G62: =F62*(1+$D$9) -> 0 | J62: =I62*(1+$D$9) -> 0 | M62: =L62*(1+$D$9) -> 0 | O62: =(D62*E62)+(G62*H62)+(J62*K62)+(M62*N62) -> 0 | P62: =N62+K62+H62+E62 -> 1 | Q62: 5634 | R62: =O62*Q62 -> 0
B63: LOW CM SPECIALIST | C63: WFF/LaRC | E63: 1 | G63: =F63*(1+$D$9) -> 0 | J63: =I63*(1+$D$9) -> 0 | M63: =L63*(1+$D$9) -> 0 | O63: =(D63*E63)+(G63*H63)+(J63*K63)+(M63*N63) -> 0 | P63: =N63+K63+H63+E63 -> 1 | Q63: 1878 | R63: =O63*Q63 -> 0
B64: INTERMEDIATE CM SPECIALIST | C64: WFF/LaRC | E64: 1 | G64: =F64*(1+$D$9) -> 0 | J64: =I64*(1+$D$9) -> 0 | M64: =L64*(1+$D$9) -> 0 | O64: =(D64*E64)+(G64*H64)+(J64*K64)+(M64*N64) -> 0 | P64: =N64+K64+H64+E64 -> 1 | Q64: 7512 | R64: =O64*Q64 -> 0
B65: HIGH CM SPECIALIST | C65: WFF/LaRC | E65: 1 | G65: =F65*(1+$D$9) -> 0 | J65: =I65*(1+$D$9) -> 0 | M65: =L65*(1+$D$9) -> 0 | O65: =(D65*E65)+(G65*H65)+(J65*K65)+(M65*N65) -> 0 | P65: =N65+K65+H65+E65 -> 1 | Q65: 1878 | R65: =O65*Q65 -> 0
B66: SENIOR 1 CM SPECIALIST | C66: WFF/LaRC | E66: 1 | G66: =F66*(1+$D$9) -> 0 | J66: =I66*(1+$D$9) -> 0 | M66: =L66*(1+$D$9) -> 0 | O66: =(D66*E66)+(G66*H66)+(J66*K66)+(M66*N66) -> 0 | P66: =N66+K66+H66+E66 -> 1 | Q66: 1878 | R66: =O66*Q66 -> 0
B67: SENIOR 3 DOCUMENTATION SPECIALIST | C67: WFF/LaRC | E67: 1 | G67: =F67*(1+$D$9) -> 0 | J67: =I67*(1+$D$9) -> 0 | M67: =L67*(1+$D$9) -> 0 | O67: =(D67*E67)+(G67*H67)+(J67*K67)+(M67*N67) -> 0 | P67: =N67+K67+H67+E67 -> 1 | Q67: 1878 | R67: =O67*Q67 -> 0
B68: INTERMEDIATE GENERAL BUSINESS SPECIALIST | C68: WFF/LaRC | E68: 1 | G68: =F68*(1+$D$9) -> 0 | J68: =I68*(1+$D$9) -> 0 | M68: =L68*(1+$D$9) -> 0 | O68: =(D68*E68)+(G68*H68)+(J68*K68)+(M68*N68) -> 0 | P68: =N68+K68+H68+E68 -> 1 | Q68: 7512 | R68: =O68*Q68 -> 0
B69: HIGH GENERAL BUSINESS SPECIALIST | C69: WFF/LaRC | E69: 1 | G69: =F69*(1+$D$9) -> 0 | J69: =I69*(1+$D$9) -> 0 | M69: =L69*(1+$D$9) -> 0 | O69: =(D69*E69)+(G69*H69)+(J69*K69)+(M69*N69) -> 0 | P69: =N69+K69+H69+E69 -> 1 | Q69: 9390 | R69: =O69*Q69 -> 0
B70: SENIOR 2 GENERAL BUSINESS SPECIALIST | C70: WFF/LaRC | E70: 1 | G70: =F70*(1+$D$9) -> 0 | J70: =I70*(1+$D$9) -> 0 | M70: =L70*(1+$D$9) -> 0 | O70: =(D70*E70)+(G70*H70)+(J70*K70)+(M70*N70) -> 0 | P70: =N70+K70+H70+E70 -> 1 | Q70: 1878 | R70: =O70*Q70 -> 0
B71: SENIOR 3 GENERAL BUSINESS SPECIALIST | C71: WFF/LaRC | E71: 1 | G71: =F71*(1+$D$9) -> 0 | J71: =I71*(1+$D$9) -> 0 | M71: =L71*(1+$D$9) -> 0 | O71: =(D71*E71)+(G71*H71)+(J71*K71)+(M71*N71) -> 0 | P71: =N71+K71+H71+E71 -> 1 | Q71: 1878 | R71: =O71*Q71 -> 0
B72: JUNIOR SCHEDULING SPECIALIST | C72: WFF/LaRC | E72: 1 | G72: =F72*(1+$D$9) -> 0 | J72: =I72*(1+$D$9) -> 0 | M72: =L72*(1+$D$9) -> 0 | O72: =(D72*E72)+(G72*H72)+(J72*K72)+(M72*N72) -> 0 | P72: =N72+K72+H72+E72 -> 1 | Q72: 1878 | R72: =O72*Q72 -> 0
B73: LOW SCHEDULING SPECIALIST | C73: WFF/LaRC | E73: 1 | G73: =F73*(1+$D$9) -> 0 | J73: =I73*(1+$D$9) -> 0 | M73: =L73*(1+$D$9) -> 0 | O73: =(D73*E73)+(G73*H73)+(J73*K73)+(M73*N73) -> 0 | P73: =N73+K73+H73+E73 -> 1 | Q73: 5634 | R73: =O73*Q73 -> 0
... B78: SENIOR 3 SCHEDULING SPECIALIST | C78: WFF/LaRC | E78: 1 | G78: =F78*(1+$D$9) -> 0 | J78: =I78*(1+$D$9) -> 0 | M78: =L78*(1+$D$9) -> 0 | O78: =(D78*E78)+(G78*H78)+(J78*K78)+(M78*N78) -> 0 | P78: =N78+K78+H78+E78 -> 1 | Q78: 15024 | R78: =O78*Q78 -> 0
B79: Management and Administrative Labor Categories | R79: =SUM(R62:R78) -> 0
...

Sheet Exhibit 1A-3
B2: Proposing Entity:
B3: Offeror Name [ ] Prime ________________________________________________________
B4: EXHIBIT 1A [PRIME OFFEROR]
E5: Composite IDIQ Rate Development by Year
G7: Prime Only
B8: Identify Prime Offeror Loadings Applied to Subcontractor FBL Rates: e.g. G&A, handling, profit
B9: Prime Offeror Load (burdens) on Subcontractors | I9: Note: The Offeror shall provide a fully burdened labor rate for each labor category.
B11: NOTE: This percentage should be consistent with what is provided in Tab B and Tab I | O11: =B12 -> Contract Year 3
B12: Contract Year 3 | D12: Prime Offeror | F12: Subcontractor (Dummy sub1) | I12: Subcontractor (Dummy 2) | L12: Subcontractor (Insert Name) | O12: TOTAL COMPOSITE
D13: Prime FBL Rate* | E13: Percent of Effort | F13: Sub 1 FBL Rate | G13: Sub FBL Rate with Prime Load | H13: Percent of Effort | I13: Sub 2 FBL Rate | J13: Sub FBL Rate with Prime Load | K13: Percent of Effort | L13: Sub 3 FBL Rate | M13: Sub FBL Rate with Prime Load | N13: Percent of Effort | O13: Composite IDIQ FBL Rate | P13: Percent of Effort | Q13: Total Hours | R13: Total Direct Labor Costs
B14: Example | D14: 39.67 | E14: 0.5 | F14: 42 | G14: =F14*(1+$D$9) -> 42 | H14: 0.5 | I14: 45 | J14: =I14*(1+$D$9) -> 45 | L14: 38 | M14: =L14*(1+$D$9) -> 38 | O14: =(D14*E14)+(G14*H14)+(J14*K14)+(M14*N14) -> 40.835 | P14: =N14+K14+H14+E14 -> 1 | Q14: 1920 | R14: =O14*Q14 -> 78403.2
B15: GSFC (Goddard Space Flight Center) / HQ (Headquarters) | C15: GSFC/HQ
B16: LOW ACCOUNTING SPECIALIST | C16: GSFC/HQ | E16: 1 | G16: =F16*(1+$E$9) -> 0 | J16: =I16*(1+$E$9) -> 0 | M16: =L16*(1+$E$9) -> 0 | O16: =(D16*E16)+(G16*H16)+(J16*K16)+(M16*N16) -> 0 | P16: =N16+K16+H16+E16 -> 1 | Q16: 1878 | R16: =O16*Q16 -> 0
B17: SENIOR 1 ACCOUNTING SPECIALIST | C17: GSFC/HQ | E17: 1 | G17: =F17*(1+$E$9) -> 0 | J17: =I17*(1+$E$9) -> 0 | M17: =L17*(1+$E$9) -> 0 | O17: =(D17*E17)+(G17*H17)+(J17*K17)+(M17*N17) -> 0 | P17: =N17+K17+H17+E17 -> 1 | Q17: 1878 | R17: =O17*Q17 -> 0
B18: SENIOR 2 ACCOUNTING SPECIALIST | C18: GSFC/HQ | E18: 1 | G18: =F18*(1+$E$9) -> 0 | J18: =I18*(1+$E$9) -> 0 | M18: =L18*(1+$E$9) -> 0 | O18: =(D18*E18)+(G18*H18)+(J18*K18)+(M18*N18) -> 0 | P18: =N18+K18+H18+E18 -> 1 | Q18: 3756 | R18: =O18*Q18 -> 0
B19: INTERMEDIATE CM SPECIALIST | C19: GSFC/HQ | E19: 1 | G19: =F19*(1+$E$9) -> 0 | J19: =I19*(1+$E$9) -> 0 | M19: =L19*(1+$E$9) -> 0 | O19: =(D19*E19)+(G19*H19)+(J19*K19)+(M19*N19) -> 0 | P19: =N19+K19+H19+E19 -> 1 | Q19: 28170 | R19: =O19*Q19 -> 0
B20: HIGH CM SPECIALIST | C20: GSFC/HQ | E20: 1 | G20: =F20*(1+$E$9) -> 0 | J20: =I20*(1+$E$9) -> 0 | M20: =L20*(1+$E$9) -> 0 | O20: =(D20*E20)+(G20*H20)+(J20*K20)+(M20*N20) -> 0 | P20: =N20+K20+H20+E20 -> 1 | Q20: 16902 | R20: =O20*Q20 -> 0
B21: SENIOR 1 CM SPECIALIST | C21: GSFC/HQ | E21: 1 | G21: =F21*(1+$E$9) -> 0 | J21: =I21*(1+$E$9) -> 0 | M21: =L21*(1+$E$9) -> 0 | O21: =(D21*E21)+(G21*H21)+(J21*K21)+(M21*N21) -> 0 | P21: =N21+K21+H21+E21 -> 1 | Q21: 13146 | R21: =O21*Q21 -> 0
B22: SENIOR 2 CM SPECIALIST | C22: GSFC/HQ | E22: 1 | G22: =F22*(1+$E$9) -> 0 | J22: =I22*(1+$E$9) -> 0 | M22: =L22*(1+$E$9) -> 0 | O22: =(D22*E22)+(G22*H22)+(J22*K22)+(M22*N22) -> 0 | P22: =N22+K22+H22+E22 -> 1 | Q22: 7512 | R22: =O22*Q22 -> 0
B23: SENIOR 3 CM SPECIALIST | C23: GSFC/HQ | E23: 1 | G23: =F23*(1+$E$9) -> 0 | J23: =I23*(1+$E$9) -> 0 | M23: =L23*(1+$E$9) -> 0 | O23: =(D23*E23)+(G23*H23)+(J23*K23)+(M23*N23) -> 0 | P23: =N23+K23+H23+E23 -> 1 | Q23: 31926 | R23: =O23*Q23 -> 0
B24: INTERMEDIATE DOCUMENTATION SPECIALIST | C24: GSFC/HQ | E24: 1 | G24: =F24*(1+$E$9) -> 0 | J24: =I24*(1+$E$9) -> 0 | M24: =L24*(1+$E$9) -> 0 | O24: =(D24*E24)+(G24*H24)+(J24*K24)+(M24*N24) -> 0 | P24: =N24+K24+H24+E24 -> 1 | Q24: 3756 | R24: =O24*Q24 -> 0
B25: HIGH DOCUMENTATION SPECIALIST | C25: GSFC/HQ | E25: 1 | G25: =F25*(1+$E$9) -> 0 | J25: =I25*(1+$E$9) -> 0 | M25: =L25*(1+$E$9) -> 0 | O25: =(D25*E25)+(G25*H25)+(J25*K25)+(M25*N25) -> 0 | P25: =N25+K25+H25+E25 -> 1 | Q25: 1878 | R25: =O25*Q25 -> 0
B26: SENIOR 1 DOCUMENTAION SPECIALIST | C26: GSFC/HQ | E26: 1 | G26: =F26*(1+$E$9) -> 0 | J26: =I26*(1+$E$9) -> 0 | M26: =L26*(1+$E$9) -> 0 | O26: =(D26*E26)+(G26*H26)+(J26*K26)+(M26*N26) -> 0 | P26: =N26+K26+H26+E26 -> 1 | Q26: 9390 | R26: =O26*Q26 -> 0
B27: SENIOR 2 DOCUMENTATION SPECIALIST | C27: GSFC/HQ | E27: 1 | G27: =F27*(1+$E$9) -> 0 | J27: =I27*(1+$E$9) -> 0 | M27: =L27*(1+$E$9) -> 0 | O27: =(D27*E27)+(G27*H27)+(J27*K27)+(M27*N27) -> 0 | P27: =N27+K27+H27+E27 -> 1 | Q27: 7512 | R27: =O27*Q27 -> 0
... B60: ASSOCIATE II | C60: GSFC/HQ | E60: 1 | G60: =F60*(1+$E$9) -> 0 | J60: =I60*(1+$E$9) -> 0 | M60: =L60*(1+$E$9) -> 0 | O60: =(D60*E60)+(G60*H60)+(J60*K60)+(M60*N60) -> 0 | P60: =N60+K60+H60+E60 -> 1 | Q60: 11865 | R60: =O60*Q60 -> 0
B61: WFF(Wallops / LaRC (Langley | C61: WFF/LaRC | R61: =SUM(R16:R60) -> 0
B62: SENIOR 2 ACCOUNTING SPECIALIST | C62: WFF/LaRC | E62: 1 | G62: =F62*(1+$D$9) -> 0 | J62: =I62*(1+$D$9) -> 0 | M62: =L62*(1+$D$9) -> 0 | O62: =(D62*E62)+(G62*H62)+(J62*K62)+(M62*N62) -> 0 | P62: =N62+K62+H62+E62 -> 1 | Q62: 5634 | R62: =O62*Q62 -> 0
B63: LOW CM SPECIALIST | C63: WFF/LaRC | E63: 1 | G63: =F63*(1+$D$9) -> 0 | J63: =I63*(1+$D$9) -> 0 | M63: =L63*(1+$D$9) -> 0 | O63: =(D63*E63)+(G63*H63)+(J63*K63)+(M63*N63) -> 0 | P63: =N63+K63+H63+E63 -> 1 | Q63: 1878 | R63: =O63*Q63 -> 0
B64: INTERMEDIATE CM SPECIALIST | C64: WFF/LaRC | E64: 1 | G64: =F64*(1+$D$9) -> 0 | J64: =I64*(1+$D$9) -> 0 | M64: =L64*(1+$D$9) -> 0 | O64: =(D64*E64)+(G64*H64)+(J64*K64)+(M64*N64) -> 0 | P64: =N64+K64+H64+E64 -> 1 | Q64: 7512 | R64: =O64*Q64 -> 0
B65: HIGH CM SPECIALIST | C65: WFF/LaRC | E65: 1 | G65: =F65*(1+$D$9) -> 0 | J65: =I65*(1+$D$9) -> 0 | M65: =L65*(1+$D$9) -> 0 | O65: =(D65*E65)+(G65*H65)+(J65*K65)+(M65*N65) -> 0 | P65: =N65+K65+H65+E65 -> 1 | Q65: 1878 | R65: =O65*Q65 -> 0
B66: SENIOR 1 CM SPECIALIST | C66: WFF/LaRC | E66: 1 | G66: =F66*(1+$D$9) -> 0 | J66: =I66*(1+$D$9) -> 0 | M66: =L66*(1+$D$9) -> 0 | O66: =(D66*E66)+(G66*H66)+(J66*K66)+(M66*N66) -> 0 | P66: =N66+K66+H66+E66 -> 1 | Q66: 1878 | R66: =O66*Q66 -> 0
B67: SENIOR 3 DOCUMENTATION SPECIALIST | C67: WFF/LaRC | E67: 1 | G67: =F67*(1+$D$9) -> 0 | J67: =I67*(1+$D$9) -> 0 | M67: =L67*(1+$D$9) -> 0 | O67: =(D67*E67)+(G67*H67)+(J67*K67)+(M67*N67) -> 0 | P67: =N67+K67+H67+E67 -> 1 | Q67: 1878 | R67: =O67*Q67 -> 0
B68: INTERMEDIATE GENERAL BUSINESS SPECIALIST | C68: WFF/LaRC | E68: 1 | G68: =F68*(1+$D$9) -> 0 | J68: =I68*(1+$D$9) -> 0 | M68: =L68*(1+$D$9) -> 0 | O68: =(D68*E68)+(G68*H68)+(J68*K68)+(M68*N68) -> 0 | P68: =N68+K68+H68+E68 -> 1 | Q68: 7512 | R68: =O68*Q68 -> 0
B69: HIGH GENERAL BUSINESS SPECIALIST | C69: WFF/LaRC | E69: 1 | G69: =F69*(1+$D$9) -> 0 | J69: =I69*(1+$D$9) -> 0 | M69: =L69*(1+$D$9) -> 0 | O69: =(D69*E69)+(G69*H69)+(J69*K69)+(M69*N69) -> 0 | P69: =N69+K69+H69+E69 -> 1 | Q69: 9390 | R69: =O69*Q69 -> 0
B70: SENIOR 2 GENERAL BUSINESS SPECIALIST | C70: WFF/LaRC | E70: 1 | G70: =F70*(1+$D$9) -> 0 | J70: =I70*(1+$D$9) -> 0 | M70: =L70*(1+$D$9) -> 0 | O70: =(D70*E70)+(G70*H70)+(J70*K70)+(M70*N70) -> 0 | P70: =N70+K70+H70+E70 -> 1 | Q70: 1878 | R70: =O70*Q70 -> 0
B71: SENIOR 3 GENERAL BUSINESS SPECIALIST | C71: WFF/LaRC | E71: 1 | G71: =F71*(1+$D$9) -> 0 | J71: =I71*(1+$D$9) -> 0 | M71: =L71*(1+$D$9) -> 0 | O71: =(D71*E71)+(G71*H71)+(J71*K71)+(M71*N71) -> 0 | P71: =N71+K71+H71+E71 -> 1 | Q71: 1878 | R71: =O71*Q71 -> 0
B72: JUNIOR SCHEDULING SPECIALIST | C72: WFF/LaRC | E72: 1 | G72: =F72*(1+$D$9) -> 0 | J72: =I72*(1+$D$9) -> 0 | M72: =L72*(1+$D$9) -> 0 | O72: =(D72*E72)+(G72*H72)+(J72*K72)+(M72*N72) -> 0 | P72: =N72+K72+H72+E72 -> 1 | Q72: 1878 | R72: =O72*Q72 -> 0
B73: LOW SCHEDULING SPECIALIST | C73: WFF/LaRC | E73: 1 | G73: =F73*(1+$D$9) -> 0 | J73: =I73*(1+$D$9) -> 0 | M73: =L73*(1+$D$9) -> 0 | O73: =(D73*E73)+(G73*H73)+(J73*K73)+(M73*N73) -> 0 | P73: =N73+K73+H73+E73 -> 1 | Q73: 5634 | R73: =O73*Q73 -> 0
... B78: SENIOR 3 SCHEDULING SPECIALIST | C78: WFF/LaRC | E78: 1 | G78: =F78*(1+$D$9) -> 0 | J78: =I78*(1+$D$9) -> 0 | M78: =L78*(1+$D$9) -> 0 | O78: =(D78*E78)+(G78*H78)+(J78*K78)+(M78*N78) -> 0 | P78: =N78+K78+H78+E78 -> 1 | Q78: 15024 | R78: =O78*Q78 -> 0
B79: Management and Administrative Labor Categories | R79: =SUM(R62:R78) -> 0
...

Sheet Exhibit 1A-4
B2: Proposing Entity:
B3: Offeror Name [ ] Prime ________________________________________________________
B4: EXHIBIT 1A [PRIME OFFEROR]
E5: Composite IDIQ Rate Development by Year
G7: Prime Only
B8: Identify Prime Offeror Loadings Applied to Subcontractor FBL Rates: e.g. G&A, handling, profit
B9: Prime Offeror Load (burdens) on Subcontractors | I9: Note: The Offeror shall provide a fully burdened labor rate for each labor category.
B11: NOTE: This percentage should be consistent with what is provided in Tab B and Tab I | O11: =B12 -> Contract Year 4
B12: Contract Year 4 | D12: Prime Offeror | F12: Subcontractor (Dummy sub1) | I12: Subcontractor (Dummy 2) | L12: Subcontractor (Insert Name) | O12: TOTAL COMPOSITE
D13: Prime FBL Rate* | E13: Percent of Effort | F13: Sub 1 FBL Rate | G13: Sub FBL Rate with Prime Load | H13: Percent of Effort | I13: Sub 2 FBL Rate | J13: Sub FBL Rate with Prime Load | K13: Percent of Effort | L13: Sub 3 FBL Rate | M13: Sub FBL Rate with Prime Load | N13: Percent of Effort | O13: Composite IDIQ FBL Rate | P13: Percent of Effort | Q13: Total Hours | R13: Total Direct Labor Costs
B14: Example | D14: 39.67 | E14: 0.5 | F14: 42 | G14: =F14*(1+$D$9) -> 42 | H14: 0.5 | I14: 45 | J14: =I14*(1+$D$9) -> 45 | L14: 38 | M14: =L14*(1+$D$9) -> 38 | O14: =(D14*E14)+(G14*H14)+(J14*K14)+(M14*N14) -> 40.835 | P14: =N14+K14+H14+E14 -> 1 | Q14: 1920 | R14: =O14*Q14 -> 78403.2
B15: GSFC (Goddard Space Flight Center) / HQ (Headquarters) | C15: GSFC/HQ
B16: LOW ACCOUNTING SPECIALIST | C16: GSFC/HQ | E16: 1 | G16: =F16*(1+$E$9) -> 0 | J16: =I16*(1+$E$9) -> 0 | M16: =L16*(1+$E$9) -> 0 | O16: =(D16*E16)+(G16*H16)+(J16*K16)+(M16*N16) -> 0 | P16: =N16+K16+H16+E16 -> 1 | Q16: 1878 | R16: =O16*Q16 -> 0
B17: SENIOR 1 ACCOUNTING SPECIALIST | C17: GSFC/HQ | E17: 1 | G17: =F17*(1+$E$9) -> 0 | J17: =I17*(1+$E$9) -> 0 | M17: =L17*(1+$E$9) -> 0 | O17: =(D17*E17)+(G17*H17)+(J17*K17)+(M17*N17) -> 0 | P17: =N17+K17+H17+E17 -> 1 | Q17: 1878 | R17: =O17*Q17 -> 0
B18: SENIOR 2 ACCOUNTING SPECIALIST | C18: GSFC/HQ | E18: 1 | G18: =F18*(1+$E$9) -> 0 | J18: =I18*(1+$E$9) -> 0 | M18: =L18*(1+$E$9) -> 0 | O18: =(D18*E18)+(G18*H18)+(J18*K18)+(M18*N18) -> 0 | P18: =N18+K18+H18+E18 -> 1 | Q18: 3756 | R18: =O18*Q18 -> 0
B19: INTERMEDIATE CM SPECIALIST | C19: GSFC/HQ | E19: 1 | G19: =F19*(1+$E$9) -> 0 | J19: =I19*(1+$E$9) -> 0 | M19: =L19*(1+$E$9) -> 0 | O19: =(D19*E19)+(G19*H19)+(J19*K19)+(M19*N19) -> 0 | P19: =N19+K19+H19+E19 -> 1 | Q19: 28170 | R19: =O19*Q19 -> 0
B20: HIGH CM SPECIALIST | C20: GSFC/HQ | E20: 1 | G20: =F20*(1+$E$9) -> 0 | J20: =I20*(1+$E$9) -> 0 | M20: =L20*(1+$E$9) -> 0 | O20: =(D20*E20)+(G20*H20)+(J20*K20)+(M20*N20) -> 0 | P20: =N20+K20+H20+E20 -> 1 | Q20: 16902 | R20: =O20*Q20 -> 0
B21: SENIOR 1 CM SPECIALIST | C21: GSFC/HQ | E21: 1 | G21: =F21*(1+$E$9) -> 0 | J21: =I21*(1+$E$9) -> 0 | M21: =L21*(1+$E$9) -> 0 | O21: =(D21*E21)+(G21*H21)+(J21*K21)+(M21*N21) -> 0 | P21: =N21+K21+H21+E21 -> 1 | Q21: 13146 | R21: =O21*Q21 -> 0
B22: SENIOR 2 CM SPECIALIST | C22: GSFC/HQ | E22: 1 | G22: =F22*(1+$E$9) -> 0 | J22: =I22*(1+$E$9) -> 0 | M22: =L22*(1+$E$9) -> 0 | O22: =(D22*E22)+(G22*H22)+(J22*K22)+(M22*N22) -> 0 | P22: =N22+K22+H22+E22 -> 1 | Q22: 7512 | R22: =O22*Q22 -> 0
B23: SENIOR 3 CM SPECIALIST | C23: GSFC/HQ | E23: 1 | G23: =F23*(1+$E$9) -> 0 | J23: =I23*(1+$E$9) -> 0 | M23: =L23*(1+$E$9) -> 0 | O23: =(D23*E23)+(G23*H23)+(J23*K23)+(M23*N23) -> 0 | P23: =N23+K23+H23+E23 -> 1 | Q23: 31926 | R23: =O23*Q23 -> 0
B24: INTERMEDIATE DOCUMENTATION SPECIALIST | C24: GSFC/HQ | E24: 1 | G24: =F24*(1+$E$9) -> 0 | J24: =I24*(1+$E$9) -> 0 | M24: =L24*(1+$E$9) -> 0 | O24: =(D24*E24)+(G24*H24)+(J24*K24)+(M24*N24) -> 0 | P24: =N24+K24+H24+E24 -> 1 | Q24: 3756 | R24: =O24*Q24 -> 0
B25: HIGH DOCUMENTATION SPECIALIST | C25: GSFC/HQ | E25: 1 | G25: =F25*(1+$E$9) -> 0 | J25: =I25*(1+$E$9) -> 0 | M25: =L25*(1+$E$9) -> 0 | O25: =(D25*E25)+(G25*H25)+(J25*K25)+(M25*N25) -> 0 | P25: =N25+K25+H25+E25 -> 1 | Q25: 1878 | R25: =O25*Q25 -> 0
B26: SENIOR 1 DOCUMENTAION SPECIALIST | C26: GSFC/HQ | E26: 1 | G26: =F26*(1+$E$9) -> 0 | J26: =I26*(1+$E$9) -> 0 | M26: =L26*(1+$E$9) -> 0 | O26: =(D26*E26)+(G26*H26)+(J26*K26)+(M26*N26) -> 0 | P26: =N26+K26+H26+E26 -> 1 | Q26: 9390 | R26: =O26*Q26 -> 0
B27: SENIOR 2 DOCUMENTATION SPECIALIST | C27: GSFC/HQ | E27: 1 | G27: =F27*(1+$E$9) -> 0 | J27: =I27*(1+$E$9) -> 0 | M27: =L27*(1+$E$9) -> 0 | O27: =(D27*E27)+(G27*H27)+(J27*K27)+(M27*N27) -> 0 | P27: =N27+K27+H27+E27 -> 1 | Q27: 7512 | R27: =O27*Q27 -> 0
... B60: ASSOCIATE II | C60: GSFC/HQ | E60: 1 | G60: =F60*(1+$E$9) -> 0 | J60: =I60*(1+$E$9) -> 0 | M60: =L60*(1+$E$9) -> 0 | O60: =(D60*E60)+(G60*H60)+(J60*K60)+(M60*N60) -> 0 | P60: =N60+K60+H60+E60 -> 1 | Q60: 11865 | R60: =O60*Q60 -> 0
B61: WFF(Wallops / LaRC (Langley | C61: WFF/LaRC | R61: =SUM(R16:R60) -> 0
B62: SENIOR 2 ACCOUNTING SPECIALIST | C62: WFF/LaRC | E62: 1 | G62: =F62*(1+$D$9) -> 0 | J62: =I62*(1+$D$9) -> 0 | M62: =L62*(1+$D$9) -> 0 | O62: =(D62*E62)+(G62*H62)+(J62*K62)+(M62*N62) -> 0 | P62: =N62+K62+H62+E62 -> 1 | Q62: 5634 | R62: =O62*Q62 -> 0
B63: LOW CM SPECIALIST | C63: WFF/LaRC | E63: 1 | G63: =F63*(1+$D$9) -> 0 | J63: =I63*(1+$D$9) -> 0 | M63: =L63*(1+$D$9) -> 0 | O63: =(D63*E63)+(G63*H63)+(J63*K63)+(M63*N63) -> 0 | P63: =N63+K63+H63+E63 -> 1 | Q63: 1878 | R63: =O63*Q63 -> 0
B64: INTERMEDIATE CM SPECIALIST | C64: WFF/LaRC | E64: 1 | G64: =F64*(1+$D$9) -> 0 | J64: =I64*(1+$D$9) -> 0 | M64: =L64*(1+$D$9) -> 0 | O64: =(D64*E64)+(G64*H64)+(J64*K64)+(M64*N64) -> 0 | P64: =N64+K64+H64+E64 -> 1 | Q64: 7512 | R64: =O64*Q64 -> 0
B65: HIGH CM SPECIALIST | C65: WFF/LaRC | E65: 1 | G65: =F65*(1+$D$9) -> 0 | J65: =I65*(1+$D$9) -> 0 | M65: =L65*(1+$D$9) -> 0 | O65: =(D65*E65)+(G65*H65)+(J65*K65)+(M65*N65) -> 0 | P65: =N65+K65+H65+E65 -> 1 | Q65: 1878 | R65: =O65*Q65 -> 0
B66: SENIOR 1 CM SPECIALIST | C66: WFF/LaRC | E66: 1 | G66: =F66*(1+$D$9) -> 0 | J66: =I66*(1+$D$9) -> 0 | M66: =L66*(1+$D$9) -> 0 | O66: =(D66*E66)+(G66*H66)+(J66*K66)+(M66*N66) -> 0 | P66: =N66+K66+H66+E66 -> 1 | Q66: 1878 | R66: =O66*Q66 -> 0
B67: SENIOR 3 DOCUMENTATION SPECIALIST | C67: WFF/LaRC | E67: 1 | G67: =F67*(1+$D$9) -> 0 | J67: =I67*(1+$D$9) -> 0 | M67: =L67*(1+$D$9) -> 0 | O67: =(D67*E67)+(G67*H67)+(J67*K67)+(M67*N67) -> 0 | P67: =N67+K67+H67+E67 -> 1 | Q67: 1878 | R67: =O67*Q67 -> 0
B68: INTERMEDIATE GENERAL BUSINESS SPECIALIST | C68: WFF/LaRC | E68: 1 | G68: =F68*(1+$D$9) -> 0 | J68: =I68*(1+$D$9) -> 0 | M68: =L68*(1+$D$9) -> 0 | O68: =(D68*E68)+(G68*H68)+(J68*K68)+(M68*N68) -> 0 | P68: =N68+K68+H68+E68 -> 1 | Q68: 7512 | R68: =O68*Q68 -> 0
B69: HIGH GENERAL BUSINESS SPECIALIST | C69: WFF/LaRC | E69: 1 | G69: =F69*(1+$D$9) -> 0 | J69: =I69*(1+$D$9) -> 0 | M69: =L69*(1+$D$9) -> 0 | O69: =(D69*E69)+(G69*H69)+(J69*K69)+(M69*N69) -> 0 | P69: =N69+K69+H69+E69 -> 1 | Q69: 9390 | R69: =O69*Q69 -> 0
B70: SENIOR 2 GENERAL BUSINESS SPECIALIST | C70: WFF/LaRC | E70: 1 | G70: =F70*(1+$D$9) -> 0 | J70: =I70*(1+$D$9) -> 0 | M70: =L70*(1+$D$9) -> 0 | O70: =(D70*E70)+(G70*H70)+(J70*K70)+(M70*N70) -> 0 | P70: =N70+K70+H70+E70 -> 1 | Q70: 1878 | R70: =O70*Q70 -> 0
B71: SENIOR 3 GENERAL BUSINESS SPECIALIST | C71: WFF/LaRC | E71: 1 | G71: =F71*(1+$D$9) -> 0 | J71: =I71*(1+$D$9) -> 0 | M71: =L71*(1+$D$9) -> 0 | O71: =(D71*E71)+(G71*H71)+(J71*K71)+(M71*N71) -> 0 | P71: =N71+K71+H71+E71 -> 1 | Q71: 1878 | R71: =O71*Q71 -> 0
B72: JUNIOR SCHEDULING SPECIALIST | C72: WFF/LaRC | E72: 1 | G72: =F72*(1+$D$9) -> 0 | J72: =I72*(1+$D$9) -> 0 | M72: =L72*(1+$D$9) -> 0 | O72: =(D72*E72)+(G72*H72)+(J72*K72)+(M72*N72) -> 0 | P72: =N72+K72+H72+E72 -> 1 | Q72: 1878 | R72: =O72*Q72 -> 0
B73: LOW SCHEDULING SPECIALIST | C73: WFF/LaRC | E73: 1 | G73: =F73*(1+$D$9) -> 0 | J73: =I73*(1+$D$9) -> 0 | M73: =L73*(1+$D$9) -> 0 | O73: =(D73*E73)+(G73*H73)+(J73*K73)+(M73*N73) -> 0 | P73: =N73+K73+H73+E73 -> 1 | Q73: 5634 | R73: =O73*Q73 -> 0
... B78: SENIOR 3 SCHEDULING SPECIALIST | C78: WFF/LaRC | E78: 1 | G78: =F78*(1+$D$9) -> 0 | J78: =I78*(1+$D$9) -> 0 | M78: =L78*(1+$D$9) -> 0 | O78: =(D78*E78)+(G78*H78)+(J78*K78)+(M78*N78) -> 0 | P78: =N78+K78+H78+E78 -> 1 | Q78: 15024 | R78: =O78*Q78 -> 0
B79: Management and Administrative Labor Categories | R79: =SUM(R62:R78) -> 0
...

Sheet Exhibit 1A-5
B2: Proposing Entity:
B3: Offeror Name [ ] Prime ________________________________________________________
B4: EXHIBIT 1A [PRIME OFFEROR]
E5: Composite IDIQ Rate Development by Year
G7: Prime Only
B8: Identify Prime Offeror Loadings Applied to Subcontractor FBL Rates: e.g. G&A, handling, profit
B9: Prime Offeror Load (burdens) on Subcontractors | I9: Note: The Offeror shall provide a fully burdened labor rate for each labor category.
B11: NOTE: This percentage should be consistent with what is provided in Tab B and Tab I | O11: =B12 -> Contract Year 5
B12: Contract Year 5 | D12: Prime Offeror | F12: Subcontractor (Dummy sub1) | I12: Subcontractor (Dummy 2) | L12: Subcontractor (Insert Name) | O12: TOTAL COMPOSITE
D13: Prime FBL Rate* | E13: Percent of Effort | F13: Sub 1 FBL Rate | G13: Sub FBL Rate with Prime Load | H13: Percent of Effort | I13: Sub 2 FBL Rate | J13: Sub FBL Rate with Prime Load | K13: Percent of Effort | L13: Sub 3 FBL Rate | M13: Sub FBL Rate with Prime Load | N13: Percent of Effort | O13: Composite IDIQ FBL Rate | P13: Percent of Effort | Q13: Total Hours | R13: Total Direct Labor Costs
B14: Example | D14: 39.67 | E14: 0.5 | F14: 42 | G14: =F14*(1+$D$9) -> 42 | H14: 0.5 | I14: 45 | J14: =I14*(1+$D$9) -> 45 | L14: 38 | M14: =L14*(1+$D$9) -> 38 | O14: =(D14*E14)+(G14*H14)+(J14*K14)+(M14*N14) -> 40.835 | P14: =N14+K14+H14+E14 -> 1 | Q14: 1920 | R14: =O14*Q14 -> 78403.2
B15: GSFC (Goddard Space Flight Center) / HQ (Headquarters) | C15: GSFC/HQ
B16: LOW ACCOUNTING SPECIALIST | C16: GSFC/HQ | E16: 1 | G16: =F16*(1+$E$9) -> 0 | J16: =I16*(1+$E$9) -> 0 | M16: =L16*(1+$E$9) -> 0 | O16: =(D16*E16)+(G16*H16)+(J16*K16)+(M16*N16) -> 0 | P16: =N16+K16+H16+E16 -> 1 | Q16: 1878 | R16: =O16*Q16 -> 0
B17: SENIOR 1 ACCOUNTING SPECIALIST | C17: GSFC/HQ | E17: 1 | G17: =F17*(1+$E$9) -> 0 | J17: =I17*(1+$E$9) -> 0 | M17: =L17*(1+$E$9) -> 0 | O17: =(D17*E17)+(G17*H17)+(J17*K17)+(M17*N17) -> 0 | P17: =N17+K17+H17+E17 -> 1 | Q17: 1878 | R17: =O17*Q17 -> 0
B18: SENIOR 2 ACCOUNTING SPECIALIST | C18: GSFC/HQ | E18: 1 | G18: =F18*(1+$E$9) -> 0 | J18: =I18*(1+$E$9) -> 0 | M18: =L18*(1+$E$9) -> 0 | O18: =(D18*E18)+(G18*H18)+(J18*K18)+(M18*N18) -> 0 | P18: =N18+K18+H18+E18 -> 1 | Q18: 3756 | R18: =O18*Q18 -> 0
B19: INTERMEDIATE CM SPECIALIST | C19: GSFC/HQ | E19: 1 | G19: =F19*(1+$E$9) -> 0 | J19: =I19*(1+$E$9) -> 0 | M19: =L19*(1+$E$9) -> 0 | O19: =(D19*E19)+(G19*H19)+(J19*K19)+(M19*N19) -> 0 | P19: =N19+K19+H19+E19 -> 1 | Q19: 28170 | R19: =O19*Q19 -> 0
B20: HIGH CM SPECIALIST | C20: GSFC/HQ | E20: 1 | G20: =F20*(1+$E$9) -> 0 | J20: =I20*(1+$E$9) -> 0 | M20: =L20*(1+$E$9) -> 0 | O20: =(D20*E20)+(G20*H20)+(J20*K20)+(M20*N20) -> 0 | P20: =N20+K20+H20+E20 -> 1 | Q20: 16902 | R20: =O20*Q20 -> 0
B21: SENIOR 1 CM SPECIALIST | C21: GSFC/HQ | E21: 1 | G21: =F21*(1+$E$9) -> 0 | J21: =I21*(1+$E$9) -> 0 | M21: =L21*(1+$E$9) -> 0 | O21: =(D21*E21)+(G21*H21)+(J21*K21)+(M21*N21) -> 0 | P21: =N21+K21+H21+E21 -> 1 | Q21: 13146 | R21: =O21*Q21 -> 0
B22: SENIOR 2 CM SPECIALIST | C22: GSFC/HQ | E22: 1 | G22: =F22*(1+$E$9) -> 0 | J22: =I22*(1+$E$9) -> 0 | M22: =L22*(1+$E$9) -> 0 | O22: =(D22*E22)+(G22*H22)+(J22*K22)+(M22*N22) -> 0 | P22: =N22+K22+H22+E22 -> 1 | Q22: 7512 | R22: =O22*Q22 -> 0
B23: SENIOR 3 CM SPECIALIST | C23: GSFC/HQ | E23: 1 | G23: =F23*(1+$E$9) -> 0 | J23: =I23*(1+$E$9) -> 0 | M23: =L23*(1+$E$9) -> 0 | O23: =(D23*E23)+(G23*H23)+(J23*K23)+(M23*N23) -> 0 | P23: =N23+K23+H23+E23 -> 1 | Q23: 31926 | R23: =O23*Q23 -> 0
B24: INTERMEDIATE DOCUMENTATION SPECIALIST | C24: GSFC/HQ | E24: 1 | G24: =F24*(1+$E$9) -> 0 | J24: =I24*(1+$E$9) -> 0 | M24: =L24*(1+$E$9) -> 0 | O24: =(D24*E24)+(G24*H24)+(J24*K24)+(M24*N24) -> 0 | P24: =N24+K24+H24+E24 -> 1 | Q24: 3756 | R24: =O24*Q24 -> 0
B25: HIGH DOCUMENTATION SPECIALIST | C25: GSFC/HQ | E25: 1 | G25: =F25*(1+$E$9) -> 0 | J25: =I25*(1+$E$9) -> 0 | M25: =L25*(1+$E$9) -> 0 | O25: =(D25*E25)+(G25*H25)+(J25*K25)+(M25*N25) -> 0 | P25: =N25+K25+H25+E25 -> 1 | Q25: 1878 | R25: =O25*Q25 -> 0
B26: SENIOR 1 DOCUMENTAION SPECIALIST | C26: GSFC/HQ | E26: 1 | G26: =F26*(1+$E$9) -> 0 | J26: =I26*(1+$E$9) -> 0 | M26: =L26*(1+$E$9) -> 0 | O26: =(D26*E26)+(G26*H26)+(J26*K26)+(M26*N26) -> 0 | P26: =N26+K26+H26+E26 -> 1 | Q26: 9390 | R26: =O26*Q26 -> 0
B27: SENIOR 2 DOCUMENTATION SPECIALIST | C27: GSFC/HQ | E27: 1 | G27: =F27*(1+$E$9) -> 0 | J27: =I27*(1+$E$9) -> 0 | M27: =L27*(1+$E$9) -> 0 | O27: =(D27*E27)+(G27*H27)+(J27*K27)+(M27*N27) -> 0 | P27: =N27+K27+H27+E27 -> 1 | Q27: 7512 | R27: =O27*Q27 -> 0
... B60: ASSOCIATE II | C60: GSFC/HQ | E60: 1 | G60: =F60*(1+$E$9) -> 0 | J60: =I60*(1+$E$9) -> 0 | M60: =L60*(1+$E$9) -> 0 | O60: =(D60*E60)+(G60*H60)+(J60*K60)+(M60*N60) -> 0 | P60: =N60+K60+H60+E60 -> 1 | Q60: 11865 | R60: =O60*Q60 -> 0
B61: WFF(Wallops / LaRC (Langley | C61: WFF/LaRC | R61: =SUM(R16:R60) -> 0
B62: SENIOR 2 ACCOUNTING SPECIALIST | C62: WFF/LaRC | E62: 1 | G62: =F62*(1+$D$9) -> 0 | J62: =I62*(1+$D$9) -> 0 | M62: =L62*(1+$D$9) -> 0 | O62: =(D62*E62)+(G62*H62)+(J62*K62)+(M62*N62) -> 0 | P62: =N62+K62+H62+E62 -> 1 | Q62: 5634 | R62: =O62*Q62 -> 0
B63: LOW CM SPECIALIST | C63: WFF/LaRC | E63: 1 | G63: =F63*(1+$D$9) -> 0 | J63: =I63*(1+$D$9) -> 0 | M63: =L63*(1+$D$9) -> 0 | O63: =(D63*E63)+(G63*H63)+(J63*K63)+(M63*N63) -> 0 | P63: =N63+K63+H63+E63 -> 1 | Q63: 1878 | R63: =O63*Q63 -> 0
B64: INTERMEDIATE CM SPECIALIST | C64: WFF/LaRC | E64: 1 | G64: =F64*(1+$D$9) -> 0 | J64: =I64*(1+$D$9) -> 0 | M64: =L64*(1+$D$9) -> 0 | O64: =(D64*E64)+(G64*H64)+(J64*K64)+(M64*N64) -> 0 | P64: =N64+K64+H64+E64 -> 1 | Q64: 7512 | R64: =O64*Q64 -> 0
B65: HIGH CM SPECIALIST | C65: WFF/LaRC | E65: 1 | G65: =F65*(1+$D$9) -> 0 | J65: =I65*(1+$D$9) -> 0 | M65: =L65*(1+$D$9) -> 0 | O65: =(D65*E65)+(G65*H65)+(J65*K65)+(M65*N65) -> 0 | P65: =N65+K65+H65+E65 -> 1 | Q65: 1878 | R65: =O65*Q65 -> 0
B66: SENIOR 1 CM SPECIALIST | C66: WFF/LaRC | E66: 1 | G66: =F66*(1+$D$9) -> 0 | J66: =I66*(1+$D$9) -> 0 | M66: =L66*(1+$D$9) -> 0 | O66: =(D66*E66)+(G66*H66)+(J66*K66)+(M66*N66) -> 0 | P66: =N66+K66+H66+E66 -> 1 | Q66: 1878 | R66: =O66*Q66 -> 0
B67: SENIOR 3 DOCUMENTATION SPECIALIST | C67: WFF/LaRC | E67: 1 | G67: =F67*(1+$D$9) -> 0 | J67: =I67*(1+$D$9) -> 0 | M67: =L67*(1+$D$9) -> 0 | O67: =(D67*E67)+(G67*H67)+(J67*K67)+(M67*N67) -> 0 | P67: =N67+K67+H67+E67 -> 1 | Q67: 1878 | R67: =O67*Q67 -> 0
B68: INTERMEDIATE GENERAL BUSINESS SPECIALIST | C68: WFF/LaRC | E68: 1 | G68: =F68*(1+$D$9) -> 0 | J68: =I68*(1+$D$9) -> 0 | M68: =L68*(1+$D$9) -> 0 | O68: =(D68*E68)+(G68*H68)+(J68*K68)+(M68*N68) -> 0 | P68: =N68+K68+H68+E68 -> 1 | Q68: 7512 | R68: =O68*Q68 -> 0
B69: HIGH GENERAL BUSINESS SPECIALIST | C69: WFF/LaRC | E69: 1 | G69: =F69*(1+$D$9) -> 0 | J69: =I69*(1+$D$9) -> 0 | M69: =L69*(1+$D$9) -> 0 | O69: =(D69*E69)+(G69*H69)+(J69*K69)+(M69*N69) -> 0 | P69: =N69+K69+H69+E69 -> 1 | Q69: 9390 | R69: =O69*Q69 -> 0
B70: SENIOR 2 GENERAL BUSINESS SPECIALIST | C70: WFF/LaRC | E70: 1 | G70: =F70*(1+$D$9) -> 0 | J70: =I70*(1+$D$9) -> 0 | M70: =L70*(1+$D$9) -> 0 | O70: =(D70*E70)+(G70*H70)+(J70*K70)+(M70*N70) -> 0 | P70: =N70+K70+H70+E70 -> 1 | Q70: 1878 | R70: =O70*Q70 -> 0
B71: SENIOR 3 GENERAL BUSINESS SPECIALIST | C71: WFF/LaRC | E71: 1 | G71: =F71*(1+$D$9) -> 0 | J71: =I71*(1+$D$9) -> 0 | M71: =L71*(1+$D$9) -> 0 | O71: =(D71*E71)+(G71*H71)+(J71*K71)+(M71*N71) -> 0 | P71: =N71+K71+H71+E71 -> 1 | Q71: 1878 | R71: =O71*Q71 -> 0
B72: JUNIOR SCHEDULING SPECIALIST | C72: WFF/LaRC | E72: 1 | G72: =F72*(1+$D$9) -> 0 | J72: =I72*(1+$D$9) -> 0 | M72: =L72*(1+$D$9) -> 0 | O72: =(D72*E72)+(G72*H72)+(J72*K72)+(M72*N72) -> 0 | P72: =N72+K72+H72+E72 -> 1 | Q72: 1878 | R72: =O72*Q72 -> 0
B73: LOW SCHEDULING SPECIALIST | C73: WFF/LaRC | E73: 1 | G73: =F73*(1+$D$9) -> 0 | J73: =I73*(1+$D$9) -> 0 | M73: =L73*(1+$D$9) -> 0 | O73: =(D73*E73)+(G73*H73)+(J73*K73)+(M73*N73) -> 0 | P73: =N73+K73+H73+E73 -> 1 | Q73: 5634 | R73: =O73*Q73 -> 0
... B78: SENIOR 3 SCHEDULING SPECIALIST | C78: WFF/LaRC | E78: 1 | G78: =F78*(1+$D$9) -> 0 | J78: =I78*(1+$D$9) -> 0 | M78: =L78*(1+$D$9) -> 0 | O78: =(D78*E78)+(G78*H78)+(J78*K78)+(M78*N78) -> 0 | P78: =N78+K78+H78+E78 -> 1 | Q78: 15024 | R78: =O78*Q78 -> 0
B79: Management and Administrative Labor Categories | R79: =SUM(R62:R78) -> 0
...

Sheet Exhibit 1A-6
B2: Proposing Entity:
B3: Offeror Name [ ] Prime ________________________________________________________
B4: EXHIBIT 1B [ PRIME OFFEROR]
B6: Non-Labor Recurring ODCs
B8: List each applicable Indirect Rate (e.g., G&A, Procurement Burden, Material Handling, etc.) and provide percentage. Add additional rows if needed. Please utilize unlocked formulas to compute Loaded ODC costs. Scroll down for further contract years.
D9: Contract Year 1
D10: Indirect Bid Rates/Expenses
B11: Other Direct Costs (By Element) | C11: Unburdened ODC Cost | D11: Material Handling | E11: G&A | F11: Subtotal | G11: Fee Rate: % | H11: Prime Offeror Loaded ODC Costs
D12: Rate: % | E12: Rate: %
B13: Example | C13: 20000 | D13: 0.01 | F13: =C13*(1+D13) -> 20200 | G13: 0.01 | H13: =F13*(1+G13) -> 20402
B14: Prime Offeror
B15: Materials:
B21: Travel:
B27: Other ODC's (Purchased by Prime)
B33: Subcontractor
B34: Materials:
B40: Travel:
B46: Other ODC's (Purchased by Subcontractor)
B52: TOTAL LOADED GPM-SPECIFIED ODC COSTS | H52: =SUM(H15:H51) -> 0
D54: Contract Year 2
D55: Indirect Bid Rates/Expenses
B56: Other Direct Costs (By Element) | C56: Unburdened ODC Cost | D56: Material Handling | E56: G&A | F56: Subtotal | G56: Fee Rate: % | H56: Prime Offeror Loaded ODC Costs
D57: Rate: % | E57: Rate: %
B58: Prime Offeror
B59: Materials:
B65: Travel:
B71: Other ODC's (Purchased by Prime)
B77: Subcontractor
B78: Materials:
B84: Travel:
B90: Other ODC's (Purchased by Subcontractor)
B96: TOTAL LOADED GPM-SPECIFIED ODC COSTS | H96: =SUM(H59:H95) -> 0
D98: Contract Year 3
D99: Indirect Bid Rates/Expenses
B100: Other Direct Costs (By Element) | C100: Unburdened ODC Cost | D100: Material Handling | E100: G&A | F100: Subtotal | G100: Fee Rate: % | H100: Prime Offeror Loaded ODC Costs
D101: Rate: % | E101: Rate: %
B102: Prime Offeror
B103: Materials:
B109: Travel:
B115: Other ODC's (Purchased by Prime)
...

Sheet Exhibit 1B
B1: DRFP# 80GSFC24R0042
B2: Proposing Entity:
B4: EXHIBIT 1B
B5: PRIME OFFEROR
B6: SUMMARY OF GOVERNMENT PRICING MODEL (GPM)
B8: Total Loaded Estimated Costs | C8: Contract Year 1 | D8: Contract Year 2 | E8: Contract Year 3 | F8: Contract Year 4 | G8: Contract Year 5 | H8: GRAND TOTAL
B9: GPM-Specified Non-Management GSFC/HQ Direct Labor Costs | C9: ='Exhibit 1A-1'!R61 -> 0 | D9: ='Exhibit 1A-2'!R61 -> 0 | E9: ='Exhibit 1A-3'!R61 -> 0 | F9: ='Exhibit 1A-4'!R61 -> 0 | G9: ='Exhibit 1A-5'!R61 -> 0 | H9: =SUM(C9:G9) -> 0
B10: GPM-Specified Non-Management WFF/LaRC Direct Labor Costs | C10: ='Exhibit 1A-1'!R79 -> 0 | D10: ='Exhibit 1A-2'!R79 -> 0 | E10: ='Exhibit 1A-3'!R79 -> 0 | F10: ='Exhibit 1A-4'!R79 -> 0 | G10: ='Exhibit 1A-5'!R79 -> 0 | H10: =SUM(C10:G10) -> 0
B11: Offeror Management and Administrative Labor Costs | C11: ='Exhibit 1A-1'!R97 -> 0 | D11: ='Exhibit 1A-2'!R97 -> 0 | E11: ='Exhibit 1A-3'!R97 -> 0 | F11: ='Exhibit 1A-4'!R97 -> 0 | G11: ='Exhibit 1A-5'!R97 -> 0 | H11: =SUM(C11:G11) -> 0
B12: Offeror Non-labor Recurring ODCs and/or Cost Estimating Relationship Costs | C12: ='Exhibit 1A-6'!H52 -> 0 | D12: ='Exhibit 1A-6'!H96 -> 0 | E12: ='Exhibit 1A-6'!H140 -> 0 | F12: ='Exhibit 1A-6'!H184 -> 0 | G12: ='Exhibit 1A-6'!H228 -> 0 | H12: =SUM(C12:G12) -> 0
B13: GRAND TOTAL GOVERNMENT PRICING MODEL | C13: =SUM(C9:C12) -> 0 | D13: =SUM(D9:D12) -> 0 | E13: =SUM(E9:E12) -> 0 | F13: =SUM(F9:F12) -> 0 | G13: =SUM(G9:G12) -> 0 | H13: =SUM(C13:G13) -> 0
B15: This exhibit contains Source Selection Information. See FAR 3.104.
