Workbook
Name _GoBack: 'IDIQ LOG FACILITIES'!#REF!
Name _GoBack: 'IDIQ LOG UTILITIES'!#REF!

Sheet IDIQ LOG FACILITIES
A1: WO Number | B1: Description | C1: Asset Number | D1: Bldg. | E1: Zone | F1: Site | G1: IDIQ Type | H1: LOL | I1: Status of Job | J1: Party Performing Work | K1: Work Order Received | L1: Date of Site Visit | M1: POP (days) | N1: Proposal Amount | O1: Submitted to Government | P1: Days with Jacobs | Q1: Days with Gov't | R1: Government Award Date | S1: Pre-Con Date | T1: Estimated Completion Date (ECD) | U1: Actual Completion Date | V1: QA Sign-Off | W1: PAR Sign-Off Date | X1: Invoice Date | Y1: Notes | Z1: Jacobs POC | AA1: Event
B5: FINISHED/Complete
B6: EXECUTION
B7: SUBMITTED
B8: FUNDED BY OTHERS | N8: =SUBTOTAL(9,N2:N7) -> 0
B9: IN-KIND
B10: WAITING FUNDING
B11: ON THE SHELF
B12: BREAK-DOWN LIST
B13: Cancelled

Sheet IDIQ LOG UTILITIES
A1: IDIQ Progress Log | G1: Suggested search technique: use filters to find work order # or bldg. #. Data may be hidden if filters are in place.
A2: As of: | B2: =TODAY() -> 45630 | G2: To clear filters, click "Data" tab on the top menu, "sort & filter" on the ribbon, then click "clear"
A4: Priority | B4: Critical Date | C4: Next Action | D4: WO Number | E4: Description | F4: Asset Number | G4: Bldg. | H4: Site | I4: Utility | J4: IDIQ Type | K4: LOL | L4: Status of Job | M4: Party Performing Work | N4: Work Order Received | O4: Date of Site Visit | P4: POP (days) | Q4: Proposal Amount | R4: Submitted to Government | S4: Days with Jacobs | T4: Days with Gov't | U4: Government Award Date | V4: Pre-Con Date | W4: Estimated Completion Date (ECD) | X4: Actual Completion Date | Y4: QA Sign-Off | Z4: PAR Sign-Off | AA4: Invoice Date | AB4: Notes | AC4: Jacobs POC | AD4: Event
E7: FINISHED/Complete | Q7: =SUBTOTAL(9,#REF!) -> #REF!
E8: EXECUTION
E9: SUBMITTED
E10: FUNDED BY OTHERS
E11: IN-KIND
E12: WAITING FUNDING
E13: ON THE SHELF
E14: BREAK-DOWN LIST
E15: Cancelled

Sheet REPORT
B1: current as of | C1: =TODAY() -> 45630
B3: FACILITIES
B4: Row Labels | C4: Count of Status of job | L4: Facilites | N4: Utilites | P4: BSVE
B5: Complete | C5: 10 | L5: Submitted | N5: Submitted | P5: Submitted
B6: Invoice Rejected | C6: 2 | L6: Start | M6: 45139 | N6: Start | O6: 45139 | P6: Start | Q6: 45139
B7: Invoiced | C7: 163 | L7: End | M7: 45169 | N7: End | O7: 45169 | P7: End | Q7: 45169
B8: Ready for Invoice | C8: 1 | L8: Count | M8: =COUNTIFS('IDIQ LOG FACILITIES'!O2:O5,">="&M6,'IDIQ LOG FACILITIES'!O2:O5,"<="&REPORT!M7) -> 0 | N8: Count | O8: =COUNTIFS(Table13[Submitted to Government],">="&O6,Table13[Submitted to Government],"<="&REPORT!O7) -> 0 | P8: Count | Q8: =COUNTIFS(#REF!,">="&Q6,#REF!,"<="&REPORT!Q7) -> #REF!
B9: Pending Invoice Approval | C9: 13
B10: Grand Total | C10: 189
L12: Facilites
L13: Funded
L14: Start | M14: 45139
L15: End | M15: 45169
L16: Count
L17: Amount | M17: 206373.97 | N17: 138783.95 | O17: 1650.48 | P17: =SUM(M17:O17) -> 346808.4
B23: UTILITIES
B24: Row Labels | C24: Count of Status of job
B25: Complete | C25: 10
B26: Invoiced | C26: 95 | L26: Sub-Total Function
B27: Pending Invoice Approval | C27: 8 | L27: Current Month Awards (filter on tabs needed) | O27: < | P27: 100000
B28: Ready for Invoice | C28: 1 | O28: 101000 | P28: 200000
B29: Grand Total | C29: 114 | L29: ='IDIQ LOG FACILITIES'!N8 -> 0 | M29: FAC | O29: 201000 | P29: 499999
L30: ='IDIQ LOG UTILITIES'!Q7 -> #REF! | M30: Utility | O30: 500000 | P30: 749999
B31: BSVE | L31: =#REF! -> #REF! | M31: BSVE | O31: > | P31: 750000
B32: Row Labels | C32: Count of Status of Job | L32: =SUM(L29:L31) -> #REF!
B33: Complete | C33: 17
B34: Invoiced | C34: 13
B35: Pending Invoice Approval | C35: 2
B36: Grand Total | C36: 32
B40: 43466 | C40: 43497 | D40: 43525 | E40: 43556 | F40: 43586 | G40: 43617 | H40: 43647 | I40: 43678 | J40: 43709 | K40: 43739 | L40: 43770 | M40: 43800 | N40: Total | P40: Average
B41: 3547019.5 | C41: 99514.06 | D41: 456845.21 | E41: 636385.41 | F41: 352474.77 | G41: 74525.59 | H41: 2500 | I41: 443726.71 | J41: 1192586.1 | K41: 23441.03 | L41: 96249.67 | M41: 99689 | N41: 7024957 | P41: 585413.08
B44: 43831 | C44: 43862 | D44: 43891 | E44: 43922 | F44: 43952 | G44: 43983 | H44: 44013 | I44: 44044 | J44: 44075 | K44: 44105 | L44: 44136 | M44: 44166
B45: 22353.71 | C45: 120360.16 | D45: 91058.98 | E45: 408385.42 | F45: 116224.24 | G45: 329898.97 | H45: 75557.16 | I45: 438344.98 | J45: 370831.12 | K45: 261249.95 | L45: 132894.9 | M45: 112255.58 | N45: 2479415.2 | P45: 206617.93
B48: 44197 | C48: 44228 | D48: 44256 | E48: 44287 | F48: 44317 | G48: 44348 | H48: 44378 | I48: 44409 | J48: 44440 | K48: 44470 | L48: 44501 | M48: 44531
B49: 95988.79 | C49: 213503.98 | D49: 1125889 | E49: 254936.55 | F49: 361807.96 | G49: 208327.22 | H49: 309473.12 | I49: 141955.17 | J49: 745110.96 | K49: 235839.97 | L49: 61809.91 | M49: 360457.07 | N49: 4115099.7 | P49: 342924.98
B52: 44562 | C52: 44593 | D52: 44621 | E52: 44652 | F52: 44682 | G52: 44713 | H52: 44743 | I52: 44774 | J52: 44805 | K52: 44835 | L52: 44866 | M52: 44896
B53: 506195.78 | C53: 289194.7 | D53: 1666245.8 | E53: 30929.71 | F53: 23230.63 | G53: 89283.41 | H53: 58919.02 | I53: 260016.28 | J53: 489356.65 | K53: 362299 | L53: 161420.87 | M53: 1162416.4 | N53: 5099508.3 | P53: 424959.03
K54: 4720
I55: 45161 | K55: 357579
B56: 44927 | C56: 44958 | D56: 44986 | E56: 45017 | F56: 45047 | G56: 45078 | H56: 45108 | I56: 45139 | J56: 45170 | K56: 45200 | L56: 45231 | M56: 45261 | Q56: Annualized
...

Sheet Breakdown
A1: WO Number | B1: Description | C1: Asset Number | D1: Bldg. | E1: Zone | F1: Site | G1: IDIQ type | H1: LOL | I1: Status of Job | J1: Party Performing Work | K1: Work Order Received | L1: Date of Site Visit | M1: POP (days) | N1: Proposal Amount | O1: Submitted to Government | P1: Days with Jacobs | Q1: Days with Gov't | R1: Government Award Date | S1: Pre-Con Date | T1: Estimated Completion Date (ECD) | U1: Actual Completion Date | V1: QA Sign-Off | W1: PAR Sign-Off Date | X1: Invoice Date | Y1: Notes | Z1: Jacobs POC
B2: Compressor Air | C2: MYP-2025-VAC-01 | D2: MAYPOR-2025 | G2: BREAKDOWN | I2: BREAKDOWN | J2: Tagged out of service, inoperable | Y2: Tagged out of service, inoperable | Z2: Dave Strickland
B3: Compressor Air - Heckscher Fuel Farm | C3: A134426 | D3: MAYFISC-104 | G3: BREAKDOWN | I3: BREAKDOWN | J3: Inoperable, controller needs to be replaced. IDIQ work order 853187 waiting approval | Y3: Inoperable, controller needs to be replaced. IDIQ work order 853187 waiting approval WO 1339745 servicing temp compressor until original is fixed | Z3: Dave Strickland
B4: Air Compressor #1 | C4: A131094 | D4: MAYPOR-1586 | G4: BREAKDOWN | I4: BREAKDOWN | J4: Abandoned, electronic controls installed | Y4: Abandoned, electronic controls installed | Z4: Dave Strickland
B5: Air Compressor #2 | C5: A131095 | D5: MAYPOR-1586 | G5: BREAKDOWN | I5: BREAKDOWN | J5: Abandoned, electronic controls installed | Y5: Abandoned, electronic controls installed | Z5: Dave Strickland
B6: Air Compressor #1 | C6: A131081 | D6: MAYPOR-1585 | G6: BREAKDOWN | I6: BREAKDOWN | J6: Abandoned, electronic controls installed | Y6: Abandoned, electronic controls installed | Z6: Dave Strickland
B7: Air Compressor #2 | C7: A131082 | D7: MAYPOR-1585 | G7: BREAKDOWN | I7: BREAKDOWN | J7: Abandoned, electronic controls installed | Y7: Abandoned, electronic controls installed | Z7: Dave Strickland
B8: Air Compressor (For Control Air) | C8: A131118 | D8: MAYPOR-1587 | G8: BREAKDOWN | I8: BREAKDOWN | J8: Abandoned, electronic controls installed | Y8: Abandoned, electronic controls installed | Z8: Dave Strickland
B9: Air Compressor (For Control Air) | C9: A131119 | D9: MAYPOR-1587 | G9: BREAKDOWN | I9: BREAKDOWN | J9: Abandoned, electronic controls installed | Y9: Abandoned, electronic controls installed | Z9: Dave Strickland
B10: Compressor - Drier Air - Chapel | C10: A116040 | D10: MAYPOR-350 | G10: BREAKDOWN | I10: BREAKDOWN | J10: Does not exist, removed | Y10: Does not exist, removed | Z10: Dave Strickland
B11: PM - Roll Gate 191 East - DLA | C11: MYP-191-RG-02 | D11: MAYPOR-191 | G11: BREAKDOWN | I11: BREAKDOWN | J11: Electric gate - inoperable due to bad control board. IDIQ WO 919593 sent for approval- Ricky Shepheard cancelled request on 4/30/21. | Y11: Electric gate - inoperable due to bad control board. IDIQ WO 919593 sent for approval- Ricky Shepheard cancelled request on 4/30/21. | Z11: Dave Strickland
B12: Door Powered R/U #1 of 6 | C12: MYP-1430-EOD-01 | D12: MAYPOR-1430 | G12: BREAKDOWN | I12: BREAKDOWN | J12: Corroded, no longer functional, IDIQ work order 1492882 waiting approval | Y12: Corroded, no longer functional, IDIQ work order 1492882 waiting approval | Z12: Dave Strickland
B13: Door Powered R/U #2 of 6 | C13: MYP-1430-EOD-02 | D13: MAYPOR-1430 | G13: BREAKDOWN | I13: BREAKDOWN | J13: Corroded, no longer functional, IDIQ work order 1492882 waiting approval | Y13: Corroded, no longer functional, IDIQ work order 1492882 waiting approval | Z13: Dave Strickland
... B53: Aboveground Tank - Bldg. 1587 - Fuel Oil, Heating, Tank 2287, 4000 Gallons (Zone 1) | C53: A117489 | D53: MAYPOR-1587 | G53: BREAKDOWN | I53: BREAKDOWN | J53: Tank emptied and closed/abandoned in place | Y53: Should be removed from 1502000-25 in future mod | Z53: Dave Strickland
B54: Backflow Devices 1"-RP - South Of Building At Fence, Tag #183 | C54: A117626 | D54: MAYFISC-38 | G54: BREAKDOWN | I54: BREAKDOWN | J54: Abandoned, no water supply to device
B55: Backflow Devices 1"-RP - West Side Of Building, Tag #200 | C55: A117625 | D55: MAYFISC-25 | G55: BREAKDOWN | I55: BREAKDOWN | J55: MAYFISC-25 demolished and replaced with MAYFISC-2669, backflow removed
B56: Aboveground Tank - Oily Waste Water - 1442-3, 303,453 Gallons (Zone 4) | C56: A125012 | D56: MAYPOR-1442 | G56: BREAKDOWN | I56: BREAKDOWN | J56: Tank is empty and no longer used.
B57: Underground Tank - Bldg. 1585 - Fuel Oil, Heating, N1585, 5000 Gallons (Zone 1) | C57: A117487 | D57: MAYPOR-1585 | G57: BREAKDOWN | J57: Tank is empty and no longer used.
B58: Underground Tank - Bldg. 1586 - Fuel Oil, Heating, N1586, 5000 Gallons (Zone 1) | C58: A117488 | D58: MAYPOR-1586 | G58: BREAKDOWN | J58: Tank is empty and no longer used.
B59: Aboveground Tank - Bldg. 191 - Fuel Oil, Heating - Tank N191B, 350 Gallon (Zone 1) | C59: A117457 | D59: MAYPOR-191 | G59: BREAKDOWN | J59: Tank is empty and no longer used.
B60: Aboveground Tank - Bldg. 234 - Used Oil - Tank N234C, 560 Gallons (Zone 2) | C60: A117496 | D60: MAYPOR-234 | G60: BREAKDOWN | J60: This tank has been closed.
B61: Aboveground Tank - Bldg. 25 (Zone 2) - Used Oil - Tank 25, 500 Gallon | C61: A117493 | D61: MAYPOR-25 | G61: BREAKDOWN | J61: This tank has been closed.
B62: Aboveground Tank - Bldg. 298 - Fuel Oil, Heating, N298, 1000 Gallons (Zone 1) | C62: A117462 | D62: MAYPOR-25 | G62: BREAKDOWN | J62: Tank is empty and no longer used.
B63: Underground Tank - Bldg. 338 - Fuel Oil, Heating, 338A, 5000 Gallons (Zone 1) | C63: A117463 | D63: MAYPOR-338 | G63: BREAKDOWN | J63: Tank is empty and no longer used.
B64: Backflow Devices -DCVA 2"- West side of bldg., Tag # 393 | C64: A124785 | D64: MAYPOR-1316 | G64: BREAKDOWN | J64: Removed and capped off
B65: Backflow Devices -DCVA 1.5"- East side of Mayport rd, north of bldg. 1962, Device #725 | C65: A124988 | D65: MAYPOR-GROUNDS | G65: BREAKDOWN | J65: Removed after a tree fell on the guard shack and the station was removed. Also listed on 1502000-22 at facility #1962.
B66: Underground Tank - Bldg. 1613 - Used Oil - N1863 1000 Gal (Zone 4) | C66: A117507 | D66: MAYPOR-1613 | G66: BREAKDOWN | J66: Tank removed and not replaced
B67: Valve #1021 Montreal St. North of Assisi Lane South valve 8" | C67: A124588 | D67: MAYPOR-WTR-VLV | G67: BREAKDOWN | J67: Inoperable
B68: Valve #1022 Montreal St. North of Assisi Lane East valve 8" | C68: A124589 | D68: MAYPOR-WTR-VLV | G68: BREAKDOWN | J68: Inoperable

Sheet Dropdown lists
B3: dropdown menu lists: | D3: Site | E3: Utility | H3: IDIQ type | J3: Action menu | L3: Status Menu | M3: Party | O3: Priority | R3: Jacobs POC
D4: HVAC Mayport | E4: Electrical | H4: O&A ROM | J4: Jacobs | L4: Planning | M4: Jacobs | O4: 1 | R4: John Armstrong
D5: Electrical Mayport | E5: Port Ops | H5: RFP | J5: Government | L5: In Scoping -Ops | M5: Subcontractor | O5: 2 | R5: Joe Keeler
D6: Mech Mayport | E6: High Voltage | H6: O&A RFP | L6: In Sub-Contracts | R6: Rae Hosler
D7: Carp Mayport | E7: Steam | H7: CAT-1 | L7: RFI's to Gov't | M7: TBD | O7: 3 | R7: Alex Reyes
D8: Plumbing Mayport | E8: Water | H8: CAT-2 | L8: Proposal under Review by Jacobs MGT | M8: Jacobs & Sub | R8: IDIQ Team
D9: Painting Mayport | E9: Waste Water | H9: CAT-3 | J9: N/A | L9: Proposal Preparation | R9: Jarrad Hampton
D10: Combined Shops Mayport | E10: Enviro | H10: CAT-4 | L10: Submitted | R10: Nolan Green
D11: Facilities | E11: Mechanic | L11: RFI's from Gov't | R11: Cheryl Miller
D12: Misc Utility | E12: Misc Utility
D13: Pool | E13: OWWO | L13: Revalidation | R13: MBOS PM
D14: Piers | E14: Various | H14: RFP Storm | L14: Execution | R14: Gene T
D15: HVAC Controls | E15: Misc Utility | H15: TO | L15: Complete | R15: Colette Snelling
D16: Environmental | H16: REA | L16: Waiting Material | R16: Mark Killmer
D17: Fire & Safety | H17: ER | L17: Hold | R17: Accounting
D18: Misc Utility | H18: INT | L18: Cancelled
D19: Fuel Farm | H19: PM-CM | L19: Finished
H20: IN-KIND | L20: Rework
H21: BREAKDOWN | L21: Invoiced | O21: Gov't Review
H22: ROM | L22: Ready for Invoice | X22: .
L23: Pending Invoice Approval
H24: Outside Contract Direct Pay | L24: Waiting Funding
L25: On the Shelf
L26: Invoice Rejected
L28: Breakdown
L29: Template row
L30: Declined/ Canceled
