Workbook
Name A10_List: _xlfn.TEXTJOIN(",",TRUE,IF(LEFT(#REF!,3)=LEFT('Asset Data'!$N$2,3),#REF!,""))
Name condition_code: 'Value Lists'!$G$3:$G$7
Name dd_component: #REF!
Name dd_mastersys: 'Value Lists'!$X$2:$X$46
Name dd_subsystem: #REF!
Name dd_system: #REF!
Name itemset: 'Value Lists'!$O$1:$O$21
Name Meter: 'Value Lists'!$AA$2:$AA$15
Name Meter_Group: 'Value Lists'!$AE$2:$AE$5
Name site: 'Value Lists'!$M$1:$M$21
Name Status: 'Value Lists'!$D$10:$D$12
Name YorN: 'Value Lists'!$D$3:$D$4

Sheet Instructions
A1: General Instructions
A2: This template can be used to insert new records or update existing records in USMCmax. Carefully review the information on this tab and the field descriptions before entering information on the data tab. Separate templates should be used to add new assets or update existing assets
A3: Asset Data Tab
A4: Enter a row for each asset to be added to USMCmax. The color code of the field indicates the information requirements. If the fields are not properly populated with data, that record will not be loaded / updated in USMCmax, and the spreadsheet will be returned for correction
A5: Indicates the field is required by the program business logic or current business practices - When an asset description is entered, the data fields will highlight in red until a value is entered. If a value can not be determined an explanation must be entered in the comments column.
A6: Indicates the field is optional and the data entered will depend on prescribed business processes. If a default value is shown for the field the field can be left blank and the default value will be used
A7: Indicates the field is populated by logic and is not editable
A8: Specification Tab
A9: Enter the asset attribute details on the specification Data tab. When a classification is entered for the asset on the asset data tab, the classification and attributes will populate on the corresponding row on the specification data tab. Enter the attribute details for each asset. If there is no classification enter the pertinent attribute data as available. Additional classifications may be requested.
A11: Some fields are associated with a value lists, others are free text. If the attribute values are free text the field will be highlighted. If a value list is associated with the field, you must select from the provided list.
A13: The comments column is used to provide additional information about the asset, or to identify data issues. As an example, if the serial number (a required field) was illegible, it would be noted in the comment field. If a specification attribute value is not on the associated it should be identified here.

Sheet Field description
A1: Database field name | B1: Field Label | C1: Comments on data field | D1: Default | E1: Value list | G1: Mapping eOMSI to USMCmax
B2: Template ID | G2: eOMSI | J2: USMCmax
A3: SITEID | B3: Site | C3: Site id for the installation | E3: Site | G3: 1 | H3: AssetNum | J3: Asset Tag
A4: ASSETNUM | B4: Asset Number (Enter value or enter Auto to auto number) | C4: Asset numbers can be auto generated by the system (recommend) or manually entered by the user | G4: 2 | H4: Description | J4: Description
A5: DESCRIPTION | B5: Asset Description | C5: Description of the asset. Utilize the standard naming convention when possible | G5: 3 | H5: Long Description | J5: Long Description
A6: DESCRIPTION_LONGDESCRIPTION | B6: Long Description | C6: Additional information about the asset. Do not cut and paste, avoid using special characters | G6: 4 | H6: MASTERSYSTEM | J6: Master System
A7: HASLD | B7: Has Long Description (0= No, 1 = Yes - Default = 0) | C7: If the Long description field is populated the Value will default to 1, if the field is blank it will defaultto= 0) (Read Only) | D7: 0 | G7: 5 | H7: SYSTEM | J7: System
A8: LOCATION | B8: Location (Must Exist In USMCmax Location application) | C8: The location the asset is assigned to. The location must exist in the USMCmax Locations application | G8: 6 | H8: SUBSYSTEM | J8: Sub System
A9: EQ1 | B9: Asset Specific Location | C9: Additional information to help locate the asset. Ex. North side of roof | G9: 7 | H9: Building Number | J9: Location
A10: ASSETTYPE | B10: Asset Type | C10: The type of asset | E10: Asset Type | G10: 8 | H10: Asset Quantity | J10: Quantity / Unit of Measure
A11: MANUFACTURER | B11: Manufacturer (Must Exist in USMCMax Company application) | C11: The company that manufactured the asset. The value must come from the USMCmax Companies application | G11: 9 | H11: Replacement Cost | J11: Purchase Price
A12: EQ13 | B12: Model # (From name plate data) | C12: From name plate data | G12: 10 | H12: Contract Number | J12: Contract #
A13: SERIALNUM | B13: Serial Number (From name plate data) | C13: Serial number from the name plate data | G13: 11 | H13: Task/Delivery Order Number | J13: Task Order #
A14: FAILURECODE | B14: Failure Code (Select From Value List) | C14: Failure code associated with this asset | E14: Failure Code | G14: 12 | H14: Warranty Expiration Date | J14: Warranty Expiration Date
A15: MASTERSYS | B15: Master System | C15: Master System from Uniformat tables. Select from value list | E15: Master System | G15: 13 | H15: Installation Date | J15: Date Installaled
A16: SYSTEM | B16: System | C16: System from Uniformat tables. Select from value list | E16: System | G16: 14 | H16: Room Number | J16: Asset Specific Location
A17: SUBSYS | B17: Sub System | C17: Sub System from Uniformat tables. Select from value list | E17: Sub-System | G17: 15 | H17: Manufacturer | J17: Manufacturer
A18: COMP_TYPE | B18: Component | C18: Component from Uniformat tables. Select from value list | E18: Component | G18: 16 | H18: Model | J18: Model #
A19: XX_VALIDATEDATE | B19: Date Validated | C19: Date the asset was validated | G19: 17 | H19: Serial # | J19: Serial Number
A20: MASTERSYS | B20: Contract number | C20: Contract number the asset was purchased under
A21: SYSTEM | B21: Task order | C21: Task order the asset was purchased under
A22: SUBSYS | B22: Quantity | C22: Quantity of assets the record represents. If the record is for flourecent lights the quantity would be the number of light fixtures. | D22: 1
A23: COMP_TYPE | B23: Unit of Measure (Default Value = EA) | C23: Unit of measure. | D23: EA
A24: HIERARCHYPATH | B24: Classification Hierarchy | C24: The classification path for the asset. The path can contain one or more levels | E24: Hierarchy
A25: CLASSSTRUCTUREID | B25: Classstructureid | C25: The numeric value for the classificaiton (read only)
A26: XX_OWNERGROUP | B26: Owner Group (Must exist in the USMCmax Person Group application) | C26: Person group responsible for the asset. Must be a valid Person Group in USMCmax
A27: METER | B27: Meter | C27: A single meter associated with the asset | E27: Meter
A28: METER | B28: Meter Group | C28: The meter group associated with the asset | E28: Meter Group
A29: VENDOR | B29: Vendor (Must Exist in USMCmax Company application) | C29: The vendor the asset was purchased from
A30: EQ23 | B30: Date Received | C30: Date Asset was received at the installation. It may be different than the Date installed if they asset is held in inventory as a spare
A31: INSTALLDATE | B31: Date Installed | C31: Date the asset was installed. May be the same as the Date Asset Received Value
A32: WARRANTYEXPDATE | B32: Warranty Expiration date | C32: Date the warranty expires on the asset. Warranty information should be entered in the Warranty Contracts application
A33: EQ11 | B33: Asset Condition Code | C33: The condition of the asset base on visual inspection | E33: Asset Condition Code
A34: PRIORITY | B34: Priority | C34: Mission related priority of the asset | E34: Priority
A35: PARENT | B35: Parent Asset (Must exist in USMCmax Asset application on in this list) | C35: If the asset has a parent asset enter the parent asset number
A36: HASPARENT | B36: Has Parent (0= No, 1 = Yes - Default = 0) | C36: If the Parent field is populated the field will default to 1. if the parent field is blank the field will default to 0 (Read only) | D36: 0 | E36: Yes or No
A37: HASCHILDREN | B37: Has Children (0= No, 1 = Yes - Default = 0) | C37: If the asset has child assets enter 1 if not enter 0 or leave blank | D37: 0 | E37: Yes or No
A38: PURCHASEPRICE | B38: Purchase Price | C38: Price paid for the asset at time of purchase | D38: 0
A39: REPLACECOST | B39: Replacement Cost | C39: Cost to replace the asset | D39: 0
A40: STATUS | B40: Status Default = NOT READY | C40: The current status of the asset | D40: NOT READY | E40: Status
...

Sheet Asset Data
A1: Template ID | B1: Site | C1: Asset Number (Enter value or enter Auto to auto number) | D1: Asset Description | E1: Long Description | F1: Has Long Description (0= No, 1 = Yes - Default = 0) | G1: Location (Must Exist In USMCmax Location application) | H1: Asset Specific Location | I1: Asset Type | J1: Manufacturer (Must Exist in USMCMax Company application) | K1: Model # (From name plate data) | L1: Serial Number (From name plate data) | M1: Failure Code (Select From Value List) | N1: Master System | O1: System | P1: Sub System | Q1: Component | R1: Date Validated | S1: Contract number | T1: Task order | U1: Quantity | V1: Unit of Measure (Default Value = EA) | W1: Classification Hierarchy | X1: Classstructureid | Y1: Owner Group (Must exist in the USMCmax Person Group application) | Z1: Meter | AA1: Meter Group | AB1: Vendor (Must Exist in USMCmax Company application) | AC1: Date Received | AD1: Date Installed | AE1: Warranty Expiration date | AF1: Asset Condition Code | AG1: Priority | AH1: Parent Asset (Must exist in USMCmax Asset application on in this list) | AI1: Has Parent (0= No, 1 = Yes - Default = 0) | AJ1: Has Children (0= No, 1 = Yes - Default = 0) | AK1: Purchase Price | AL1: Replacement Cost | AM1: Status Default = NOT READY | AN1: Status Date | AO1: Asset Tag # | AP1: UEM Location ( Utility Assets Only) | AQ1: Comments
A2: Sample Data | B2: YU | C2: PW-025187 | D2: Air Cooled Condenser | E2: Enter additional information for the long descrition field. Do not copy text with formatting | F2: 1 | G2: 622 | H2: SERVER 156 | I2: FACILITIES | J2: CARRIER | K2: PX023UA1AD | L2: 1625KLT58648 | M2: Air Cooled Conderser | N2: D30-HVAC | O2: D3030-COOLING GENERATING SYSTEMS | P2: D303002-DIRECT EXPANSION SYSTEMS | Q2: D303002-Condenser, DX, Air Cooled | R2: 44535 | U2: 1 | V2: EA | W2: Air Conditioner Condenser Unit | X2: 1002 | AB2: ACME AC | AC2: 43871 | AD2: 43871 | AE2: 44237 | AF2: 2 | AG2: 2 | AI2: 0 | AK2: 2500 | AL2: 2750 | AM2: OPERATING | AN2: 43871 | AO2: ACCOND3
A3: 1 | F3: =IF(ISBLANK(B3),"",IF(ISBLANK(E3),0,1)) | X3: =IFERROR(VLOOKUP(W3,Specifications!A:B,2,FALSE),"") | AI3: =IF(ISBLANK(B3),"",IF(ISBLANK(AH3),0,1))
A4: 2 | F4: =IF(ISBLANK(B4),"",IF(ISBLANK(E4),0,1)) | X4: =IFERROR(VLOOKUP(W4,Specifications!A:B,2,FALSE),"") | AI4: =IF(ISBLANK(B4),"",IF(ISBLANK(AH4),0,1))
A5: 3 | F5: =IF(ISBLANK(B5),"",IF(ISBLANK(E5),0,1)) | X5: =IFERROR(VLOOKUP(W5,Specifications!A:B,2,FALSE),"") | AI5: =IF(ISBLANK(B5),"",IF(ISBLANK(AH5),0,1))
A6: 4 | F6: =IF(ISBLANK(B6),"",IF(ISBLANK(E6),0,1)) | X6: =IFERROR(VLOOKUP(W6,Specifications!A:B,2,FALSE),"") | AI6: =IF(ISBLANK(B6),"",IF(ISBLANK(AH6),0,1))
A7: 5 | F7: =IF(ISBLANK(B7),"",IF(ISBLANK(E7),0,1)) | X7: =IFERROR(VLOOKUP(W7,Specifications!A:B,2,FALSE),"") | AI7: =IF(ISBLANK(B7),"",IF(ISBLANK(AH7),0,1))
A8: 6 | F8: =IF(ISBLANK(B8),"",IF(ISBLANK(E8),0,1)) | X8: =IFERROR(VLOOKUP(W8,Specifications!A:B,2,FALSE),"") | AI8: =IF(ISBLANK(B8),"",IF(ISBLANK(AH8),0,1))
A9: 7 | F9: =IF(ISBLANK(B9),"",IF(ISBLANK(E9),0,1)) | X9: =IFERROR(VLOOKUP(W9,Specifications!A:B,2,FALSE),"") | AI9: =IF(ISBLANK(B9),"",IF(ISBLANK(AH9),0,1))
A10: 8 | F10: =IF(ISBLANK(B10),"",IF(ISBLANK(E10),0,1)) | X10: =IFERROR(VLOOKUP(W10,Specifications!A:B,2,FALSE),"") | AI10: =IF(ISBLANK(B10),"",IF(ISBLANK(AH10),0,1))
A11: 9 | F11: =IF(ISBLANK(B11),"",IF(ISBLANK(E11),0,1)) | X11: =IFERROR(VLOOKUP(W11,Specifications!A:B,2,FALSE),"") | AI11: =IF(ISBLANK(B11),"",IF(ISBLANK(AH11),0,1))
A12: 10 | F12: =IF(ISBLANK(B12),"",IF(ISBLANK(E12),0,1)) | X12: =IFERROR(VLOOKUP(W12,Specifications!A:B,2,FALSE),"") | AI12: =IF(ISBLANK(B12),"",IF(ISBLANK(AH12),0,1))
A13: 11 | F13: =IF(ISBLANK(B13),"",IF(ISBLANK(E13),0,1)) | X13: =IFERROR(VLOOKUP(W13,Specifications!A:B,2,FALSE),"") | AI13: =IF(ISBLANK(B13),"",IF(ISBLANK(AH13),0,1))
A14: 12 | F14: =IF(ISBLANK(B14),"",IF(ISBLANK(E14),0,1)) | X14: =IFERROR(VLOOKUP(W14,Specifications!A:B,2,FALSE),"") | AI14: =IF(ISBLANK(B14),"",IF(ISBLANK(AH14),0,1))
... A502: 500 | F502: =IF(ISBLANK(B502),"",IF(ISBLANK(E502),0,1)) | X502: =IFERROR(VLOOKUP(W502,Specifications!A:B,2,FALSE),"") | AI502: =IF(ISBLANK(B502),"",IF(ISBLANK(AH502),0,1))

Sheet Specification Data
A1: template ID # | B1: assetnum | C1: Classtructureid | D1: Hierarchy | E1: Attribute 1 | F1: Value | G1: attribute 2 | H1: Value | I1: Attribute 3 | J1: Value | K1: Attribute 4 | L1: Value | M1: Attribute 5 | N1: Value | O1: Attribute 6 | P1: Value | Q1: Attribute 7 | R1: Value | S1: Attribute 8 | T1: Value | U1: Attribute 9 | V1: Value | W1: Attribute 10 | X1: Value | Y1: Attribute 11 | Z1: Value | AA1: Attribute 12 | AB1: Value | AC1: Attribute 13 | AD1: Value | AE1: Attribute 14 | AF1: Value | AG1: Attribute 15 | AH1: Value | AI1: Attribute 16 | AJ1: Value | AK1: Attribute 17 | AL1: Value | AM1: Attribute 18 | AN1: Value | AO1: Attribute 19 | AP1: Value | AQ1: Attribute 20 | AR1: Value | AS1: Attribute 21 | AT1: Value | AU1: Attribute 22 | AV1: Value | AW1: Attribute 23 | AX1: Value | AY1: Attribute 24 | AZ1: Value | BA1: Attribute 25 | BB1: Value | BC1: Attribute 26 | BD1: Value | BE1: Attribute 27 | BF1: Value | BG1: Attribute 28 | BH1: Value | BI1: Attribute 29 | BJ1: Value | BK1: Attribute 30 | BL1: Value | BM1: Attribute 31 | BN1: Value | BO1: Attribute 32 | BP1: Value | BQ1: Attribute 33 | BR1: Value | BS1: Attribute 34 | BT1: Value | BU1: Attribute 35 | BV1: Value | BW1: Attribute 36 | BX1: Value | BY1: Attribute 37 | BZ1: Value | CA1: Attribute 38 | CB1: Value | CC1: Attribute 39 | CD1: Value | CE1: Attribute 40 | CF1: Value | CG1: Attribute 41 | CH1: Value | CI1: Attribute 42 | CJ1: Value | CK1: Attribute 43 | CL1: Value | CM1: Attribute 44 | CN1: Value | CO1: Attribute 45 | CP1: Value | CQ1: Attribute 46 | CR1: Value | CS1: Attribute 47 | CT1: Value
A2: =IF(ISBLANK('Asset Data'!C3),0,'Asset Data'!A3) -> 0 | B2: =IF($A2<1,"",VLOOKUP($A2,'Asset Data'!$A:$C,3,FALSE)) | C2: =IF(A2<1,"",VLOOKUP(D2,Specifications!A:B,2,FALSE)) | D2: =IF(A2<1,"",VLOOKUP(A2,'Asset Data'!A:W,23,FALSE)) | E2: =IF($A2<1,"",VLOOKUP($D2,Specifications!$A:$AX,4,FALSE)) | G2: =IF($A2<1,"",VLOOKUP($D2,Specifications!$A:$AX,5,FALSE)) | I2: =IF($A2<1,"",VLOOKUP($D2,Specifications!$A:$AX,6,FALSE)) | K2: =IF($A2<1,"",VLOOKUP($D2,Specifications!$A:$AX,7,FALSE)) | M2: =IF($A2<1,"",VLOOKUP($D2,Specifications!$A:$AX,8,FALSE)) | O2: =IF($A2<1,"",VLOOKUP($D2,Specifications!$A:$AX,9,FALSE)) | Q2: =IF($A2<1,"",VLOOKUP($D2,Specifications!$A:$AX,10,FALSE)) | S2: =IF($A2<1,"",VLOOKUP($D2,Specifications!$A:$AX,11,FALSE)) | U2: =IF($A2<1,"",VLOOKUP($D2,Specifications!$A:$AX,12,FALSE)) | W2: =IF($A2<1,"",VLOOKUP($D2,Specifications!$A:$AX,13,FALSE)) | Y2: =IF($A2<1,"",VLOOKUP($D2,Specifications!$A:$AX,14,FALSE)) | AA2: =IF($A2<1,"",VLOOKUP($D2,Specifications!$A:$AX,15,FALSE)) | AC2: =IF($A2<1,"",VLOOKUP($D2,Specifications!$A:$AX,16,FALSE)) | AE2: =IF($A2<1,"",VLOOKUP($D2,Specifications!$A:$AX,17,FALSE)) | AG2: =IF($A2<1,"",VLOOKUP($D2,Specifications!$A:$AX,18,FALSE)) | AI2: =IF($A2<1,"",VLOOKUP($D2,Specifications!$A:$AX,19,FALSE)) | AK2: =IF($A2<1,"",VLOOKUP($D2,Specifications!$A:$AX,20,FALSE)) | AM2: =IF($A2<1,"",VLOOKUP($D2,Specifications!$A:$AX,21,FALSE)) | AO2: =IF($A2<1,"",VLOOKUP($D2,Specifications!$A:$AX,22,FALSE)) | AQ2: =IF($A2<1,"",VLOOKUP($D2,Specifications!$A:$AX,23,FALSE)) | AS2: =IF($A2<1,"",VLOOKUP($D2,Specifications!$A:$AX,24,FALSE)) | AU2: =IF($A2<1,"",VLOOKUP($D2,Specifications!$A:$AX,25,FALSE)) | AW2: =IF($A2<1,"",VLOOKUP($D2,Specifications!$A:$AX,26,FALSE)) | AY2: =IF($A2<1,"",VLOOKUP($D2,Specifications!$A:$AX,27,FALSE)) | BA2: =IF($A2<1,"",VLOOKUP($D2,Specifications!$A:$AX,28,FALSE)) | BC2: =IF($A2<1,"",VLOOKUP($D2,Specifications!$A:$AX,29,FALSE)) | BE2: =IF($A2<1,"",VLOOKUP($D2,Specifications!$A:$AX,30,FALSE)) | BG2: =IF($A2<1,"",VLOOKUP($D2,Specifications!$A:$AX,31,FALSE)) | BI2: =IF($A2<1,"",VLOOKUP($D2,Specifications!$A:$AX,32,FALSE)) | BK2: =IF($A2<1,"",VLOOKUP($D2,Specifications!$A:$AX,33,FALSE)) | BM2: =IF($A2<1,"",VLOOKUP($D2,Specifications!$A:$AX,34,FALSE)) | BO2: =IF($A2<1,"",VLOOKUP($D2,Specifications!$A:$AX,35,FALSE)) | BQ2: =IF($A2<1,"",VLOOKUP($D2,Specifications!$A:$AX,36,FALSE)) | BS2: =IF($A2<1,"",VLOOKUP($D2,Specifications!$A:$AX,37,FALSE)) | BU2: =IF($A2<1,"",VLOOKUP($D2,Specifications!$A:$AX,38,FALSE)) | BW2: =IF($A2<1,"",VLOOKUP($D2,Specifications!$A:$AX,39,FALSE)) | BY2: =IF($A2<1,"",VLOOKUP($D2,Specifications!$A:$AX,40,FALSE)) | CA2: =IF($A2<1,"",VLOOKUP($D2,Specifications!$A:$AX,41,FALSE)) | CC2: =IF($A2<1,"",VLOOKUP($D2,Specifications!$A:$AX,42,FALSE)) | CE2: =IF($A2<1,"",VLOOKUP($D2,Specifications!$A:$AX,43,FALSE)) | CG2: =IF($A2<1,"",VLOOKUP($D2,Specifications!$A:$AX,44,FALSE)) | CI2: =IF($A2<1,"",VLOOKUP($D2,Specifications!$A:$AX,45,FALSE)) | CK2: =IF($A2<1,"",VLOOKUP($D2,Specifications!$A:$AX,46,FALSE)) | CM2: =IF($A2<1,"",VLOOKUP($D2,Specifications!$A:$AX,47,FALSE)) | CO2: =IF($A2<1,"",VLOOKUP($D2,Specifications!$A:$AX,48,FALSE)) | CQ2: =IF($A2<1,"",VLOOKUP($D2,Specifications!$A:$AX,49,FALSE)) | CS2: =IF($A2<1,"",VLOOKUP($D2,Specifications!$A:$AX,50,FALSE))
A3: =IF(ISBLANK('Asset Data'!C4),0,'Asset Data'!A4) -> 0 | B3: =IF($A3<1,"",VLOOKUP($A3,'Asset Data'!$A:$C,3,FALSE)) | C3: =IF(A3<1,"",VLOOKUP(D3,Specifications!A:B,2,FALSE)) | D3: =IF(A3<1,"",VLOOKUP(A3,'Asset Data'!A:W,23,FALSE)) | E3: =IF($A3<1,"",VLOOKUP($D3,Specifications!$A:$AX,4,FALSE)) | G3: =IF($A3<1,"",VLOOKUP($D3,Specifications!$A:$AX,5,FALSE)) | I3: =IF($A3<1,"",VLOOKUP($D3,Specifications!$A:$AX,6,FALSE)) | K3: =IF($A3<1,"",VLOOKUP($D3,Specifications!$A:$AX,7,FALSE)) | M3: =IF($A3<1,"",VLOOKUP($D3,Specifications!$A:$AX,8,FALSE)) | O3: =IF($A3<1,"",VLOOKUP($D3,Specifications!$A:$AX,9,FALSE)) | Q3: =IF($A3<1,"",VLOOKUP($D3,Specifications!$A:$AX,10,FALSE)) | S3: =IF($A3<1,"",VLOOKUP($D3,Specifications!$A:$AX,11,FALSE)) | U3: =IF($A3<1,"",VLOOKUP($D3,Specifications!$A:$AX,12,FALSE)) | W3: =IF($A3<1,"",VLOOKUP($D3,Specifications!$A:$AX,13,FALSE)) | Y3: =IF($A3<1,"",VLOOKUP($D3,Specifications!$A:$AX,14,FALSE)) | AA3: =IF($A3<1,"",VLOOKUP($D3,Specifications!$A:$AX,15,FALSE)) | AC3: =IF($A3<1,"",VLOOKUP($D3,Specifications!$A:$AX,16,FALSE)) | AE3: =IF($A3<1,"",VLOOKUP($D3,Specifications!$A:$AX,17,FALSE)) | AG3: =IF($A3<1,"",VLOOKUP($D3,Specifications!$A:$AX,18,FALSE)) | AI3: =IF($A3<1,"",VLOOKUP($D3,Specifications!$A:$AX,19,FALSE)) | AK3: =IF($A3<1,"",VLOOKUP($D3,Specifications!$A:$AX,20,FALSE)) | AM3: =IF($A3<1,"",VLOOKUP($D3,Specifications!$A:$AX,21,FALSE)) | AO3: =IF($A3<1,"",VLOOKUP($D3,Specifications!$A:$AX,22,FALSE)) | AQ3: =IF($A3<1,"",VLOOKUP($D3,Specifications!$A:$AX,23,FALSE)) | AS3: =IF($A3<1,"",VLOOKUP($D3,Specifications!$A:$AX,24,FALSE)) | AU3: =IF($A3<1,"",VLOOKUP($D3,Specifications!$A:$AX,25,FALSE)) | AW3: =IF($A3<1,"",VLOOKUP($D3,Specifications!$A:$AX,26,FALSE)) | AY3: =IF($A3<1,"",VLOOKUP($D3,Specifications!$A:$AX,27,FALSE)) | BA3: =IF($A3<1,"",VLOOKUP($D3,Specifications!$A:$AX,28,FALSE)) | BC3: =IF($A3<1,"",VLOOKUP($D3,Specifications!$A:$AX,29,FALSE)) | BE3: =IF($A3<1,"",VLOOKUP($D3,Specifications!$A:$AX,30,FALSE)) | BG3: =IF($A3<1,"",VLOOKUP($D3,Specifications!$A:$AX,31,FALSE)) | BI3: =IF($A3<1,"",VLOOKUP($D3,Specifications!$A:$AX,32,FALSE)) | BK3: =IF($A3<1,"",VLOOKUP($D3,Specifications!$A:$AX,33,FALSE)) | BM3: =IF($A3<1,"",VLOOKUP($D3,Specifications!$A:$AX,34,FALSE)) | BO3: =IF($A3<1,"",VLOOKUP($D3,Specifications!$A:$AX,35,FALSE)) | BQ3: =IF($A3<1,"",VLOOKUP($D3,Specifications!$A:$AX,36,FALSE)) | BS3: =IF($A3<1,"",VLOOKUP($D3,Specifications!$A:$AX,37,FALSE)) | BU3: =IF($A3<1,"",VLOOKUP($D3,Specifications!$A:$AX,38,FALSE)) | BW3: =IF($A3<1,"",VLOOKUP($D3,Specifications!$A:$AX,39,FALSE)) | BY3: =IF($A3<1,"",VLOOKUP($D3,Specifications!$A:$AX,40,FALSE)) | CA3: =IF($A3<1,"",VLOOKUP($D3,Specifications!$A:$AX,41,FALSE)) | CC3: =IF($A3<1,"",VLOOKUP($D3,Specifications!$A:$AX,42,FALSE)) | CE3: =IF($A3<1,"",VLOOKUP($D3,Specifications!$A:$AX,43,FALSE)) | CG3: =IF($A3<1,"",VLOOKUP($D3,Specifications!$A:$AX,44,FALSE)) | CI3: =IF($A3<1,"",VLOOKUP($D3,Specifications!$A:$AX,45,FALSE)) | CK3: =IF($A3<1,"",VLOOKUP($D3,Specifications!$A:$AX,46,FALSE)) | CM3: =IF($A3<1,"",VLOOKUP($D3,Specifications!$A:$AX,47,FALSE)) | CO3: =IF($A3<1,"",VLOOKUP($D3,Specifications!$A:$AX,48,FALSE)) | CQ3: =IF($A3<1,"",VLOOKUP($D3,Specifications!$A:$AX,49,FALSE)) | CS3: =IF($A3<1,"",VLOOKUP($D3,Specifications!$A:$AX,50,FALSE))
A4: =IF(ISBLANK('Asset Data'!C5),0,'Asset Data'!A5) -> 0 | B4: =IF($A4<1,"",VLOOKUP($A4,'Asset Data'!$A:$C,3,FALSE)) | C4: =IF(A4<1,"",VLOOKUP(D4,Specifications!A:B,2,FALSE)) | D4: =IF(A4<1,"",VLOOKUP(A4,'Asset Data'!A:W,23,FALSE)) | E4: =IF($A4<1,"",VLOOKUP($D4,Specifications!$A:$AX,4,FALSE)) | G4: =IF($A4<1,"",VLOOKUP($D4,Specifications!$A:$AX,5,FALSE)) | I4: =IF($A4<1,"",VLOOKUP($D4,Specifications!$A:$AX,6,FALSE)) | K4: =IF($A4<1,"",VLOOKUP($D4,Specifications!$A:$AX,7,FALSE)) | M4: =IF($A4<1,"",VLOOKUP($D4,Specifications!$A:$AX,8,FALSE)) | O4: =IF($A4<1,"",VLOOKUP($D4,Specifications!$A:$AX,9,FALSE)) | Q4: =IF($A4<1,"",VLOOKUP($D4,Specifications!$A:$AX,10,FALSE)) | S4: =IF($A4<1,"",VLOOKUP($D4,Specifications!$A:$AX,11,FALSE)) | U4: =IF($A4<1,"",VLOOKUP($D4,Specifications!$A:$AX,12,FALSE)) | W4: =IF($A4<1,"",VLOOKUP($D4,Specifications!$A:$AX,13,FALSE)) | Y4: =IF($A4<1,"",VLOOKUP($D4,Specifications!$A:$AX,14,FALSE)) | AA4: =IF($A4<1,"",VLOOKUP($D4,Specifications!$A:$AX,15,FALSE)) | AC4: =IF($A4<1,"",VLOOKUP($D4,Specifications!$A:$AX,16,FALSE)) | AE4: =IF($A4<1,"",VLOOKUP($D4,Specifications!$A:$AX,17,FALSE)) | AG4: =IF($A4<1,"",VLOOKUP($D4,Specifications!$A:$AX,18,FALSE)) | AI4: =IF($A4<1,"",VLOOKUP($D4,Specifications!$A:$AX,19,FALSE)) | AK4: =IF($A4<1,"",VLOOKUP($D4,Specifications!$A:$AX,20,FALSE)) | AM4: =IF($A4<1,"",VLOOKUP($D4,Specifications!$A:$AX,21,FALSE)) | AO4: =IF($A4<1,"",VLOOKUP($D4,Specifications!$A:$AX,22,FALSE)) | AQ4: =IF($A4<1,"",VLOOKUP($D4,Specifications!$A:$AX,23,FALSE)) | AS4: =IF($A4<1,"",VLOOKUP($D4,Specifications!$A:$AX,24,FALSE)) | AU4: =IF($A4<1,"",VLOOKUP($D4,Specifications!$A:$AX,25,FALSE)) | AW4: =IF($A4<1,"",VLOOKUP($D4,Specifications!$A:$AX,26,FALSE)) | AY4: =IF($A4<1,"",VLOOKUP($D4,Specifications!$A:$AX,27,FALSE)) | BA4: =IF($A4<1,"",VLOOKUP($D4,Specifications!$A:$AX,28,FALSE)) | BC4: =IF($A4<1,"",VLOOKUP($D4,Specifications!$A:$AX,29,FALSE)) | BE4: =IF($A4<1,"",VLOOKUP($D4,Specifications!$A:$AX,30,FALSE)) | BG4: =IF($A4<1,"",VLOOKUP($D4,Specifications!$A:$AX,31,FALSE)) | BI4: =IF($A4<1,"",VLOOKUP($D4,Specifications!$A:$AX,32,FALSE)) | BK4: =IF($A4<1,"",VLOOKUP($D4,Specifications!$A:$AX,33,FALSE)) | BM4: =IF($A4<1,"",VLOOKUP($D4,Specifications!$A:$AX,34,FALSE)) | BO4: =IF($A4<1,"",VLOOKUP($D4,Specifications!$A:$AX,35,FALSE)) | BQ4: =IF($A4<1,"",VLOOKUP($D4,Specifications!$A:$AX,36,FALSE)) | BS4: =IF($A4<1,"",VLOOKUP($D4,Specifications!$A:$AX,37,FALSE)) | BU4: =IF($A4<1,"",VLOOKUP($D4,Specifications!$A:$AX,38,FALSE)) | BW4: =IF($A4<1,"",VLOOKUP($D4,Specifications!$A:$AX,39,FALSE)) | BY4: =IF($A4<1,"",VLOOKUP($D4,Specifications!$A:$AX,40,FALSE)) | CA4: =IF($A4<1,"",VLOOKUP($D4,Specifications!$A:$AX,41,FALSE)) | CC4: =IF($A4<1,"",VLOOKUP($D4,Specifications!$A:$AX,42,FALSE)) | CE4: =IF($A4<1,"",VLOOKUP($D4,Specifications!$A:$AX,43,FALSE)) | CG4: =IF($A4<1,"",VLOOKUP($D4,Specifications!$A:$AX,44,FALSE)) | CI4: =IF($A4<1,"",VLOOKUP($D4,Specifications!$A:$AX,45,FALSE)) | CK4: =IF($A4<1,"",VLOOKUP($D4,Specifications!$A:$AX,46,FALSE)) | CM4: =IF($A4<1,"",VLOOKUP($D4,Specifications!$A:$AX,47,FALSE)) | CO4: =IF($A4<1,"",VLOOKUP($D4,Specifications!$A:$AX,48,FALSE)) | CQ4: =IF($A4<1,"",VLOOKUP($D4,Specifications!$A:$AX,49,FALSE)) | CS4: =IF($A4<1,"",VLOOKUP($D4,Specifications!$A:$AX,50,FALSE))
A5: =IF(ISBLANK('Asset Data'!C6),0,'Asset Data'!A6) -> 0 | B5: =IF($A5<1,"",VLOOKUP($A5,'Asset Data'!$A:$C,3,FALSE)) | C5: =IF(A5<1,"",VLOOKUP(D5,Specifications!A:B,2,FALSE)) | D5: =IF(A5<1,"",VLOOKUP(A5,'Asset Data'!A:W,23,FALSE)) | E5: =IF($A5<1,"",VLOOKUP($D5,Specifications!$A:$AX,4,FALSE)) | G5: =IF($A5<1,"",VLOOKUP($D5,Specifications!$A:$AX,5,FALSE)) | I5: =IF($A5<1,"",VLOOKUP($D5,Specifications!$A:$AX,6,FALSE)) | K5: =IF($A5<1,"",VLOOKUP($D5,Specifications!$A:$AX,7,FALSE)) | M5: =IF($A5<1,"",VLOOKUP($D5,Specifications!$A:$AX,8,FALSE)) | O5: =IF($A5<1,"",VLOOKUP($D5,Specifications!$A:$AX,9,FALSE)) | Q5: =IF($A5<1,"",VLOOKUP($D5,Specifications!$A:$AX,10,FALSE)) | S5: =IF($A5<1,"",VLOOKUP($D5,Specifications!$A:$AX,11,FALSE)) | U5: =IF($A5<1,"",VLOOKUP($D5,Specifications!$A:$AX,12,FALSE)) | W5: =IF($A5<1,"",VLOOKUP($D5,Specifications!$A:$AX,13,FALSE)) | Y5: =IF($A5<1,"",VLOOKUP($D5,Specifications!$A:$AX,14,FALSE)) | AA5: =IF($A5<1,"",VLOOKUP($D5,Specifications!$A:$AX,15,FALSE)) | AC5: =IF($A5<1,"",VLOOKUP($D5,Specifications!$A:$AX,16,FALSE)) | AE5: =IF($A5<1,"",VLOOKUP($D5,Specifications!$A:$AX,17,FALSE)) | AG5: =IF($A5<1,"",VLOOKUP($D5,Specifications!$A:$AX,18,FALSE)) | AI5: =IF($A5<1,"",VLOOKUP($D5,Specifications!$A:$AX,19,FALSE)) | AK5: =IF($A5<1,"",VLOOKUP($D5,Specifications!$A:$AX,20,FALSE)) | AM5: =IF($A5<1,"",VLOOKUP($D5,Specifications!$A:$AX,21,FALSE)) | AO5: =IF($A5<1,"",VLOOKUP($D5,Specifications!$A:$AX,22,FALSE)) | AQ5: =IF($A5<1,"",VLOOKUP($D5,Specifications!$A:$AX,23,FALSE)) | AS5: =IF($A5<1,"",VLOOKUP($D5,Specifications!$A:$AX,24,FALSE)) | AU5: =IF($A5<1,"",VLOOKUP($D5,Specifications!$A:$AX,25,FALSE)) | AW5: =IF($A5<1,"",VLOOKUP($D5,Specifications!$A:$AX,26,FALSE)) | AY5: =IF($A5<1,"",VLOOKUP($D5,Specifications!$A:$AX,27,FALSE)) | BA5: =IF($A5<1,"",VLOOKUP($D5,Specifications!$A:$AX,28,FALSE)) | BC5: =IF($A5<1,"",VLOOKUP($D5,Specifications!$A:$AX,29,FALSE)) | BE5: =IF($A5<1,"",VLOOKUP($D5,Specifications!$A:$AX,30,FALSE)) | BG5: =IF($A5<1,"",VLOOKUP($D5,Specifications!$A:$AX,31,FALSE)) | BI5: =IF($A5<1,"",VLOOKUP($D5,Specifications!$A:$AX,32,FALSE)) | BK5: =IF($A5<1,"",VLOOKUP($D5,Specifications!$A:$AX,33,FALSE)) | BM5: =IF($A5<1,"",VLOOKUP($D5,Specifications!$A:$AX,34,FALSE)) | BO5: =IF($A5<1,"",VLOOKUP($D5,Specifications!$A:$AX,35,FALSE)) | BQ5: =IF($A5<1,"",VLOOKUP($D5,Specifications!$A:$AX,36,FALSE)) | BS5: =IF($A5<1,"",VLOOKUP($D5,Specifications!$A:$AX,37,FALSE)) | BU5: =IF($A5<1,"",VLOOKUP($D5,Specifications!$A:$AX,38,FALSE)) | BW5: =IF($A5<1,"",VLOOKUP($D5,Specifications!$A:$AX,39,FALSE)) | BY5: =IF($A5<1,"",VLOOKUP($D5,Specifications!$A:$AX,40,FALSE)) | CA5: =IF($A5<1,"",VLOOKUP($D5,Specifications!$A:$AX,41,FALSE)) | CC5: =IF($A5<1,"",VLOOKUP($D5,Specifications!$A:$AX,42,FALSE)) | CE5: =IF($A5<1,"",VLOOKUP($D5,Specifications!$A:$AX,43,FALSE)) | CG5: =IF($A5<1,"",VLOOKUP($D5,Specifications!$A:$AX,44,FALSE)) | CI5: =IF($A5<1,"",VLOOKUP($D5,Specifications!$A:$AX,45,FALSE)) | CK5: =IF($A5<1,"",VLOOKUP($D5,Specifications!$A:$AX,46,FALSE)) | CM5: =IF($A5<1,"",VLOOKUP($D5,Specifications!$A:$AX,47,FALSE)) | CO5: =IF($A5<1,"",VLOOKUP($D5,Specifications!$A:$AX,48,FALSE)) | CQ5: =IF($A5<1,"",VLOOKUP($D5,Specifications!$A:$AX,49,FALSE)) | CS5: =IF($A5<1,"",VLOOKUP($D5,Specifications!$A:$AX,50,FALSE))
A6: =IF(ISBLANK('Asset Data'!C7),0,'Asset Data'!A7) -> 0 | B6: =IF($A6<1,"",VLOOKUP($A6,'Asset Data'!$A:$C,3,FALSE)) | C6: =IF(A6<1,"",VLOOKUP(D6,Specifications!A:B,2,FALSE)) | D6: =IF(A6<1,"",VLOOKUP(A6,'Asset Data'!A:W,23,FALSE)) | E6: =IF($A6<1,"",VLOOKUP($D6,Specifications!$A:$AX,4,FALSE)) | G6: =IF($A6<1,"",VLOOKUP($D6,Specifications!$A:$AX,5,FALSE)) | I6: =IF($A6<1,"",VLOOKUP($D6,Specifications!$A:$AX,6,FALSE)) | K6: =IF($A6<1,"",VLOOKUP($D6,Specifications!$A:$AX,7,FALSE)) | M6: =IF($A6<1,"",VLOOKUP($D6,Specifications!$A:$AX,8,FALSE)) | O6: =IF($A6<1,"",VLOOKUP($D6,Specifications!$A:$AX,9,FALSE)) | Q6: =IF($A6<1,"",VLOOKUP($D6,Specifications!$A:$AX,10,FALSE)) | S6: =IF($A6<1,"",VLOOKUP($D6,Specifications!$A:$AX,11,FALSE)) | U6: =IF($A6<1,"",VLOOKUP($D6,Specifications!$A:$AX,12,FALSE)) | W6: =IF($A6<1,"",VLOOKUP($D6,Specifications!$A:$AX,13,FALSE)) | Y6: =IF($A6<1,"",VLOOKUP($D6,Specifications!$A:$AX,14,FALSE)) | AA6: =IF($A6<1,"",VLOOKUP($D6,Specifications!$A:$AX,15,FALSE)) | AC6: =IF($A6<1,"",VLOOKUP($D6,Specifications!$A:$AX,16,FALSE)) | AE6: =IF($A6<1,"",VLOOKUP($D6,Specifications!$A:$AX,17,FALSE)) | AG6: =IF($A6<1,"",VLOOKUP($D6,Specifications!$A:$AX,18,FALSE)) | AI6: =IF($A6<1,"",VLOOKUP($D6,Specifications!$A:$AX,19,FALSE)) | AK6: =IF($A6<1,"",VLOOKUP($D6,Specifications!$A:$AX,20,FALSE)) | AM6: =IF($A6<1,"",VLOOKUP($D6,Specifications!$A:$AX,21,FALSE)) | AO6: =IF($A6<1,"",VLOOKUP($D6,Specifications!$A:$AX,22,FALSE)) | AQ6: =IF($A6<1,"",VLOOKUP($D6,Specifications!$A:$AX,23,FALSE)) | AS6: =IF($A6<1,"",VLOOKUP($D6,Specifications!$A:$AX,24,FALSE)) | AU6: =IF($A6<1,"",VLOOKUP($D6,Specifications!$A:$AX,25,FALSE)) | AW6: =IF($A6<1,"",VLOOKUP($D6,Specifications!$A:$AX,26,FALSE)) | AY6: =IF($A6<1,"",VLOOKUP($D6,Specifications!$A:$AX,27,FALSE)) | BA6: =IF($A6<1,"",VLOOKUP($D6,Specifications!$A:$AX,28,FALSE)) | BC6: =IF($A6<1,"",VLOOKUP($D6,Specifications!$A:$AX,29,FALSE)) | BE6: =IF($A6<1,"",VLOOKUP($D6,Specifications!$A:$AX,30,FALSE)) | BG6: =IF($A6<1,"",VLOOKUP($D6,Specifications!$A:$AX,31,FALSE)) | BI6: =IF($A6<1,"",VLOOKUP($D6,Specifications!$A:$AX,32,FALSE)) | BK6: =IF($A6<1,"",VLOOKUP($D6,Specifications!$A:$AX,33,FALSE)) | BM6: =IF($A6<1,"",VLOOKUP($D6,Specifications!$A:$AX,34,FALSE)) | BO6: =IF($A6<1,"",VLOOKUP($D6,Specifications!$A:$AX,35,FALSE)) | BQ6: =IF($A6<1,"",VLOOKUP($D6,Specifications!$A:$AX,36,FALSE)) | BS6: =IF($A6<1,"",VLOOKUP($D6,Specifications!$A:$AX,37,FALSE)) | BU6: =IF($A6<1,"",VLOOKUP($D6,Specifications!$A:$AX,38,FALSE)) | BW6: =IF($A6<1,"",VLOOKUP($D6,Specifications!$A:$AX,39,FALSE)) | BY6: =IF($A6<1,"",VLOOKUP($D6,Specifications!$A:$AX,40,FALSE)) | CA6: =IF($A6<1,"",VLOOKUP($D6,Specifications!$A:$AX,41,FALSE)) | CC6: =IF($A6<1,"",VLOOKUP($D6,Specifications!$A:$AX,42,FALSE)) | CE6: =IF($A6<1,"",VLOOKUP($D6,Specifications!$A:$AX,43,FALSE)) | CG6: =IF($A6<1,"",VLOOKUP($D6,Specifications!$A:$AX,44,FALSE)) | CI6: =IF($A6<1,"",VLOOKUP($D6,Specifications!$A:$AX,45,FALSE)) | CK6: =IF($A6<1,"",VLOOKUP($D6,Specifications!$A:$AX,46,FALSE)) | CM6: =IF($A6<1,"",VLOOKUP($D6,Specifications!$A:$AX,47,FALSE)) | CO6: =IF($A6<1,"",VLOOKUP($D6,Specifications!$A:$AX,48,FALSE)) | CQ6: =IF($A6<1,"",VLOOKUP($D6,Specifications!$A:$AX,49,FALSE)) | CS6: =IF($A6<1,"",VLOOKUP($D6,Specifications!$A:$AX,50,FALSE))
A7: =IF(ISBLANK('Asset Data'!C8),0,'Asset Data'!A8) -> 0 | B7: =IF($A7<1,"",VLOOKUP($A7,'Asset Data'!$A:$C,3,FALSE)) | C7: =IF(A7<1,"",VLOOKUP(D7,Specifications!A:B,2,FALSE)) | D7: =IF(A7<1,"",VLOOKUP(A7,'Asset Data'!A:W,23,FALSE)) | E7: =IF($A7<1,"",VLOOKUP($D7,Specifications!$A:$AX,4,FALSE)) | G7: =IF($A7<1,"",VLOOKUP($D7,Specifications!$A:$AX,5,FALSE)) | I7: =IF($A7<1,"",VLOOKUP($D7,Specifications!$A:$AX,6,FALSE)) | K7: =IF($A7<1,"",VLOOKUP($D7,Specifications!$A:$AX,7,FALSE)) | M7: =IF($A7<1,"",VLOOKUP($D7,Specifications!$A:$AX,8,FALSE)) | O7: =IF($A7<1,"",VLOOKUP($D7,Specifications!$A:$AX,9,FALSE)) | Q7: =IF($A7<1,"",VLOOKUP($D7,Specifications!$A:$AX,10,FALSE)) | S7: =IF($A7<1,"",VLOOKUP($D7,Specifications!$A:$AX,11,FALSE)) | U7: =IF($A7<1,"",VLOOKUP($D7,Specifications!$A:$AX,12,FALSE)) | W7: =IF($A7<1,"",VLOOKUP($D7,Specifications!$A:$AX,13,FALSE)) | Y7: =IF($A7<1,"",VLOOKUP($D7,Specifications!$A:$AX,14,FALSE)) | AA7: =IF($A7<1,"",VLOOKUP($D7,Specifications!$A:$AX,15,FALSE)) | AC7: =IF($A7<1,"",VLOOKUP($D7,Specifications!$A:$AX,16,FALSE)) | AE7: =IF($A7<1,"",VLOOKUP($D7,Specifications!$A:$AX,17,FALSE)) | AG7: =IF($A7<1,"",VLOOKUP($D7,Specifications!$A:$AX,18,FALSE)) | AI7: =IF($A7<1,"",VLOOKUP($D7,Specifications!$A:$AX,19,FALSE)) | AK7: =IF($A7<1,"",VLOOKUP($D7,Specifications!$A:$AX,20,FALSE)) | AM7: =IF($A7<1,"",VLOOKUP($D7,Specifications!$A:$AX,21,FALSE)) | AO7: =IF($A7<1,"",VLOOKUP($D7,Specifications!$A:$AX,22,FALSE)) | AQ7: =IF($A7<1,"",VLOOKUP($D7,Specifications!$A:$AX,23,FALSE)) | AS7: =IF($A7<1,"",VLOOKUP($D7,Specifications!$A:$AX,24,FALSE)) | AU7: =IF($A7<1,"",VLOOKUP($D7,Specifications!$A:$AX,25,FALSE)) | AW7: =IF($A7<1,"",VLOOKUP($D7,Specifications!$A:$AX,26,FALSE)) | AY7: =IF($A7<1,"",VLOOKUP($D7,Specifications!$A:$AX,27,FALSE)) | BA7: =IF($A7<1,"",VLOOKUP($D7,Specifications!$A:$AX,28,FALSE)) | BC7: =IF($A7<1,"",VLOOKUP($D7,Specifications!$A:$AX,29,FALSE)) | BE7: =IF($A7<1,"",VLOOKUP($D7,Specifications!$A:$AX,30,FALSE)) | BG7: =IF($A7<1,"",VLOOKUP($D7,Specifications!$A:$AX,31,FALSE)) | BI7: =IF($A7<1,"",VLOOKUP($D7,Specifications!$A:$AX,32,FALSE)) | BK7: =IF($A7<1,"",VLOOKUP($D7,Specifications!$A:$AX,33,FALSE)) | BM7: =IF($A7<1,"",VLOOKUP($D7,Specifications!$A:$AX,34,FALSE)) | BO7: =IF($A7<1,"",VLOOKUP($D7,Specifications!$A:$AX,35,FALSE)) | BQ7: =IF($A7<1,"",VLOOKUP($D7,Specifications!$A:$AX,36,FALSE)) | BS7: =IF($A7<1,"",VLOOKUP($D7,Specifications!$A:$AX,37,FALSE)) | BU7: =IF($A7<1,"",VLOOKUP($D7,Specifications!$A:$AX,38,FALSE)) | BW7: =IF($A7<1,"",VLOOKUP($D7,Specifications!$A:$AX,39,FALSE)) | BY7: =IF($A7<1,"",VLOOKUP($D7,Specifications!$A:$AX,40,FALSE)) | CA7: =IF($A7<1,"",VLOOKUP($D7,Specifications!$A:$AX,41,FALSE)) | CC7: =IF($A7<1,"",VLOOKUP($D7,Specifications!$A:$AX,42,FALSE)) | CE7: =IF($A7<1,"",VLOOKUP($D7,Specifications!$A:$AX,43,FALSE)) | CG7: =IF($A7<1,"",VLOOKUP($D7,Specifications!$A:$AX,44,FALSE)) | CI7: =IF($A7<1,"",VLOOKUP($D7,Specifications!$A:$AX,45,FALSE)) | CK7: =IF($A7<1,"",VLOOKUP($D7,Specifications!$A:$AX,46,FALSE)) | CM7: =IF($A7<1,"",VLOOKUP($D7,Specifications!$A:$AX,47,FALSE)) | CO7: =IF($A7<1,"",VLOOKUP($D7,Specifications!$A:$AX,48,FALSE)) | CQ7: =IF($A7<1,"",VLOOKUP($D7,Specifications!$A:$AX,49,FALSE)) | CS7: =IF($A7<1,"",VLOOKUP($D7,Specifications!$A:$AX,50,FALSE))
A8: =IF(ISBLANK('Asset Data'!C9),0,'Asset Data'!A9) -> 0 | B8: =IF($A8<1,"",VLOOKUP($A8,'Asset Data'!$A:$C,3,FALSE)) | C8: =IF(A8<1,"",VLOOKUP(D8,Specifications!A:B,2,FALSE)) | D8: =IF(A8<1,"",VLOOKUP(A8,'Asset Data'!A:W,23,FALSE)) | E8: =IF($A8<1,"",VLOOKUP($D8,Specifications!$A:$AX,4,FALSE)) | G8: =IF($A8<1,"",VLOOKUP($D8,Specifications!$A:$AX,5,FALSE)) | I8: =IF($A8<1,"",VLOOKUP($D8,Specifications!$A:$AX,6,FALSE)) | K8: =IF($A8<1,"",VLOOKUP($D8,Specifications!$A:$AX,7,FALSE)) | M8: =IF($A8<1,"",VLOOKUP($D8,Specifications!$A:$AX,8,FALSE)) | O8: =IF($A8<1,"",VLOOKUP($D8,Specifications!$A:$AX,9,FALSE)) | Q8: =IF($A8<1,"",VLOOKUP($D8,Specifications!$A:$AX,10,FALSE)) | S8: =IF($A8<1,"",VLOOKUP($D8,Specifications!$A:$AX,11,FALSE)) | U8: =IF($A8<1,"",VLOOKUP($D8,Specifications!$A:$AX,12,FALSE)) | W8: =IF($A8<1,"",VLOOKUP($D8,Specifications!$A:$AX,13,FALSE)) | Y8: =IF($A8<1,"",VLOOKUP($D8,Specifications!$A:$AX,14,FALSE)) | AA8: =IF($A8<1,"",VLOOKUP($D8,Specifications!$A:$AX,15,FALSE)) | AC8: =IF($A8<1,"",VLOOKUP($D8,Specifications!$A:$AX,16,FALSE)) | AE8: =IF($A8<1,"",VLOOKUP($D8,Specifications!$A:$AX,17,FALSE)) | AG8: =IF($A8<1,"",VLOOKUP($D8,Specifications!$A:$AX,18,FALSE)) | AI8: =IF($A8<1,"",VLOOKUP($D8,Specifications!$A:$AX,19,FALSE)) | AK8: =IF($A8<1,"",VLOOKUP($D8,Specifications!$A:$AX,20,FALSE)) | AM8: =IF($A8<1,"",VLOOKUP($D8,Specifications!$A:$AX,21,FALSE)) | AO8: =IF($A8<1,"",VLOOKUP($D8,Specifications!$A:$AX,22,FALSE)) | AQ8: =IF($A8<1,"",VLOOKUP($D8,Specifications!$A:$AX,23,FALSE)) | AS8: =IF($A8<1,"",VLOOKUP($D8,Specifications!$A:$AX,24,FALSE)) | AU8: =IF($A8<1,"",VLOOKUP($D8,Specifications!$A:$AX,25,FALSE)) | AW8: =IF($A8<1,"",VLOOKUP($D8,Specifications!$A:$AX,26,FALSE)) | AY8: =IF($A8<1,"",VLOOKUP($D8,Specifications!$A:$AX,27,FALSE)) | BA8: =IF($A8<1,"",VLOOKUP($D8,Specifications!$A:$AX,28,FALSE)) | BC8: =IF($A8<1,"",VLOOKUP($D8,Specifications!$A:$AX,29,FALSE)) | BE8: =IF($A8<1,"",VLOOKUP($D8,Specifications!$A:$AX,30,FALSE)) | BG8: =IF($A8<1,"",VLOOKUP($D8,Specifications!$A:$AX,31,FALSE)) | BI8: =IF($A8<1,"",VLOOKUP($D8,Specifications!$A:$AX,32,FALSE)) | BK8: =IF($A8<1,"",VLOOKUP($D8,Specifications!$A:$AX,33,FALSE)) | BM8: =IF($A8<1,"",VLOOKUP($D8,Specifications!$A:$AX,34,FALSE)) | BO8: =IF($A8<1,"",VLOOKUP($D8,Specifications!$A:$AX,35,FALSE)) | BQ8: =IF($A8<1,"",VLOOKUP($D8,Specifications!$A:$AX,36,FALSE)) | BS8: =IF($A8<1,"",VLOOKUP($D8,Specifications!$A:$AX,37,FALSE)) | BU8: =IF($A8<1,"",VLOOKUP($D8,Specifications!$A:$AX,38,FALSE)) | BW8: =IF($A8<1,"",VLOOKUP($D8,Specifications!$A:$AX,39,FALSE)) | BY8: =IF($A8<1,"",VLOOKUP($D8,Specifications!$A:$AX,40,FALSE)) | CA8: =IF($A8<1,"",VLOOKUP($D8,Specifications!$A:$AX,41,FALSE)) | CC8: =IF($A8<1,"",VLOOKUP($D8,Specifications!$A:$AX,42,FALSE)) | CE8: =IF($A8<1,"",VLOOKUP($D8,Specifications!$A:$AX,43,FALSE)) | CG8: =IF($A8<1,"",VLOOKUP($D8,Specifications!$A:$AX,44,FALSE)) | CI8: =IF($A8<1,"",VLOOKUP($D8,Specifications!$A:$AX,45,FALSE)) | CK8: =IF($A8<1,"",VLOOKUP($D8,Specifications!$A:$AX,46,FALSE)) | CM8: =IF($A8<1,"",VLOOKUP($D8,Specifications!$A:$AX,47,FALSE)) | CO8: =IF($A8<1,"",VLOOKUP($D8,Specifications!$A:$AX,48,FALSE)) | CQ8: =IF($A8<1,"",VLOOKUP($D8,Specifications!$A:$AX,49,FALSE)) | CS8: =IF($A8<1,"",VLOOKUP($D8,Specifications!$A:$AX,50,FALSE))
A9: =IF(ISBLANK('Asset Data'!C10),0,'Asset Data'!A10) -> 0 | B9: =IF($A9<1,"",VLOOKUP($A9,'Asset Data'!$A:$C,3,FALSE)) | C9: =IF(A9<1,"",VLOOKUP(D9,Specifications!A:B,2,FALSE)) | D9: =IF(A9<1,"",VLOOKUP(A9,'Asset Data'!A:W,23,FALSE)) | E9: =IF($A9<1,"",VLOOKUP($D9,Specifications!$A:$AX,4,FALSE)) | G9: =IF($A9<1,"",VLOOKUP($D9,Specifications!$A:$AX,5,FALSE)) | I9: =IF($A9<1,"",VLOOKUP($D9,Specifications!$A:$AX,6,FALSE)) | K9: =IF($A9<1,"",VLOOKUP($D9,Specifications!$A:$AX,7,FALSE)) | M9: =IF($A9<1,"",VLOOKUP($D9,Specifications!$A:$AX,8,FALSE)) | O9: =IF($A9<1,"",VLOOKUP($D9,Specifications!$A:$AX,9,FALSE)) | Q9: =IF($A9<1,"",VLOOKUP($D9,Specifications!$A:$AX,10,FALSE)) | S9: =IF($A9<1,"",VLOOKUP($D9,Specifications!$A:$AX,11,FALSE)) | U9: =IF($A9<1,"",VLOOKUP($D9,Specifications!$A:$AX,12,FALSE)) | W9: =IF($A9<1,"",VLOOKUP($D9,Specifications!$A:$AX,13,FALSE)) | Y9: =IF($A9<1,"",VLOOKUP($D9,Specifications!$A:$AX,14,FALSE)) | AA9: =IF($A9<1,"",VLOOKUP($D9,Specifications!$A:$AX,15,FALSE)) | AC9: =IF($A9<1,"",VLOOKUP($D9,Specifications!$A:$AX,16,FALSE)) | AE9: =IF($A9<1,"",VLOOKUP($D9,Specifications!$A:$AX,17,FALSE)) | AG9: =IF($A9<1,"",VLOOKUP($D9,Specifications!$A:$AX,18,FALSE)) | AI9: =IF($A9<1,"",VLOOKUP($D9,Specifications!$A:$AX,19,FALSE)) | AK9: =IF($A9<1,"",VLOOKUP($D9,Specifications!$A:$AX,20,FALSE)) | AM9: =IF($A9<1,"",VLOOKUP($D9,Specifications!$A:$AX,21,FALSE)) | AO9: =IF($A9<1,"",VLOOKUP($D9,Specifications!$A:$AX,22,FALSE)) | AQ9: =IF($A9<1,"",VLOOKUP($D9,Specifications!$A:$AX,23,FALSE)) | AS9: =IF($A9<1,"",VLOOKUP($D9,Specifications!$A:$AX,24,FALSE)) | AU9: =IF($A9<1,"",VLOOKUP($D9,Specifications!$A:$AX,25,FALSE)) | AW9: =IF($A9<1,"",VLOOKUP($D9,Specifications!$A:$AX,26,FALSE)) | AY9: =IF($A9<1,"",VLOOKUP($D9,Specifications!$A:$AX,27,FALSE)) | BA9: =IF($A9<1,"",VLOOKUP($D9,Specifications!$A:$AX,28,FALSE)) | BC9: =IF($A9<1,"",VLOOKUP($D9,Specifications!$A:$AX,29,FALSE)) | BE9: =IF($A9<1,"",VLOOKUP($D9,Specifications!$A:$AX,30,FALSE)) | BG9: =IF($A9<1,"",VLOOKUP($D9,Specifications!$A:$AX,31,FALSE)) | BI9: =IF($A9<1,"",VLOOKUP($D9,Specifications!$A:$AX,32,FALSE)) | BK9: =IF($A9<1,"",VLOOKUP($D9,Specifications!$A:$AX,33,FALSE)) | BM9: =IF($A9<1,"",VLOOKUP($D9,Specifications!$A:$AX,34,FALSE)) | BO9: =IF($A9<1,"",VLOOKUP($D9,Specifications!$A:$AX,35,FALSE)) | BQ9: =IF($A9<1,"",VLOOKUP($D9,Specifications!$A:$AX,36,FALSE)) | BS9: =IF($A9<1,"",VLOOKUP($D9,Specifications!$A:$AX,37,FALSE)) | BU9: =IF($A9<1,"",VLOOKUP($D9,Specifications!$A:$AX,38,FALSE)) | BW9: =IF($A9<1,"",VLOOKUP($D9,Specifications!$A:$AX,39,FALSE)) | BY9: =IF($A9<1,"",VLOOKUP($D9,Specifications!$A:$AX,40,FALSE)) | CA9: =IF($A9<1,"",VLOOKUP($D9,Specifications!$A:$AX,41,FALSE)) | CC9: =IF($A9<1,"",VLOOKUP($D9,Specifications!$A:$AX,42,FALSE)) | CE9: =IF($A9<1,"",VLOOKUP($D9,Specifications!$A:$AX,43,FALSE)) | CG9: =IF($A9<1,"",VLOOKUP($D9,Specifications!$A:$AX,44,FALSE)) | CI9: =IF($A9<1,"",VLOOKUP($D9,Specifications!$A:$AX,45,FALSE)) | CK9: =IF($A9<1,"",VLOOKUP($D9,Specifications!$A:$AX,46,FALSE)) | CM9: =IF($A9<1,"",VLOOKUP($D9,Specifications!$A:$AX,47,FALSE)) | CO9: =IF($A9<1,"",VLOOKUP($D9,Specifications!$A:$AX,48,FALSE)) | CQ9: =IF($A9<1,"",VLOOKUP($D9,Specifications!$A:$AX,49,FALSE)) | CS9: =IF($A9<1,"",VLOOKUP($D9,Specifications!$A:$AX,50,FALSE))
A10: =IF(ISBLANK('Asset Data'!C11),0,'Asset Data'!A11) -> 0 | B10: =IF($A10<1,"",VLOOKUP($A10,'Asset Data'!$A:$C,3,FALSE)) | C10: =IF(A10<1,"",VLOOKUP(D10,Specifications!A:B,2,FALSE)) | D10: =IF(A10<1,"",VLOOKUP(A10,'Asset Data'!A:W,23,FALSE)) | E10: =IF($A10<1,"",VLOOKUP($D10,Specifications!$A:$AX,4,FALSE)) | G10: =IF($A10<1,"",VLOOKUP($D10,Specifications!$A:$AX,5,FALSE)) | I10: =IF($A10<1,"",VLOOKUP($D10,Specifications!$A:$AX,6,FALSE)) | K10: =IF($A10<1,"",VLOOKUP($D10,Specifications!$A:$AX,7,FALSE)) | M10: =IF($A10<1,"",VLOOKUP($D10,Specifications!$A:$AX,8,FALSE)) | O10: =IF($A10<1,"",VLOOKUP($D10,Specifications!$A:$AX,9,FALSE)) | Q10: =IF($A10<1,"",VLOOKUP($D10,Specifications!$A:$AX,10,FALSE)) | S10: =IF($A10<1,"",VLOOKUP($D10,Specifications!$A:$AX,11,FALSE)) | U10: =IF($A10<1,"",VLOOKUP($D10,Specifications!$A:$AX,12,FALSE)) | W10: =IF($A10<1,"",VLOOKUP($D10,Specifications!$A:$AX,13,FALSE)) | Y10: =IF($A10<1,"",VLOOKUP($D10,Specifications!$A:$AX,14,FALSE)) | AA10: =IF($A10<1,"",VLOOKUP($D10,Specifications!$A:$AX,15,FALSE)) | AC10: =IF($A10<1,"",VLOOKUP($D10,Specifications!$A:$AX,16,FALSE)) | AE10: =IF($A10<1,"",VLOOKUP($D10,Specifications!$A:$AX,17,FALSE)) | AG10: =IF($A10<1,"",VLOOKUP($D10,Specifications!$A:$AX,18,FALSE)) | AI10: =IF($A10<1,"",VLOOKUP($D10,Specifications!$A:$AX,19,FALSE)) | AK10: =IF($A10<1,"",VLOOKUP($D10,Specifications!$A:$AX,20,FALSE)) | AM10: =IF($A10<1,"",VLOOKUP($D10,Specifications!$A:$AX,21,FALSE)) | AO10: =IF($A10<1,"",VLOOKUP($D10,Specifications!$A:$AX,22,FALSE)) | AQ10: =IF($A10<1,"",VLOOKUP($D10,Specifications!$A:$AX,23,FALSE)) | AS10: =IF($A10<1,"",VLOOKUP($D10,Specifications!$A:$AX,24,FALSE)) | AU10: =IF($A10<1,"",VLOOKUP($D10,Specifications!$A:$AX,25,FALSE)) | AW10: =IF($A10<1,"",VLOOKUP($D10,Specifications!$A:$AX,26,FALSE)) | AY10: =IF($A10<1,"",VLOOKUP($D10,Specifications!$A:$AX,27,FALSE)) | BA10: =IF($A10<1,"",VLOOKUP($D10,Specifications!$A:$AX,28,FALSE)) | BC10: =IF($A10<1,"",VLOOKUP($D10,Specifications!$A:$AX,29,FALSE)) | BE10: =IF($A10<1,"",VLOOKUP($D10,Specifications!$A:$AX,30,FALSE)) | BG10: =IF($A10<1,"",VLOOKUP($D10,Specifications!$A:$AX,31,FALSE)) | BI10: =IF($A10<1,"",VLOOKUP($D10,Specifications!$A:$AX,32,FALSE)) | BK10: =IF($A10<1,"",VLOOKUP($D10,Specifications!$A:$AX,33,FALSE)) | BM10: =IF($A10<1,"",VLOOKUP($D10,Specifications!$A:$AX,34,FALSE)) | BO10: =IF($A10<1,"",VLOOKUP($D10,Specifications!$A:$AX,35,FALSE)) | BQ10: =IF($A10<1,"",VLOOKUP($D10,Specifications!$A:$AX,36,FALSE)) | BS10: =IF($A10<1,"",VLOOKUP($D10,Specifications!$A:$AX,37,FALSE)) | BU10: =IF($A10<1,"",VLOOKUP($D10,Specifications!$A:$AX,38,FALSE)) | BW10: =IF($A10<1,"",VLOOKUP($D10,Specifications!$A:$AX,39,FALSE)) | BY10: =IF($A10<1,"",VLOOKUP($D10,Specifications!$A:$AX,40,FALSE)) | CA10: =IF($A10<1,"",VLOOKUP($D10,Specifications!$A:$AX,41,FALSE)) | CC10: =IF($A10<1,"",VLOOKUP($D10,Specifications!$A:$AX,42,FALSE)) | CE10: =IF($A10<1,"",VLOOKUP($D10,Specifications!$A:$AX,43,FALSE)) | CG10: =IF($A10<1,"",VLOOKUP($D10,Specifications!$A:$AX,44,FALSE)) | CI10: =IF($A10<1,"",VLOOKUP($D10,Specifications!$A:$AX,45,FALSE)) | CK10: =IF($A10<1,"",VLOOKUP($D10,Specifications!$A:$AX,46,FALSE)) | CM10: =IF($A10<1,"",VLOOKUP($D10,Specifications!$A:$AX,47,FALSE)) | CO10: =IF($A10<1,"",VLOOKUP($D10,Specifications!$A:$AX,48,FALSE)) | CQ10: =IF($A10<1,"",VLOOKUP($D10,Specifications!$A:$AX,49,FALSE)) | CS10: =IF($A10<1,"",VLOOKUP($D10,Specifications!$A:$AX,50,FALSE))
A11: =IF(ISBLANK('Asset Data'!C12),0,'Asset Data'!A12) -> 0 | B11: =IF($A11<1,"",VLOOKUP($A11,'Asset Data'!$A:$C,3,FALSE)) | C11: =IF(A11<1,"",VLOOKUP(D11,Specifications!A:B,2,FALSE)) | D11: =IF(A11<1,"",VLOOKUP(A11,'Asset Data'!A:W,23,FALSE)) | E11: =IF($A11<1,"",VLOOKUP($D11,Specifications!$A:$AX,4,FALSE)) | G11: =IF($A11<1,"",VLOOKUP($D11,Specifications!$A:$AX,5,FALSE)) | I11: =IF($A11<1,"",VLOOKUP($D11,Specifications!$A:$AX,6,FALSE)) | K11: =IF($A11<1,"",VLOOKUP($D11,Specifications!$A:$AX,7,FALSE)) | M11: =IF($A11<1,"",VLOOKUP($D11,Specifications!$A:$AX,8,FALSE)) | O11: =IF($A11<1,"",VLOOKUP($D11,Specifications!$A:$AX,9,FALSE)) | Q11: =IF($A11<1,"",VLOOKUP($D11,Specifications!$A:$AX,10,FALSE)) | S11: =IF($A11<1,"",VLOOKUP($D11,Specifications!$A:$AX,11,FALSE)) | U11: =IF($A11<1,"",VLOOKUP($D11,Specifications!$A:$AX,12,FALSE)) | W11: =IF($A11<1,"",VLOOKUP($D11,Specifications!$A:$AX,13,FALSE)) | Y11: =IF($A11<1,"",VLOOKUP($D11,Specifications!$A:$AX,14,FALSE)) | AA11: =IF($A11<1,"",VLOOKUP($D11,Specifications!$A:$AX,15,FALSE)) | AC11: =IF($A11<1,"",VLOOKUP($D11,Specifications!$A:$AX,16,FALSE)) | AE11: =IF($A11<1,"",VLOOKUP($D11,Specifications!$A:$AX,17,FALSE)) | AG11: =IF($A11<1,"",VLOOKUP($D11,Specifications!$A:$AX,18,FALSE)) | AI11: =IF($A11<1,"",VLOOKUP($D11,Specifications!$A:$AX,19,FALSE)) | AK11: =IF($A11<1,"",VLOOKUP($D11,Specifications!$A:$AX,20,FALSE)) | AM11: =IF($A11<1,"",VLOOKUP($D11,Specifications!$A:$AX,21,FALSE)) | AO11: =IF($A11<1,"",VLOOKUP($D11,Specifications!$A:$AX,22,FALSE)) | AQ11: =IF($A11<1,"",VLOOKUP($D11,Specifications!$A:$AX,23,FALSE)) | AS11: =IF($A11<1,"",VLOOKUP($D11,Specifications!$A:$AX,24,FALSE)) | AU11: =IF($A11<1,"",VLOOKUP($D11,Specifications!$A:$AX,25,FALSE)) | AW11: =IF($A11<1,"",VLOOKUP($D11,Specifications!$A:$AX,26,FALSE)) | AY11: =IF($A11<1,"",VLOOKUP($D11,Specifications!$A:$AX,27,FALSE)) | BA11: =IF($A11<1,"",VLOOKUP($D11,Specifications!$A:$AX,28,FALSE)) | BC11: =IF($A11<1,"",VLOOKUP($D11,Specifications!$A:$AX,29,FALSE)) | BE11: =IF($A11<1,"",VLOOKUP($D11,Specifications!$A:$AX,30,FALSE)) | BG11: =IF($A11<1,"",VLOOKUP($D11,Specifications!$A:$AX,31,FALSE)) | BI11: =IF($A11<1,"",VLOOKUP($D11,Specifications!$A:$AX,32,FALSE)) | BK11: =IF($A11<1,"",VLOOKUP($D11,Specifications!$A:$AX,33,FALSE)) | BM11: =IF($A11<1,"",VLOOKUP($D11,Specifications!$A:$AX,34,FALSE)) | BO11: =IF($A11<1,"",VLOOKUP($D11,Specifications!$A:$AX,35,FALSE)) | BQ11: =IF($A11<1,"",VLOOKUP($D11,Specifications!$A:$AX,36,FALSE)) | BS11: =IF($A11<1,"",VLOOKUP($D11,Specifications!$A:$AX,37,FALSE)) | BU11: =IF($A11<1,"",VLOOKUP($D11,Specifications!$A:$AX,38,FALSE)) | BW11: =IF($A11<1,"",VLOOKUP($D11,Specifications!$A:$AX,39,FALSE)) | BY11: =IF($A11<1,"",VLOOKUP($D11,Specifications!$A:$AX,40,FALSE)) | CA11: =IF($A11<1,"",VLOOKUP($D11,Specifications!$A:$AX,41,FALSE)) | CC11: =IF($A11<1,"",VLOOKUP($D11,Specifications!$A:$AX,42,FALSE)) | CE11: =IF($A11<1,"",VLOOKUP($D11,Specifications!$A:$AX,43,FALSE)) | CG11: =IF($A11<1,"",VLOOKUP($D11,Specifications!$A:$AX,44,FALSE)) | CI11: =IF($A11<1,"",VLOOKUP($D11,Specifications!$A:$AX,45,FALSE)) | CK11: =IF($A11<1,"",VLOOKUP($D11,Specifications!$A:$AX,46,FALSE)) | CM11: =IF($A11<1,"",VLOOKUP($D11,Specifications!$A:$AX,47,FALSE)) | CO11: =IF($A11<1,"",VLOOKUP($D11,Specifications!$A:$AX,48,FALSE)) | CQ11: =IF($A11<1,"",VLOOKUP($D11,Specifications!$A:$AX,49,FALSE)) | CS11: =IF($A11<1,"",VLOOKUP($D11,Specifications!$A:$AX,50,FALSE))
A12: =IF(ISBLANK('Asset Data'!C13),0,'Asset Data'!A13) -> 0 | B12: =IF($A12<1,"",VLOOKUP($A12,'Asset Data'!$A:$C,3,FALSE)) | C12: =IF(A12<1,"",VLOOKUP(D12,Specifications!A:B,2,FALSE)) | D12: =IF(A12<1,"",VLOOKUP(A12,'Asset Data'!A:W,23,FALSE)) | E12: =IF($A12<1,"",VLOOKUP($D12,Specifications!$A:$AX,4,FALSE)) | G12: =IF($A12<1,"",VLOOKUP($D12,Specifications!$A:$AX,5,FALSE)) | I12: =IF($A12<1,"",VLOOKUP($D12,Specifications!$A:$AX,6,FALSE)) | K12: =IF($A12<1,"",VLOOKUP($D12,Specifications!$A:$AX,7,FALSE)) | M12: =IF($A12<1,"",VLOOKUP($D12,Specifications!$A:$AX,8,FALSE)) | O12: =IF($A12<1,"",VLOOKUP($D12,Specifications!$A:$AX,9,FALSE)) | Q12: =IF($A12<1,"",VLOOKUP($D12,Specifications!$A:$AX,10,FALSE)) | S12: =IF($A12<1,"",VLOOKUP($D12,Specifications!$A:$AX,11,FALSE)) | U12: =IF($A12<1,"",VLOOKUP($D12,Specifications!$A:$AX,12,FALSE)) | W12: =IF($A12<1,"",VLOOKUP($D12,Specifications!$A:$AX,13,FALSE)) | Y12: =IF($A12<1,"",VLOOKUP($D12,Specifications!$A:$AX,14,FALSE)) | AA12: =IF($A12<1,"",VLOOKUP($D12,Specifications!$A:$AX,15,FALSE)) | AC12: =IF($A12<1,"",VLOOKUP($D12,Specifications!$A:$AX,16,FALSE)) | AE12: =IF($A12<1,"",VLOOKUP($D12,Specifications!$A:$AX,17,FALSE)) | AG12: =IF($A12<1,"",VLOOKUP($D12,Specifications!$A:$AX,18,FALSE)) | AI12: =IF($A12<1,"",VLOOKUP($D12,Specifications!$A:$AX,19,FALSE)) | AK12: =IF($A12<1,"",VLOOKUP($D12,Specifications!$A:$AX,20,FALSE)) | AM12: =IF($A12<1,"",VLOOKUP($D12,Specifications!$A:$AX,21,FALSE)) | AO12: =IF($A12<1,"",VLOOKUP($D12,Specifications!$A:$AX,22,FALSE)) | AQ12: =IF($A12<1,"",VLOOKUP($D12,Specifications!$A:$AX,23,FALSE)) | AS12: =IF($A12<1,"",VLOOKUP($D12,Specifications!$A:$AX,24,FALSE)) | AU12: =IF($A12<1,"",VLOOKUP($D12,Specifications!$A:$AX,25,FALSE)) | AW12: =IF($A12<1,"",VLOOKUP($D12,Specifications!$A:$AX,26,FALSE)) | AY12: =IF($A12<1,"",VLOOKUP($D12,Specifications!$A:$AX,27,FALSE)) | BA12: =IF($A12<1,"",VLOOKUP($D12,Specifications!$A:$AX,28,FALSE)) | BC12: =IF($A12<1,"",VLOOKUP($D12,Specifications!$A:$AX,29,FALSE)) | BE12: =IF($A12<1,"",VLOOKUP($D12,Specifications!$A:$AX,30,FALSE)) | BG12: =IF($A12<1,"",VLOOKUP($D12,Specifications!$A:$AX,31,FALSE)) | BI12: =IF($A12<1,"",VLOOKUP($D12,Specifications!$A:$AX,32,FALSE)) | BK12: =IF($A12<1,"",VLOOKUP($D12,Specifications!$A:$AX,33,FALSE)) | BM12: =IF($A12<1,"",VLOOKUP($D12,Specifications!$A:$AX,34,FALSE)) | BO12: =IF($A12<1,"",VLOOKUP($D12,Specifications!$A:$AX,35,FALSE)) | BQ12: =IF($A12<1,"",VLOOKUP($D12,Specifications!$A:$AX,36,FALSE)) | BS12: =IF($A12<1,"",VLOOKUP($D12,Specifications!$A:$AX,37,FALSE)) | BU12: =IF($A12<1,"",VLOOKUP($D12,Specifications!$A:$AX,38,FALSE)) | BW12: =IF($A12<1,"",VLOOKUP($D12,Specifications!$A:$AX,39,FALSE)) | BY12: =IF($A12<1,"",VLOOKUP($D12,Specifications!$A:$AX,40,FALSE)) | CA12: =IF($A12<1,"",VLOOKUP($D12,Specifications!$A:$AX,41,FALSE)) | CC12: =IF($A12<1,"",VLOOKUP($D12,Specifications!$A:$AX,42,FALSE)) | CE12: =IF($A12<1,"",VLOOKUP($D12,Specifications!$A:$AX,43,FALSE)) | CG12: =IF($A12<1,"",VLOOKUP($D12,Specifications!$A:$AX,44,FALSE)) | CI12: =IF($A12<1,"",VLOOKUP($D12,Specifications!$A:$AX,45,FALSE)) | CK12: =IF($A12<1,"",VLOOKUP($D12,Specifications!$A:$AX,46,FALSE)) | CM12: =IF($A12<1,"",VLOOKUP($D12,Specifications!$A:$AX,47,FALSE)) | CO12: =IF($A12<1,"",VLOOKUP($D12,Specifications!$A:$AX,48,FALSE)) | CQ12: =IF($A12<1,"",VLOOKUP($D12,Specifications!$A:$AX,49,FALSE)) | CS12: =IF($A12<1,"",VLOOKUP($D12,Specifications!$A:$AX,50,FALSE))
A13: =IF(ISBLANK('Asset Data'!C14),0,'Asset Data'!A14) -> 0 | B13: =IF($A13<1,"",VLOOKUP($A13,'Asset Data'!$A:$C,3,FALSE)) | C13: =IF(A13<1,"",VLOOKUP(D13,Specifications!A:B,2,FALSE)) | D13: =IF(A13<1,"",VLOOKUP(A13,'Asset Data'!A:W,23,FALSE)) | E13: =IF($A13<1,"",VLOOKUP($D13,Specifications!$A:$AX,4,FALSE)) | G13: =IF($A13<1,"",VLOOKUP($D13,Specifications!$A:$AX,5,FALSE)) | I13: =IF($A13<1,"",VLOOKUP($D13,Specifications!$A:$AX,6,FALSE)) | K13: =IF($A13<1,"",VLOOKUP($D13,Specifications!$A:$AX,7,FALSE)) | M13: =IF($A13<1,"",VLOOKUP($D13,Specifications!$A:$AX,8,FALSE)) | O13: =IF($A13<1,"",VLOOKUP($D13,Specifications!$A:$AX,9,FALSE)) | Q13: =IF($A13<1,"",VLOOKUP($D13,Specifications!$A:$AX,10,FALSE)) | S13: =IF($A13<1,"",VLOOKUP($D13,Specifications!$A:$AX,11,FALSE)) | U13: =IF($A13<1,"",VLOOKUP($D13,Specifications!$A:$AX,12,FALSE)) | W13: =IF($A13<1,"",VLOOKUP($D13,Specifications!$A:$AX,13,FALSE)) | Y13: =IF($A13<1,"",VLOOKUP($D13,Specifications!$A:$AX,14,FALSE)) | AA13: =IF($A13<1,"",VLOOKUP($D13,Specifications!$A:$AX,15,FALSE)) | AC13: =IF($A13<1,"",VLOOKUP($D13,Specifications!$A:$AX,16,FALSE)) | AE13: =IF($A13<1,"",VLOOKUP($D13,Specifications!$A:$AX,17,FALSE)) | AG13: =IF($A13<1,"",VLOOKUP($D13,Specifications!$A:$AX,18,FALSE)) | AI13: =IF($A13<1,"",VLOOKUP($D13,Specifications!$A:$AX,19,FALSE)) | AK13: =IF($A13<1,"",VLOOKUP($D13,Specifications!$A:$AX,20,FALSE)) | AM13: =IF($A13<1,"",VLOOKUP($D13,Specifications!$A:$AX,21,FALSE)) | AO13: =IF($A13<1,"",VLOOKUP($D13,Specifications!$A:$AX,22,FALSE)) | AQ13: =IF($A13<1,"",VLOOKUP($D13,Specifications!$A:$AX,23,FALSE)) | AS13: =IF($A13<1,"",VLOOKUP($D13,Specifications!$A:$AX,24,FALSE)) | AU13: =IF($A13<1,"",VLOOKUP($D13,Specifications!$A:$AX,25,FALSE)) | AW13: =IF($A13<1,"",VLOOKUP($D13,Specifications!$A:$AX,26,FALSE)) | AY13: =IF($A13<1,"",VLOOKUP($D13,Specifications!$A:$AX,27,FALSE)) | BA13: =IF($A13<1,"",VLOOKUP($D13,Specifications!$A:$AX,28,FALSE)) | BC13: =IF($A13<1,"",VLOOKUP($D13,Specifications!$A:$AX,29,FALSE)) | BE13: =IF($A13<1,"",VLOOKUP($D13,Specifications!$A:$AX,30,FALSE)) | BG13: =IF($A13<1,"",VLOOKUP($D13,Specifications!$A:$AX,31,FALSE)) | BI13: =IF($A13<1,"",VLOOKUP($D13,Specifications!$A:$AX,32,FALSE)) | BK13: =IF($A13<1,"",VLOOKUP($D13,Specifications!$A:$AX,33,FALSE)) | BM13: =IF($A13<1,"",VLOOKUP($D13,Specifications!$A:$AX,34,FALSE)) | BO13: =IF($A13<1,"",VLOOKUP($D13,Specifications!$A:$AX,35,FALSE)) | BQ13: =IF($A13<1,"",VLOOKUP($D13,Specifications!$A:$AX,36,FALSE)) | BS13: =IF($A13<1,"",VLOOKUP($D13,Specifications!$A:$AX,37,FALSE)) | BU13: =IF($A13<1,"",VLOOKUP($D13,Specifications!$A:$AX,38,FALSE)) | BW13: =IF($A13<1,"",VLOOKUP($D13,Specifications!$A:$AX,39,FALSE)) | BY13: =IF($A13<1,"",VLOOKUP($D13,Specifications!$A:$AX,40,FALSE)) | CA13: =IF($A13<1,"",VLOOKUP($D13,Specifications!$A:$AX,41,FALSE)) | CC13: =IF($A13<1,"",VLOOKUP($D13,Specifications!$A:$AX,42,FALSE)) | CE13: =IF($A13<1,"",VLOOKUP($D13,Specifications!$A:$AX,43,FALSE)) | CG13: =IF($A13<1,"",VLOOKUP($D13,Specifications!$A:$AX,44,FALSE)) | CI13: =IF($A13<1,"",VLOOKUP($D13,Specifications!$A:$AX,45,FALSE)) | CK13: =IF($A13<1,"",VLOOKUP($D13,Specifications!$A:$AX,46,FALSE)) | CM13: =IF($A13<1,"",VLOOKUP($D13,Specifications!$A:$AX,47,FALSE)) | CO13: =IF($A13<1,"",VLOOKUP($D13,Specifications!$A:$AX,48,FALSE)) | CQ13: =IF($A13<1,"",VLOOKUP($D13,Specifications!$A:$AX,49,FALSE)) | CS13: =IF($A13<1,"",VLOOKUP($D13,Specifications!$A:$AX,50,FALSE))
... A500: =IF(ISBLANK('Asset Data'!C501),0,'Asset Data'!A501) -> 0 | B500: =IF($A500<1,"",VLOOKUP($A500,'Asset Data'!$A:$C,3,FALSE)) | C500: =IF(A500<1,"",VLOOKUP(D500,Specifications!A:B,2,FALSE)) | D500: =IF(A500<1,"",VLOOKUP(A500,'Asset Data'!A:W,23,FALSE)) | E500: =IF($A500<1,"",VLOOKUP($D500,Specifications!$A:$AX,4,FALSE)) | G500: =IF($A500<1,"",VLOOKUP($D500,Specifications!$A:$AX,5,FALSE)) | I500: =IF($A500<1,"",VLOOKUP($D500,Specifications!$A:$AX,6,FALSE)) | K500: =IF($A500<1,"",VLOOKUP($D500,Specifications!$A:$AX,7,FALSE)) | M500: =IF($A500<1,"",VLOOKUP($D500,Specifications!$A:$AX,8,FALSE)) | O500: =IF($A500<1,"",VLOOKUP($D500,Specifications!$A:$AX,9,FALSE)) | Q500: =IF($A500<1,"",VLOOKUP($D500,Specifications!$A:$AX,10,FALSE)) | S500: =IF($A500<1,"",VLOOKUP($D500,Specifications!$A:$AX,11,FALSE)) | U500: =IF($A500<1,"",VLOOKUP($D500,Specifications!$A:$AX,12,FALSE)) | W500: =IF($A500<1,"",VLOOKUP($D500,Specifications!$A:$AX,13,FALSE)) | Y500: =IF($A500<1,"",VLOOKUP($D500,Specifications!$A:$AX,14,FALSE)) | AA500: =IF($A500<1,"",VLOOKUP($D500,Specifications!$A:$AX,15,FALSE)) | AC500: =IF($A500<1,"",VLOOKUP($D500,Specifications!$A:$AX,16,FALSE)) | AE500: =IF($A500<1,"",VLOOKUP($D500,Specifications!$A:$AX,17,FALSE)) | AG500: =IF($A500<1,"",VLOOKUP($D500,Specifications!$A:$AX,18,FALSE)) | AI500: =IF($A500<1,"",VLOOKUP($D500,Specifications!$A:$AX,19,FALSE)) | AK500: =IF($A500<1,"",VLOOKUP($D500,Specifications!$A:$AX,20,FALSE)) | AM500: =IF($A500<1,"",VLOOKUP($D500,Specifications!$A:$AX,21,FALSE)) | AO500: =IF($A500<1,"",VLOOKUP($D500,Specifications!$A:$AX,22,FALSE)) | AQ500: =IF($A500<1,"",VLOOKUP($D500,Specifications!$A:$AX,23,FALSE)) | AS500: =IF($A500<1,"",VLOOKUP($D500,Specifications!$A:$AX,24,FALSE)) | AU500: =IF($A500<1,"",VLOOKUP($D500,Specifications!$A:$AX,25,FALSE)) | AW500: =IF($A500<1,"",VLOOKUP($D500,Specifications!$A:$AX,26,FALSE)) | AY500: =IF($A500<1,"",VLOOKUP($D500,Specifications!$A:$AX,27,FALSE)) | BA500: =IF($A500<1,"",VLOOKUP($D500,Specifications!$A:$AX,28,FALSE)) | BC500: =IF($A500<1,"",VLOOKUP($D500,Specifications!$A:$AX,29,FALSE)) | BE500: =IF($A500<1,"",VLOOKUP($D500,Specifications!$A:$AX,30,FALSE)) | BG500: =IF($A500<1,"",VLOOKUP($D500,Specifications!$A:$AX,31,FALSE)) | BI500: =IF($A500<1,"",VLOOKUP($D500,Specifications!$A:$AX,32,FALSE)) | BK500: =IF($A500<1,"",VLOOKUP($D500,Specifications!$A:$AX,33,FALSE)) | BM500: =IF($A500<1,"",VLOOKUP($D500,Specifications!$A:$AX,34,FALSE)) | BO500: =IF($A500<1,"",VLOOKUP($D500,Specifications!$A:$AX,35,FALSE)) | BQ500: =IF($A500<1,"",VLOOKUP($D500,Specifications!$A:$AX,36,FALSE)) | BS500: =IF($A500<1,"",VLOOKUP($D500,Specifications!$A:$AX,37,FALSE)) | BU500: =IF($A500<1,"",VLOOKUP($D500,Specifications!$A:$AX,38,FALSE)) | BW500: =IF($A500<1,"",VLOOKUP($D500,Specifications!$A:$AX,39,FALSE)) | BY500: =IF($A500<1,"",VLOOKUP($D500,Specifications!$A:$AX,40,FALSE)) | CA500: =IF($A500<1,"",VLOOKUP($D500,Specifications!$A:$AX,41,FALSE)) | CC500: =IF($A500<1,"",VLOOKUP($D500,Specifications!$A:$AX,42,FALSE)) | CE500: =IF($A500<1,"",VLOOKUP($D500,Specifications!$A:$AX,43,FALSE)) | CG500: =IF($A500<1,"",VLOOKUP($D500,Specifications!$A:$AX,44,FALSE)) | CI500: =IF($A500<1,"",VLOOKUP($D500,Specifications!$A:$AX,45,FALSE)) | CK500: =IF($A500<1,"",VLOOKUP($D500,Specifications!$A:$AX,46,FALSE)) | CM500: =IF($A500<1,"",VLOOKUP($D500,Specifications!$A:$AX,47,FALSE)) | CO500: =IF($A500<1,"",VLOOKUP($D500,Specifications!$A:$AX,48,FALSE)) | CQ500: =IF($A500<1,"",VLOOKUP($D500,Specifications!$A:$AX,49,FALSE)) | CS500: =IF($A500<1,"",VLOOKUP($D500,Specifications!$A:$AX,50,FALSE))
