Workbook
Name __bookmark_1: '[2]1502000 FX'!#REF!
Name __bookmark_1: '[2]1502000 FX'!#REF!
Name __bookmark_1: '[2]1502000 FX'!#REF!
Name _FTE1: #REF!
Name _FTE1: #REF!
Name _FTE1: #REF!
Name _ORG1: #REF!
Name _ORG1: #REF!
Name _ORG1: #REF!
Name Additional_Costs_1_Cost: #REF!
Name Additional_Costs_1_Cost: #REF!
Name Additional_Costs_1_Cost: #REF!
Name Additional_Costs_2_Cost: #REF!
Name Additional_Costs_2_Cost: #REF!
Name Additional_Costs_2_Cost: #REF!
Name Additional_Costs_3_Cost: #REF!
Name Additional_Costs_3_Cost: #REF!
Name Additional_Costs_3_Cost: #REF!
Name Additional_Costs_4_Cost: #REF!
Name Additional_Costs_4_Cost: #REF!
Name Additional_Costs_4_Cost: #REF!
Name Additional_Costs_5_Cost: #REF!
Name Additional_Costs_5_Cost: #REF!
Name Additional_Costs_5_Cost: #REF!
Name Additional_Costs_6_Cost: #REF!
Name Additional_Costs_6_Cost: #REF!
Name Additional_Costs_6_Cost: #REF!
Name Allocated_Labor_Cost_per_Production_Man_Hour: #REF!
Name Allocated_Labor_Cost_per_Production_Man_Hour: #REF!
Name Allocated_Labor_Cost_per_Production_Man_Hour: #REF!
Name annex: #REF!
Name annex: #REF!
Name annex: #REF!
Name ANNEX1: #REF!
Name ANNEX1: #REF!
Name ANNEX1: #REF!
Name Area_of_Country_List: #REF!
Name Area_of_Country_List: #REF!
Name Area_of_Country_List: #REF!
Name AREA1: #REF!
Name AREA1: #REF!
Name AREA1: #REF!
Name ARRA_Compliant: #REF!
Name ARRA_Compliant: #REF!
Name ARRA_Compliant: #REF!
Name Ballast_Codes: #REF!
Name Ballast_Codes: #REF!
Name Ballast_Codes: #REF!
Name Ballast_Specs: #REF!
Name Ballast_Specs: #REF!
Name Ballast_Specs: #REF!
Name BASE_ST_MP: '[5]BASE WAGES & BENEFITS - ST'!$A$4:$AM$33
Name BASE_ST_TCNJ: '[5]BASE WAGES & BENEFITS - ST'!$A$258:$AN$295
Name BASE_ST_TCNP: '[5]BASE WAGES & BENEFITS - ST'!$A$38:$AM$253
Name BBB_Charge: #REF!
Name BBB_Charge: #REF!
Name BBB_Charge: #REF!
Name BBB_Labor_Charge: #REF!
Name BBB_Labor_Charge: #REF!
Name BBB_Labor_Charge: #REF!

Sheet CLIN 0001 Base Period RW
C1: Attachment J-0200000-17
C2: Exhibit Line Item Numbers - NAVSTA Mayport
C3: Contract No.: N6945025R0003
C4: CLIN 0001 - Recurring Work - Base Period
C5: Provide Prices for Recurring Work in accordance with Section C, Spec Item 3
C6: ELINs A001 through A014
A7: Customer | B7: Funding Source | C7: Category | D7: Sub-Category | E7: ELIN | F7: Sub-ELIN | G7: Annex/Sub-annex | H7: Spec Item | I7: Description | J7: Quantity | K7: Unit of Measure | L7: Unit Price | M7: Extended Price
A8: CNRSE | B8: Port Ops | C8: Port Operations | D8: Port Ops Equipment Work Order | E8: A001 | F8: A001AA | G8: 0600000 | H8: 3.1 | I8: Port Ops Equipment Work Order | J8: 20 | K8: EA
A9: CNRSE | B9: Port Ops | C9: Port Operations | D9: Recurring Work | E9: A001 | F9: A001AB | G9: 0600000 | H9: 3.2 | I9: Ship Movements - Berthing and Hotel Services | J9: 12 | K9: MO
A10: CNRSE | B10: CNRSE FP | C10: Facility Management | D10: Recurring Work | E10: A001 | F10: A001AC | G10: 1501000 | H10: 3.1 | I10: NAVFAC Maximo Data Entry | J10: 12 | K10: MO
A11: CNRSE | B11: CNRSE FP | C11: Facility Management | D11: Recurring Work | E11: A001 | F11: A001AD | G11: 1501000 | H11: 3.2 | I11: Infrastructure Condition Assessment Program (ICAP) Services | J11: 12 | K11: MO
A12: CNRSE | B12: CNRSE FP | C12: Facility Management | D12: Recurring Work | E12: A001 | F12: A001AE | G12: 1501000 | H12: 3.3 | I12: Technical Library Operations | J12: 12 | K12: MO
A13: CNRSE | B13: CNRSE ST-FAC | C13: Facility Investment | D13: E/U/R Work Orders | E13: A001 | F13: A001AF | G13: 1502000 | H13: 3.1 | I13: Emergency, Urgent and Routine (E/U/R) Work | J13: 3658 | K13: EA
A14: CNRSE | B14: CNRSE ST-FAC | C14: Facility Investment | D14: Recurring Work | E14: A001 | F14: A001AG | G14: 1502000 | H14: 3.2 | I14: Project Work Orders | J14: 50 | K14: EA
A15: CNRSE | B15: CNRSE ST-FAC | C15: Facility Investment | D15: Preventive Maintenance (PM) Program | E15: A001 | F15: A001AH | G15: 1502000 | H15: 3.3.1 | I15: Airfield Lighting Systems | J15: 12 | K15: MO
A16: CNRSE | B16: CNRSE ST-FAC | C16: Facility Investment | D16: Preventive Maintenance (PM) Program | E16: A001 | F16: A001AJ | G16: 1502000 | H16: 3.3.2 | I16: Auxiliary Generator Systems | J16: 12 | K16: MO
A17: CNRSE | B17: CNRSE ST-FAC | C17: Facility Investment | D17: Preventive Maintenance (PM) Program | E17: A001 | F17: A001AK | G17: 1502000 | H17: 3.3.3 | I17: Boiler and Unfired Pressure Vessel (UPV) Systems | J17: 12 | K17: MO
A18: CNRSE | B18: CNRSE ST-FAC | C18: Facility Investment | D18: Preventive Maintenance (PM) Program | E18: A001 | F18: A001AL | G18: 1502000 | H18: 3.3.4 | I18: Compressed Air Systems | J18: 12 | K18: MO
A19: CNRSE | B19: CNRSE ST-FAC | C19: Facility Investment | D19: Preventive Maintenance (PM) Program | E19: A001 | F19: A001AM | G19: 1502000 | H19: 3.3.5 | I19: Door and Gate Systems | J19: 12 | K19: MO
A20: CNRSE | B20: CNRSE ST-FAC | C20: Facility Investment | D20: Preventive Maintenance (PM) Program | E20: A001 | F20: A001AN | G20: 1502000 | H20: 3.3.6 | I20: Fire Protection Systems | J20: 12 | K20: MO
A21: CNRSE | B21: CNRSE ST-FAC | C21: Facility Investment | D21: Preventive Maintenance (PM) Program | E21: A001 | F21: A001AP | G21: 1502000 | H21: 3.3.7 | I21: Frequency Converter (400 HZ) Systems | J21: 12 | K21: MO
A22: CNRSE | B22: CNRSE ST-FAC | C22: Facility Investment | D22: Preventive Maintenance (PM) Program | E22: A001 | F22: A001AQ | G22: 1502000 | H22: 3.3.8 | I22: Galley Equipment and Systems | J22: 12 | K22: MO
A23: CNRSE | B23: CNRSE ST-FAC | C23: Facility Investment | D23: Preventive Maintenance (PM) Program | E23: A001 | F23: A001AR | G23: 1502000 | H23: 3.3.9 | I23: HVAC and Refrigeration Systems | J23: 12 | K23: MO
A24: CNRSE | B24: CNRSE ST-FAC | C24: Facility Investment | D24: Preventive Maintenance (PM) Program | E24: A001 | F24: A001AS | G24: 1502000 | H24: 3.3.10 | I24: Security Systems and Equipment | J24: 12 | K24: MO
A25: CNRSE | B25: CNRSE ST-FAC | C25: Facility Investment | D25: Preventive Maintenance (PM) Program | E25: A001 | F25: A001AT | G25: 1502000 | H25: 3.3.11 | I25: Uninterruptible Power Supplies (UPS) | J25: 12 | K25: MO
A26: CNRSE | B26: CNRSE ST-FAC | C26: Facility Investment | D26: Preventive Maintenance (PM) Program | E26: A001 | F26: A001AU | G26: 1502000 | H26: 3.3.12 | I26: Vertical Transportation Equipment (VTE) | J26: 12 | K26: MO
... A42: CNRSE | B42: CNRSE ST-FAC | C42: Facility Investment | D42: Other Recurring Services Program | E42: A001 | F42: A001BL | G42: 1502000 | H42: 3.5.11 | I42: Spot Coolers | J42: 12 | K42: MO
A43: CNRSE | B43: CNRSE ST-FAC | C43: Facility Investment | D43: Other (Swimming Pools) | E43: A001 | F43: A001BM | G43: 1503040 | H43: 3.1 | I43: Pool Operator Maintenance | J43: 12 | K43: MO
A44: CNRSE | B44: CNRSE ST-FAC | C44: Facility Investment | D44: Other (Swimming Pools) | E44: A001 | F44: A001BN | G44: 1503040 | H44: 3.2 | I44: Preventive Maintenance (PM) Program | J44: 12 | K44: MO
A45: CNRSE | B45: CNRSE FX | C45: Facility Investment | D45: Other (Swimming Pools) | E45: A001 | F45: A001BP | G45: 1503040 | H45: 3.3 | I45: Water Treatment | J45: 12 | K45: MO
A46: CNRSE | B46: CNRSE UT | C46: Utilities Management | D46: Utility Operations Support | E46: A001 | F46: A001BQ | G46: 1601000 | H46: 3.1 | I46: Utility Operations Support | J46: 12 | K46: MO
A47: CNRSE | B47: CNRSE UT | C47: Utilities Management | D47: Recurring Work | E47: A001 | F47: A001BR | G47: 1601000 | H47: 3.2 | I47: Utility Infrastructure Condition Assessment Program (UICAP) Support | J47: 12 | K47: MO
A48: CNRSE | B48: CNRSE UT | C48: Utilities Management | D48: Recurring Work | E48: A001 | F48: A001BS | G48: 1601000 | H48: 3.3 | I48: Operation and Management of Facility Related Control Systems (FRCS) | J48: 12 | K48: MO
A49: CNRSE | B49: CNRSE UT | C49: Utilities Management | D49: Recurring Work | E49: A001 | F49: A001BT | G49: 1601000 | H49: 3.4 | I49: NAVFAC Maximo Data Entry | J49: 12 | K49: MO
A50: CNRSE | B50: CNRSE UT | C50: Electrical | D50: Recurring Work | E50: A001 | F50: A001BU | G50: 1602000 | H50: 3.1 | I50: Operate Electrical Power Transmission and Distribution Systems | J50: 12 | K50: MO
A51: CNRSE | B51: CNRSE ST | C51: Electrical | D51: E/U/R Work Orders | E51: A001 | F51: A001BV | G51: 1602000 | H51: 3.2 | I51: Emergency, Urgent and Routine (E/U/R) Work | J51: 220 | K51: EA
A52: CNRSE | B52: CNRSE ST | C52: Electrical | D52: Recurring Work | E52: A001 | F52: A001BW | G52: 1602000 | H52: 3.3 | I52: Preventive Maintenance (PM) Program | J52: 12 | K52: MO
A53: CNRSE | B53: CNRSE UT | C53: Electrical | D53: Other Recurring Services Program | E53: A001 | F53: A001BX | G53: 1602000 | H53: 3.4 | I53: Other Recurring Services | J53: 12 | K53: MO
A54: CNRSE | B54: CNRSE UT | C54: Electrical | D54: Other Recurring Services Program | E54: A001 | F54: A001BY | G54: 1602000 | H54: 3.5 | I54: Utility Right of Way Clearance | J54: 12 | K54: MO
A55: CNRSE | B55: CNRSE TR | C55: Transportation | D55: Operations | E55: A001 | F55: A001BZ | G55: 1700000 | H55: 3.1.1 | I55: WHE/MHE/NTVE Services | J55: 12 | K55: MO
...

Sheet CLIN 0002 Base Period N-RW
B1: Attachment J-0200000-17
B2: Exhibit Line Item Numbers - NAVSTA Mayport
B3: Contract No.: N6945025R0003
B5: CLIN 0002 - Non-Recurring Work - Base Period
B6: Provide Prices for Recurring Work in accordance with Section C, Spec Item 4
B7: ELINs A700 through A718
A8: ELIN | B8: Product Name (120 Characters) | C8: Description Extended | D8: Estimated Quantity | E8: Unit of Measure | F8: Unit Price | G8: Extended Price
A9: A700 | B9: Unit Priced Labor Hour Work - MUST BE NEGOTIATED BY KO. | C9: The Contractor shall perform all UPL work in accordance with the scope and delivery schedule negotiated per each task order. Refer to: Section C, Annex 0200000 Managmenent and Administration, Specification Item 2.15.2 Unit Priced Labor (UPL)Work (Negotiated) for description of UPL Work. Refer to: Section J, Annex 0200000 Managmenent and Administration, Attachment J-0200000-01 Definitions and Acronyms for description of Unit Priced Labor (UPL) Hour and Universal Equipment. Task order completion times will be specified on each task order. For self-performed work: the unit price proposed for Sub-ELIN A700AA will be used to determine the labor cost to the Governent. For subcontracted labor: the FBR proposed for Sub-ELIN A700AB will be used to determine the labor cost to the Governmnet. The estimated quantity of each Sub-ELIN is used to establish the ELIN Extended Price. During administration the labor Sub-ELINs may be used in any combination and quantity provided the ELIN extended price is not exceeded. The contract will not be modified to re-allocate capacity among labor SLINs. | D9: =G10+G11 -> 0 | E9: DO | F9: 1
A10: A700AA | B10: Self-Performed Unit Priced Labor Hour Work - MUST BE NEGOTIATED BY KO. | C10: The Contractor shall self-perform all UPL work in accordance with the scope and delivery schedule negotiated per each task order. Refer to: Section C, Annex 0200000 Managmenent and Administration, Specification Item 2.15.2 Unit Priced Labor (UPL)Work (Negotiated) for description of UPL Work. Refer to: Section J, Annex 0200000 Managmenent and Administration, Attachment J-0200000-01 Definitions and Acronyms for description of Unit Priced Labor (UPL) Hour and Universal Equipment. | D10: 16000 | E10: LH
A11: A700AB | B11: Subcontractor Labor (Fixed Burden Rate) - MUST BE NEGOTIATED BY KO. | C11: The Contractor shall perform management and oversight of subcontracted non-recurring work in accordance with the scope and delivery schedule negotiated per each task order. Refer to: Section C, Annex 0200000 Management and Administration, Specification Item 2.15.2.1.2 Subcontractor Requirements description of Sub. Refer to: Section J, Annex 0200000 Management and Administration, Attachment J-0200000-01 Definitions and Acronyms for definition of Sub-Contractor Fixed Burden Rate. The estimated quantity (in dollars) is provided. A Fixed Burdened Rate (FBR) shall be entered in the Unit Price column. The FBR shall include all direct and indirect factors for management and oversight of subcontracted non-recurring work. Similar to FBR example in J-0200000-01, if a 15% markup is the Contractor's proposed FBR, the Unit Price should be $1.15. During performance, if the lowest subcontractor labor proposal is $1,000.00 and the FBR is $1.15, the labor cost to the Government will be $1,150.00. (DO - Dollars). | D11: 1600000 | E11: DO
A12: A701 | B12: Material and Equipment - MUST BE NEGOTIATED BY KO. | C12: Provide all materials and construction equipment to perform Unit Priced Labor work per the scope and delivery schedule specified in the order. Pre-expended bin supplies and materials will not be included in the list of materials since the cost for these items were included in the labor hour unit price bid. Material prices provided by the Contractor shall be the lowest price available considering the availability of materials and the time constraints of the job. The direct material price shall be adjusted by all discounts and rebates for core value or salvage value that accrue to the Contractor. Contractor owned equipment rental rates shall be based on calculations set forth in US Army Corp of Engineers “Construction Equipment Ownership and Operating Expense Schedule (EP 1110-1-8 (Vol. 11) July 03 or latest revision) Chapter 2. The estitmate quantity (in dollars) is provided. A Fixed burdened rate (FBR) shall be entered in the Unit Price column. The FBR shall include factors for ordering, handling, and stockpiling materials and repair parts. Similar to FBR example in J-0200000-01, if a 10% markup is the Contractor's proposed FBR, the Unit Price should be $1.10. When multiplying the proposed Unit Price by the Estimated Quantity, the Extended Price should be During administration, if the vendor's invoice on material is $1,000.00 and the unit price is $1.10, the cost of the material to the government will be $1,050.00. (DO - Dollars) | D12: 2000000 | E12: DO
A13: A702 | B13: Category I Calls - MUST BE NEGOTIATED BY KO. | C13: The Contractor shall perform Category I Calls to accomplish any work identified within the entire boundary of the installation and will include a wide variety of work. Category I Calls shall be completed within two weeks of receipt of call order, unless otherwise agreed to by the customer and contractor and annotated on the CAT call request. As part of the Category I Call, the Contractor has full responsibility for any work identified up to the Category I Call Threshold of $5,000 in direct labor and direct material, per Category I Call. A Blanket Task Order (BTO) may be issued on a DD Form 1155 with a Not To Exceed (NTE) quantity and value for Non-recurring Work Category Calls. | D13: 115 | E13: EA
A14: A703 | B14: Category II Calls - MUST BE NEGOTIATED BY KO. | C14: The Contractor shall perform Category II Calls to accomplish any work identified within the entire boundary of the installation and will include a wide variety of work. Category II Calls shall be completed within three weeks of receipt of call order, unless otherwise agreed to by the customer and contractor and annotated on the CAT call request. As part of the Category II Call, the Contractor has full responsibility for any work identified up to the Category II Call Threshold of $7,500 in direct labor and direct material, per Category II Call. A Blanket Task Order (BTO) may be issued on a DD Form 1155 with a Not To Exceed (NTE) quantity and value for Non-recurring Work Category Calls. | D14: 130 | E14: EA
A15: A704 | B15: Category III Calls - MUST BE NEGOTIATED BY KO. | C15: The Contractor shall perform Category III Calls to accomplish any work identified within the entire boundary of the installation and will include a wide variety of work. Category III Calls shall be completed within 30 days of receipt of call order, unless otherwise agreed to by the customer and contractor and annotated on the CAT call request. As part of the Category III Call, the Contractor has full responsibility for any work identified up to the Category III Call Threshold of $10,000 in direct labor and direct material, per Category III Call. A Blanket Task Order (BTO) may be issued on a DD Form 1155 with a Not To Exceed (NTE) quantity and value for Non-recurring Work Category Calls. | D15: 95 | E15: EA
A16: A705 | B16: Category IV Calls - MUST BE NEGOTIATED BY KO. | C16: The Contractor shall perform Category IV Calls to accomplish any work identified within the entire boundary of the installation and will include a wide variety of work. Category IV Calls shall be completed within 30 days of receipt of call order, unless otherwise agreed to by the customer and contractor and annotated on the CAT call request. As part of the Category IV Call, the Contractor has full responsibility for any work identified up to the Category IV Call Threshold of $12,500 in direct labor and direct material, per Category IV Call. A Blanket Task Order (BTO) may be issued on a DD Form 1155 with a Not To Exceed (NTE) quantity and value for Non-recurring Work Category Calls. | D16: 50 | E16: EA
A17: A706 | B17: Category V Calls - MUST BE NEGOTIATED BY KO. | C17: The Contractor shall perform Category V Calls to accomplish any work identified within the entire boundary of the installation and will include a wide variety of work. Category V Calls shall be completed within 30 days of receipt of call order, unless otherwise agreed to by the customer and contractor and annotated on the CAT call request. As part of the Category V Call, the Contractor has full responsibility for any work identified up to the Category V Call Threshold of $15,000 in direct labor and direct material, per Category V Call. A Blanket Task Order (BTO) may be issued on a DD Form 1155 with a Not To Exceed (NTE) quantity and value for Non-recurring Work Category Calls. | D17: 40 | E17: EA
A18: A707 | B18: Category VI Calls - MUST BE NEGOTIATED BY KO. | C18: The Contractor shall perform Category VI Calls to accomplish any work identified within the entire boundary of the installation and will include a wide variety of work. Category VI Calls shall be completed within 30 days of receipt of call order, unless otherwise agreed to by the customer and contractor and annotated on the CAT call request. As part of the Category VI Call, the Contractor has full responsibility for any work identified up to the Category VI Call Threshold of $17,500 in direct labor and direct material, per Category VI Call. A Blanket Task Order (BTO) may be issued on a DD Form 1155 with a Not To Exceed (NTE) quantity and value for Non-recurring Work Category Calls. | D18: 30 | E18: EA
A19: A708 | B19: Category VII Calls - MUST BE NEGOTIATED BY KO. | C19: The Contractor shall perform Category VII Calls to accomplish any work identified within the entire boundary of the installation and will include a wide variety of work. Category VII Calls shall be completed within 30 days of receipt of call order, unless otherwise agreed to by the customer and contractor and annotated on the CAT call request. As part of the Category VII Call, the Contractor has full responsibility for any work identified up to the Category VII Call Threshold of $20,000 in direct labor and direct material, per Category VII Call. A Blanket Task Order (BTO) may be issued on a DD Form 1155 with a Not To Exceed (NTE) quantity and value for Non-recurring Work Category Calls. | D19: 20 | E19: EA
A20: A709 | B20: Water Damage Removal available on FEDMALL | C20: The Contractor shall carefully remove and dispose of damaged interior finishes to include drywall, carpeting, etc. to prevent further damage or mold/mildew development in the event of water intrusion into a facility. In addition to the removal of the interior finishes, the Contractor shall dry the effected areas by providing dehumidifaction and airflow to remove any moisture from the space. Work shall begin within 12 hours of notification. Task order completion times will be specified on each task order. | D20: 20000 | E20: SF
A21: A710 | B21: Temporary Roof Repairs available on FEDMALL | C21: The Contractor shall provide all labor, material, and equipment to perform temporary roof repairs (i.e. tarping, roof patches, polyethylene film, etc.) to minimize water intrusion into a facility. Roof repairs shall be sufficient to last for a period no less than six months before requiring replacement or further repair.Within six months from the date of the original installation, the Contractor shall provide repairs and maintenance of the temporary repair at no additional cost to the Government. Work shall begin within 12 hours of notification. Task order completion times will be specified on each task order. | D21: 30000 | E21: SF
... A29: A718 | B29: Blount Island Shoreline Cleanup available on FEDMALL | C29: The Contractor shall perfrome shore cleanup, following the MCSF-BI Integrated Natural Resources Management Plan (INRMP). The shoreline clean up covers approximately 5 acres, and includes removal of debris, separation of recycling and not recycling materials, and proper disposal of the removed materials. The Contractor shall submit a report to the contracting Officer within 2 days after each service. Work shall begin within 12 hours of notification. | D29: 2 | E29: EA
A30: Total Non-recurring Work - Base Period:

Sheet CLIN 0003 Base Water RW
B1: Attachment J-0200000-17
B2: Exhibit Line Item Numbers - NAVSTA Mayport
B3: Contract No.: N6945025R0003
B6: CLIN 0003 - UT Recurring Work - Base Period
B7: Provide Prices for Recurring Work in accordance with Section C, Spec Item 3
B8: ELIN A015
A9: Customer/ Program | B9: Category | C9: Sub-Category | D9: ELIN | E9: Sub-ELIN | F9: Annex/Sub-annex | G9: Spec Item | H9: Description | I9: Quantity | J9: Unit of Measure | K9: Unit Price | L9: Extended Price
A10: CNRSE UT | B10: Water | C10: Recurring Services | D10: A015 | E10: A015AA | F10: 1606000 | G10: 3.1 | H10: Operation | I10: 12 | J10: MO
A11: CNRSE ST | B11: Water | C11: E/U/R Work Orders | D11: A015 | E11: A015AC | F11: 1606000 | G11: 3.2.2 | H11: E/U/R Work Orders | I11: 80 | J11: EA
A12: CNRSE ST | B12: Water | C12: Recurring Services | D12: A015 | E12: A015AE | F12: 1606000 | G12: 3.3 | H12: Preventive Maintenance (PM) | I12: 12 | J12: MO
A13: CNRSE UT | B13: Water | C13: Recurring Services | D13: A015 | E13: A015AF | F13: 1606000 | G13: 3.4 | H13: Inspection, Testing, and Certification of Fire Hydrants | I13: 12 | J13: MO

Sheet CLIN 0004 1st Period Opt RW
C1: Attachment J-0200000-17
C2: Exhibit Line Item Numbers - NAVSTA Mayport
C3: Contract No.: N6945025R0003
C4: CLIN 0004 - Recurring Work - First Option Period
C5: Provide Prices for Recurring Work in accordance with Section C, Spec Item 3
C6: ELINs B001 through B014
A7: Customer | B7: Funding Source | C7: Category | D7: Sub-Category | E7: ELIN | F7: Sub-ELIN | G7: Annex/Sub-annex | H7: Spec Item | I7: Description | J7: Quantity | K7: Unit of Measure | L7: Unit Price | M7: Extended Price
A8: CNRSE | B8: Port Ops | C8: Port Operations | D8: Port Ops Equipment Work Order | E8: B001 | F8: B001AA | G8: 0600000 | H8: 3.1 | I8: Port Ops Equipment Work Order | J8: 20 | K8: EA
A9: CNRSE | B9: Port Ops | C9: Port Operations | D9: Recurring Work | E9: B001 | F9: B001AB | G9: 0600000 | H9: 3.2 | I9: Ship Movements - Berthing and Hotel Services | J9: 12 | K9: MO
A10: CNRSE | B10: CNRSE FP | C10: Facility Management | D10: Recurring Work | E10: B001 | F10: B001AC | G10: 1501000 | H10: 3.1 | I10: NAVFAC Maximo Data Entry | J10: 12 | K10: MO
A11: CNRSE | B11: CNRSE FP | C11: Facility Management | D11: Recurring Work | E11: B001 | F11: B001AD | G11: 1501000 | H11: 3.2 | I11: Infrastructure Condition Assessment Program (ICAP) Services | J11: 12 | K11: MO
A12: CNRSE | B12: CNRSE FP | C12: Facility Management | D12: Recurring Work | E12: B001 | F12: B001AE | G12: 1501000 | H12: 3.3 | I12: Technical Library Operations | J12: 12 | K12: MO
A13: CNRSE | B13: CNRSE ST-FAC | C13: Facility Investment | D13: E/U/R Work Orders | E13: B001 | F13: B001AF | G13: 1502000 | H13: 3.1 | I13: Emergency, Urgent and Routine (E/U/R) Work | J13: 3658 | K13: EA
A14: CNRSE | B14: CNRSE ST-FAC | C14: Facility Investment | D14: Recurring Work | E14: B001 | F14: B001AG | G14: 1502000 | H14: 3.2 | I14: Project Work Orders | J14: 50 | K14: EA
A15: CNRSE | B15: CNRSE ST-FAC | C15: Facility Investment | D15: Preventive Maintenance (PM) Program | E15: B001 | F15: B001AH | G15: 1502000 | H15: 3.3.1 | I15: Airfield Lighting Systems | J15: 12 | K15: MO
A16: CNRSE | B16: CNRSE ST-FAC | C16: Facility Investment | D16: Preventive Maintenance (PM) Program | E16: B001 | F16: B001AJ | G16: 1502000 | H16: 3.3.2 | I16: Auxiliary Generator Systems | J16: 12 | K16: MO
A17: CNRSE | B17: CNRSE ST-FAC | C17: Facility Investment | D17: Preventive Maintenance (PM) Program | E17: B001 | F17: B001AK | G17: 1502000 | H17: 3.3.3 | I17: Boiler and Unfired Pressure Vessel (UPV) Systems | J17: 12 | K17: MO
A18: CNRSE | B18: CNRSE ST-FAC | C18: Facility Investment | D18: Preventive Maintenance (PM) Program | E18: B001 | F18: B001AL | G18: 1502000 | H18: 3.3.4 | I18: Compressed Air Systems | J18: 12 | K18: MO
A19: CNRSE | B19: CNRSE ST-FAC | C19: Facility Investment | D19: Preventive Maintenance (PM) Program | E19: B001 | F19: B001AM | G19: 1502000 | H19: 3.3.5 | I19: Door and Gate Systems | J19: 12 | K19: MO
A20: CNRSE | B20: CNRSE ST-FAC | C20: Facility Investment | D20: Preventive Maintenance (PM) Program | E20: B001 | F20: B001AN | G20: 1502000 | H20: 3.3.6 | I20: Fire Protection Systems | J20: 12 | K20: MO
A21: CNRSE | B21: CNRSE ST-FAC | C21: Facility Investment | D21: Preventive Maintenance (PM) Program | E21: B001 | F21: B001AP | G21: 1502000 | H21: 3.3.7 | I21: Frequency Converter (400 HZ) Systems | J21: 12 | K21: MO
A22: CNRSE | B22: CNRSE ST-FAC | C22: Facility Investment | D22: Preventive Maintenance (PM) Program | E22: B001 | F22: B001AQ | G22: 1502000 | H22: 3.3.8 | I22: Galley Equipment and Systems | J22: 12 | K22: MO
A23: CNRSE | B23: CNRSE ST-FAC | C23: Facility Investment | D23: Preventive Maintenance (PM) Program | E23: B001 | F23: B001AR | G23: 1502000 | H23: 3.3.9 | I23: HVAC and Refrigeration Systems | J23: 12 | K23: MO
A24: CNRSE | B24: CNRSE ST-FAC | C24: Facility Investment | D24: Preventive Maintenance (PM) Program | E24: B001 | F24: B001AS | G24: 1502000 | H24: 3.3.10 | I24: Security Systems and Equipment | J24: 12 | K24: MO
A25: CNRSE | B25: CNRSE ST-FAC | C25: Facility Investment | D25: Preventive Maintenance (PM) Program | E25: B001 | F25: B001AT | G25: 1502000 | H25: 3.3.11 | I25: Uninterruptible Power Supplies (UPS) | J25: 12 | K25: MO
A26: CNRSE | B26: CNRSE ST-FAC | C26: Facility Investment | D26: Preventive Maintenance (PM) Program | E26: B001 | F26: B001AU | G26: 1502000 | H26: 3.3.12 | I26: Vertical Transportation Equipment (VTE) | J26: 12 | K26: MO
... A42: CNRSE | B42: CNRSE ST-FAC | C42: Facility Investment | D42: Other Recurring Services Program | E42: B001 | F42: B001BL | G42: 1502000 | H42: 3.5.11 | I42: Spot Coolers | J42: 12 | K42: MO
A43: CNRSE | B43: CNRSE ST-FAC | C43: Facility Investment | D43: Other (Swimming Pools) | E43: B001 | F43: B001BM | G43: 1503040 | H43: 3.1 | I43: Pool Operator Maintenance | J43: 12 | K43: MO
A44: CNRSE | B44: CNRSE ST-FAC | C44: Facility Investment | D44: Other (Swimming Pools) | E44: B001 | F44: B001BN | G44: 1503040 | H44: 3.2 | I44: Preventive Maintenance (PM) Program | J44: 12 | K44: MO
A45: CNRSE | B45: CNRSE FX | C45: Facility Investment | D45: Other (Swimming Pools) | E45: B001 | F45: B001BP | G45: 1503040 | H45: 3.3 | I45: Water Treatment | J45: 12 | K45: MO
A46: CNRSE | B46: CNRSE UT | C46: Utilities Management | D46: Utility Operations Support | E46: B001 | F46: B001BQ | G46: 1601000 | H46: 3.1 | I46: Utility Operations Support | J46: 12 | K46: MO
A47: CNRSE | B47: CNRSE UT | C47: Utilities Management | D47: Recurring Work | E47: B001 | F47: B001BR | G47: 1601000 | H47: 3.2 | I47: Utility Infrastructure Condition Assessment Program (UICAP) Support | J47: 12 | K47: MO
A48: CNRSE | B48: CNRSE UT | C48: Utilities Management | D48: Recurring Work | E48: B001 | F48: B001BS | G48: 1601000 | H48: 3.3 | I48: Operation and Management of Facility Related Control Systems (FRCS) | J48: 12 | K48: MO
A49: CNRSE | B49: CNRSE UT | C49: Utilities Management | D49: Recurring Work | E49: B001 | F49: B001BT | G49: 1601000 | H49: 3.4 | I49: NAVFAC Maximo Data Entry | J49: 12 | K49: MO
A50: CNRSE | B50: CNRSE UT | C50: Electrical | D50: Recurring Work | E50: B001 | F50: B001BU | G50: 1602000 | H50: 3.1 | I50: Operate Electrical Power Transmission and Distribution Systems | J50: 12 | K50: MO
A51: CNRSE | B51: CNRSE ST | C51: Electrical | D51: E/U/R Work Orders | E51: B001 | F51: B001BV | G51: 1602000 | H51: 3.2 | I51: Emergency, Urgent and Routine (E/U/R) Work | J51: 220 | K51: EA
A52: CNRSE | B52: CNRSE ST | C52: Electrical | D52: Recurring Work | E52: B001 | F52: B001BW | G52: 1602000 | H52: 3.3 | I52: Preventive Maintenance (PM) Program | J52: 12 | K52: MO
A53: CNRSE | B53: CNRSE UT | C53: Electrical | D53: Other Recurring Services Program | E53: B001 | F53: B001BX | G53: 1602000 | H53: 3.4 | I53: Other Recurring Services | J53: 12 | K53: MO
A54: CNRSE | B54: CNRSE UT | C54: Electrical | D54: Other Recurring Services Program | E54: B001 | F54: B001BY | G54: 1602000 | H54: 3.5 | I54: Utility Right of Way Clearance | J54: 12 | K54: MO
A55: CNRSE | B55: CNRSE TR | C55: Transportation | D55: Operations | E55: B001 | F55: B001BZ | G55: 1700000 | H55: 3.1.1 | I55: WHE/MHE/NTVE Services | J55: 12 | K55: MO
...

Sheet CLIN 0005 1st Period Opt N-RW
B1: Attachment J-0200000-17
B2: Exhibit Line Item Numbers - NAVSTA Mayport
B3: Contract No.: N6945025R0003
B5: CLIN 0005 - Non-Recurring Work - Option Period 1
B6: Provide Prices for Recurring Work in accordance with Section C, Spec Item 4
B7: ELINs B700 through B718
A8: ELIN | B8: Product Name (120 Characters) | C8: Description Extended | D8: Estimated Quantity | E8: Unit of Measure | F8: Unit Price | G8: Extended Price
A9: B700 | B9: Unit Priced Labor Hour Work - MUST BE NEGOTIATED BY KO. | C9: The Contractor shall perform all UPL work in accordance with the scope and delivery schedule negotiated per each task order. Refer to: Section C, Annex 0200000 Managmenent and Administration, Specification Item 2.15.2 Unit Priced Labor (UPL)Work (Negotiated) for description of UPL Work. Refer to: Section J, Annex 0200000 Managmenent and Administration, Attachment J-0200000-01 Definitions and Acronyms for description of Unit Priced Labor (UPL) Hour and Universal Equipment. Task order completion times will be specified on each task order. For self-performed work: the unit price proposed for Sub-ELIN B700AA will be used to determine the labor cost to the Governent. For subcontracted labor: the FBR proposed for Sub-ELIN B700AB will be used to determine the labor cost to the Governmnet. The estimated quantity of each Sub-ELIN is used to establish the ELIN Extended Price. During administration the labor Sub-ELINs may be used in any combination and quantity provided the ELIN extended price is not exceeded. The contract will not be modified to re-allocate capacity among labor SLINs. | D9: =G10+G11 -> 0 | E9: DO | F9: 1
A10: B700AA | B10: Self-Performed Unit Priced Labor Hour Work - MUST BE NEGOTIATED BY KO. | C10: The Contractor shall self-perform all UPL work in accordance with the scope and delivery schedule negotiated per each task order. Refer to: Section C, Annex 0200000 Managmenent and Administration, Specification Item 2.15.2 Unit Priced Labor (UPL)Work (Negotiated) for description of UPL Work. Refer to: Section J, Annex 0200000 Managmenent and Administration, Attachment J-0200000-01 Definitions and Acronyms for description of Unit Priced Labor (UPL) Hour and Universal Equipment. | D10: ='CLIN 0002 Base Period N-RW'!D10 -> 16000 | E10: LH
A11: B700AB | B11: Subcontractor Labor (Fixed Burden Rate) - MUST BE NEGOTIATED BY KO. | C11: The Contractor shall perform management and oversight of subcontracted non-recurring work in accordance with the scope and delivery schedule negotiated per each task order. Refer to: Section C, Annex 0200000 Management and Administration, Specification Item 2.15.2.1.2 Subcontractor Requirements description of Sub. Refer to: Section J, Annex 0200000 Management and Administration, Attachment J-0200000-01 Definitions and Acronyms for definition of Sub-Contractor Fixed Burden Rate. The estimated quantity (in dollars) is provided. A Fixed Burdened Rate (FBR) shall be entered in the Unit Price column. The FBR shall include all direct and indirect factors for management and oversight of subcontracted non-recurring work. Similar to FBR example in J-0200000-01, if a 15% markup is the Contractor's proposed FBR, the Unit Price should be $1.15. During performance, if the lowest subcontractor labor proposal is $1,000.00 and the FBR is $1.15, the labor cost to the Government will be $1,150.00. (DO - Dollars). | D11: ='CLIN 0002 Base Period N-RW'!D11 -> 1600000 | E11: DO
A12: B701 | B12: Material and Equipment - MUST BE NEGOTIATED BY KO. | C12: Provide all materials and construction equipment to perform Unit Priced Labor work per the scope and delivery schedule specified in the order. Pre-expended bin supplies and materials will not be included in the list of materials since the cost for these items were included in the labor hour unit price bid. Material prices provided by the Contractor shall be the lowest price available considering the availability of materials and the time constraints of the job. The direct material price shall be adjusted by all discounts and rebates for core value or salvage value that accrue to the Contractor. Contractor owned equipment rental rates shall be based on calculations set forth in US Army Corp of Engineers “Construction Equipment Ownership and Operating Expense Schedule (EP 1110-1-8 (Vol. 11) July 03 or latest revision) Chapter 2. The estitmate quantity (in dollars) is provided. A Fixed burdened rate (FBR) shall be entered in the Unit Price column. The FBR shall include factors for ordering, handling, and stockpiling materials and repair parts. Similar to FBR example in J-0200000-01, if a 10% markup is the Contractor's proposed FBR, the Unit Price should be $1.10. When multiplying the proposed Unit Price by the Estimated Quantity, the Extended Price should be During administration, if the vendor's invoice on material is $1,000.00 and the unit price is $1.10, the cost of the material to the government will be $1,050.00. (DO - Dollars) | D12: ='CLIN 0002 Base Period N-RW'!D12 -> 2000000 | E12: DO
A13: B702 | B13: Category I Calls - MUST BE NEGOTIATED BY KO. | C13: The Contractor shall perform Category I Calls to accomplish any work identified within the entire boundary of the installation and will include a wide variety of work. Category I Calls shall be completed within two weeks of receipt of call order, unless otherwise agreed to by the customer and contractor and annotated on the CAT call request. As part of the Category I Call, the Contractor has full responsibility for any work identified up to the Category I Call Threshold of $5,000 in direct labor and direct material, per Category I Call. A Blanket Task Order (BTO) may be issued on a DD Form 1155 with a Not To Exceed (NTE) quantity and value for Non-recurring Work Category Calls. | D13: ='CLIN 0002 Base Period N-RW'!D13 -> 115 | E13: EA
A14: B703 | B14: Category II Calls - MUST BE NEGOTIATED BY KO. | C14: The Contractor shall perform Category II Calls to accomplish any work identified within the entire boundary of the installation and will include a wide variety of work. Category II Calls shall be completed within three weeks of receipt of call order, unless otherwise agreed to by the customer and contractor and annotated on the CAT call request. As part of the Category II Call, the Contractor has full responsibility for any work identified up to the Category II Call Threshold of $7,500 in direct labor and direct material, per Category II Call. A Blanket Task Order (BTO) may be issued on a DD Form 1155 with a Not To Exceed (NTE) quantity and value for Non-recurring Work Category Calls. | D14: ='CLIN 0002 Base Period N-RW'!D14 -> 130 | E14: EA
A15: B704 | B15: Category III Calls - MUST BE NEGOTIATED BY KO. | C15: The Contractor shall perform Category III Calls to accomplish any work identified within the entire boundary of the installation and will include a wide variety of work. Category III Calls shall be completed within 30 days of receipt of call order, unless otherwise agreed to by the customer and contractor and annotated on the CAT call request. As part of the Category III Call, the Contractor has full responsibility for any work identified up to the Category III Call Threshold of $10,000 in direct labor and direct material, per Category III Call. A Blanket Task Order (BTO) may be issued on a DD Form 1155 with a Not To Exceed (NTE) quantity and value for Non-recurring Work Category Calls. | D15: ='CLIN 0002 Base Period N-RW'!D15 -> 95 | E15: EA
A16: B705 | B16: Category IV Calls - MUST BE NEGOTIATED BY KO. | C16: The Contractor shall perform Category IV Calls to accomplish any work identified within the entire boundary of the installation and will include a wide variety of work. Category IV Calls shall be completed within 30 days of receipt of call order, unless otherwise agreed to by the customer and contractor and annotated on the CAT call request. As part of the Category IV Call, the Contractor has full responsibility for any work identified up to the Category IV Call Threshold of $12,500 in direct labor and direct material, per Category IV Call. A Blanket Task Order (BTO) may be issued on a DD Form 1155 with a Not To Exceed (NTE) quantity and value for Non-recurring Work Category Calls. | D16: ='CLIN 0002 Base Period N-RW'!D16 -> 50 | E16: EA
A17: B706 | B17: Category V Calls - MUST BE NEGOTIATED BY KO. | C17: The Contractor shall perform Category V Calls to accomplish any work identified within the entire boundary of the installation and will include a wide variety of work. Category V Calls shall be completed within 30 days of receipt of call order, unless otherwise agreed to by the customer and contractor and annotated on the CAT call request. As part of the Category V Call, the Contractor has full responsibility for any work identified up to the Category V Call Threshold of $15,000 in direct labor and direct material, per Category V Call. A Blanket Task Order (BTO) may be issued on a DD Form 1155 with a Not To Exceed (NTE) quantity and value for Non-recurring Work Category Calls. | D17: ='CLIN 0002 Base Period N-RW'!D17 -> 40 | E17: EA
A18: B707 | B18: Category VI Calls - MUST BE NEGOTIATED BY KO. | C18: The Contractor shall perform Category VI Calls to accomplish any work identified within the entire boundary of the installation and will include a wide variety of work. Category VI Calls shall be completed within 30 days of receipt of call order, unless otherwise agreed to by the customer and contractor and annotated on the CAT call request. As part of the Category VI Call, the Contractor has full responsibility for any work identified up to the Category VI Call Threshold of $17,500 in direct labor and direct material, per Category VI Call. A Blanket Task Order (BTO) may be issued on a DD Form 1155 with a Not To Exceed (NTE) quantity and value for Non-recurring Work Category Calls. | D18: ='CLIN 0002 Base Period N-RW'!D18 -> 30 | E18: EA
A19: B708 | B19: Category VII Calls - MUST BE NEGOTIATED BY KO. | C19: The Contractor shall perform Category VII Calls to accomplish any work identified within the entire boundary of the installation and will include a wide variety of work. Category VII Calls shall be completed within 30 days of receipt of call order, unless otherwise agreed to by the customer and contractor and annotated on the CAT call request. As part of the Category VII Call, the Contractor has full responsibility for any work identified up to the Category VII Call Threshold of $20,000 in direct labor and direct material, per Category VII Call. A Blanket Task Order (BTO) may be issued on a DD Form 1155 with a Not To Exceed (NTE) quantity and value for Non-recurring Work Category Calls. | D19: ='CLIN 0002 Base Period N-RW'!D19 -> 20 | E19: EA
A20: B709 | B20: Water Damage Removal available on FEDMALL | C20: The Contractor shall carefully remove and dispose of damaged interior finishes to include drywall, carpeting, etc. to prevent further damage or mold/mildew development in the event of water intrusion into a facility. In addition to the removal of the interior finishes, the Contractor shall dry the effected areas by providing dehumidifaction and airflow to remove any moisture from the space. Work shall begin within 12 hours of notification. Task order completion times will be specified on each task order. | D20: ='CLIN 0002 Base Period N-RW'!D20 -> 20000 | E20: SF
A21: B710 | B21: Temporary Roof Repairs available on FEDMALL | C21: The Contractor shall provide all labor, material, and equipment to perform temporary roof repairs (i.e. tarping, roof patches, polyethylene film, etc.) to minimize water intrusion into a facility. Roof repairs shall be sufficient to last for a period no less than six months before requiring replacement or further repair.Within six months from the date of the original installation, the Contractor shall provide repairs and maintenance of the temporary repair at no additional cost to the Government. Work shall begin within 12 hours of notification. Task order completion times will be specified on each task order. | D21: ='CLIN 0002 Base Period N-RW'!D21 -> 30000 | E21: SF
... A29: B718 | B29: Blount Island Shoreline Cleanup available on FEDMALL | C29: The Contractor shall perfrome shore cleanup, following the MCSF-BI Integrated Natural Resources Management Plan (INRMP). The shoreline clean up covers approximately 5 acres, and includes removal of debris, separation of recycling and not recycling materials, and proper disposal of the removed materials. The Contractor shall submit a report to the contracting Officer within 2 days after each service. Work shall begin within 12 hours of notification. | D29: ='CLIN 0002 Base Period N-RW'!D29 -> 2 | E29: EA
A30: Total Non-recurring Work - Base Period:

Sheet CLIN 0006 -1st Period Water RW
B1: Attachment J-0200000-17
B2: Exhibit Line Item Numbers - NAVSTA Mayport
B3: Contract No.: N6945025R0003
B6: CLIN 0006 - UT Recurring Work - First Option Period
B7: Provide Prices for Recurring Work in accordance with Section C, Spec Item 3
B8: ELIN B015
A9: Customer/ Program | B9: Category | C9: Sub-Category | D9: ELIN | E9: Sub-ELIN | F9: Annex/Sub-annex | G9: Spec Item | H9: Description | I9: Quantity | J9: Unit of Measure | K9: Unit Price | L9: Extended Price
A10: CNRSE UT | B10: Water | C10: Recurring Services | D10: B015 | E10: B015AA | F10: 1606000 | G10: 3.1 | H10: Operation | I10: 12 | J10: MO
A11: CNRSE ST | B11: Water | C11: E/U/R Work Orders | D11: B015 | E11: B015AC | F11: 1606000 | G11: 3.2.2 | H11: E/U/R Work Orders | I11: 80 | J11: EA
A12: CNRSE ST | B12: Water | C12: Recurring Services | D12: B015 | E12: B015AE | F12: 1606000 | G12: 3.3 | H12: Preventive Maintenance (PM) | I12: 12 | J12: MO
A13: CNRSE UT | B13: Water | C13: Recurring Services | D13: B015 | E13: B015AF | F13: 1606000 | G13: 3.4 | H13: Inspection, Testing, and Certification of Fire Hydrants | I13: 12 | J13: MO

Sheet CLIN 0007 2nd Period Opt RW
C1: Attachment J-0200000-17
C2: Exhibit Line Item Numbers - NAVSTA Mayport
C3: Contract No.: N6945025R0003
C4: CLIN 0007 - Recurring Work - Second Period
C5: Provide Prices for Recurring Work in accordance with Section C, Spec Item 3
C6: ELINs C001 through C014
A7: Customer | B7: Funding Source | C7: Category | D7: Sub-Category | E7: ELIN | F7: Sub-ELIN | G7: Annex/Sub-annex | H7: Spec Item | I7: Description | J7: Quantity | K7: Unit of Measure | L7: Unit Price | M7: Extended Price
A8: CNRSE | B8: Port Ops | C8: Port Operations | D8: Port Ops Equipment Work Order | E8: C001 | F8: C001AA | G8: 0600000 | H8: 3.1 | I8: Port Ops Equipment Work Order | J8: 20 | K8: EA
A9: CNRSE | B9: Port Ops | C9: Port Operations | D9: Recurring Work | E9: C001 | F9: C001AB | G9: 0600000 | H9: 3.2 | I9: Ship Movements - Berthing and Hotel Services | J9: 12 | K9: MO
A10: CNRSE | B10: CNRSE FP | C10: Facility Management | D10: Recurring Work | E10: C001 | F10: C001AC | G10: 1501000 | H10: 3.1 | I10: NAVFAC Maximo Data Entry | J10: 12 | K10: MO
A11: CNRSE | B11: CNRSE FP | C11: Facility Management | D11: Recurring Work | E11: C001 | F11: C001AD | G11: 1501000 | H11: 3.2 | I11: Infrastructure Condition Assessment Program (ICAP) Services | J11: 12 | K11: MO
A12: CNRSE | B12: CNRSE FP | C12: Facility Management | D12: Recurring Work | E12: C001 | F12: C001AE | G12: 1501000 | H12: 3.3 | I12: Technical Library Operations | J12: 12 | K12: MO
A13: CNRSE | B13: CNRSE ST-FAC | C13: Facility Investment | D13: E/U/R Work Orders | E13: C001 | F13: C001AF | G13: 1502000 | H13: 3.1 | I13: Emergency, Urgent and Routine (E/U/R) Work | J13: 3658 | K13: EA
A14: CNRSE | B14: CNRSE ST-FAC | C14: Facility Investment | D14: Recurring Work | E14: C001 | F14: C001AG | G14: 1502000 | H14: 3.2 | I14: Project Work Orders | J14: 50 | K14: EA
A15: CNRSE | B15: CNRSE ST-FAC | C15: Facility Investment | D15: Preventive Maintenance (PM) Program | E15: C001 | F15: C001AH | G15: 1502000 | H15: 3.3.1 | I15: Airfield Lighting Systems | J15: 12 | K15: MO
A16: CNRSE | B16: CNRSE ST-FAC | C16: Facility Investment | D16: Preventive Maintenance (PM) Program | E16: C001 | F16: C001AJ | G16: 1502000 | H16: 3.3.2 | I16: Auxiliary Generator Systems | J16: 12 | K16: MO
A17: CNRSE | B17: CNRSE ST-FAC | C17: Facility Investment | D17: Preventive Maintenance (PM) Program | E17: C001 | F17: C001AK | G17: 1502000 | H17: 3.3.3 | I17: Boiler and Unfired Pressure Vessel (UPV) Systems | J17: 12 | K17: MO
A18: CNRSE | B18: CNRSE ST-FAC | C18: Facility Investment | D18: Preventive Maintenance (PM) Program | E18: C001 | F18: C001AL | G18: 1502000 | H18: 3.3.4 | I18: Compressed Air Systems | J18: 12 | K18: MO
A19: CNRSE | B19: CNRSE ST-FAC | C19: Facility Investment | D19: Preventive Maintenance (PM) Program | E19: C001 | F19: C001AM | G19: 1502000 | H19: 3.3.5 | I19: Door and Gate Systems | J19: 12 | K19: MO
A20: CNRSE | B20: CNRSE ST-FAC | C20: Facility Investment | D20: Preventive Maintenance (PM) Program | E20: C001 | F20: C001AN | G20: 1502000 | H20: 3.3.6 | I20: Fire Protection Systems | J20: 12 | K20: MO
A21: CNRSE | B21: CNRSE ST-FAC | C21: Facility Investment | D21: Preventive Maintenance (PM) Program | E21: C001 | F21: C001AP | G21: 1502000 | H21: 3.3.7 | I21: Frequency Converter (400 HZ) Systems | J21: 12 | K21: MO
A22: CNRSE | B22: CNRSE ST-FAC | C22: Facility Investment | D22: Preventive Maintenance (PM) Program | E22: C001 | F22: C001AQ | G22: 1502000 | H22: 3.3.8 | I22: Galley Equipment and Systems | J22: 12 | K22: MO
A23: CNRSE | B23: CNRSE ST-FAC | C23: Facility Investment | D23: Preventive Maintenance (PM) Program | E23: C001 | F23: C001AR | G23: 1502000 | H23: 3.3.9 | I23: HVAC and Refrigeration Systems | J23: 12 | K23: MO
A24: CNRSE | B24: CNRSE ST-FAC | C24: Facility Investment | D24: Preventive Maintenance (PM) Program | E24: C001 | F24: C001AS | G24: 1502000 | H24: 3.3.10 | I24: Security Systems and Equipment | J24: 12 | K24: MO
A25: CNRSE | B25: CNRSE ST-FAC | C25: Facility Investment | D25: Preventive Maintenance (PM) Program | E25: C001 | F25: C001AT | G25: 1502000 | H25: 3.3.11 | I25: Uninterruptible Power Supplies (UPS) | J25: 12 | K25: MO
A26: CNRSE | B26: CNRSE ST-FAC | C26: Facility Investment | D26: Preventive Maintenance (PM) Program | E26: C001 | F26: C001AU | G26: 1502000 | H26: 3.3.12 | I26: Vertical Transportation Equipment (VTE) | J26: 12 | K26: MO
... A42: CNRSE | B42: CNRSE ST-FAC | C42: Facility Investment | D42: Other Recurring Services Program | E42: C001 | F42: C001BL | G42: 1502000 | H42: 3.5.11 | I42: Spot Coolers | J42: 12 | K42: MO
A43: CNRSE | B43: CNRSE ST-FAC | C43: Facility Investment | D43: Other (Swimming Pools) | E43: C001 | F43: C001BM | G43: 1503040 | H43: 3.1 | I43: Pool Operator Maintenance | J43: 12 | K43: MO
A44: CNRSE | B44: CNRSE ST-FAC | C44: Facility Investment | D44: Other (Swimming Pools) | E44: C001 | F44: C001BN | G44: 1503040 | H44: 3.2 | I44: Preventive Maintenance (PM) Program | J44: 12 | K44: MO
A45: CNRSE | B45: CNRSE FX | C45: Facility Investment | D45: Other (Swimming Pools) | E45: C001 | F45: C001BP | G45: 1503040 | H45: 3.3 | I45: Water Treatment | J45: 12 | K45: MO
A46: CNRSE | B46: CNRSE UT | C46: Utilities Management | D46: Utility Operations Support | E46: C001 | F46: C001BQ | G46: 1601000 | H46: 3.1 | I46: Utility Operations Support | J46: 12 | K46: MO
A47: CNRSE | B47: CNRSE UT | C47: Utilities Management | D47: Recurring Work | E47: C001 | F47: C001BR | G47: 1601000 | H47: 3.2 | I47: Utility Infrastructure Condition Assessment Program (UICAP) Support | J47: 12 | K47: MO
A48: CNRSE | B48: CNRSE UT | C48: Utilities Management | D48: Recurring Work | E48: C001 | F48: C001BS | G48: 1601000 | H48: 3.3 | I48: Operation and Management of Facility Related Control Systems (FRCS) | J48: 12 | K48: MO
A49: CNRSE | B49: CNRSE UT | C49: Utilities Management | D49: Recurring Work | E49: C001 | F49: C001BT | G49: 1601000 | H49: 3.4 | I49: NAVFAC Maximo Data Entry | J49: 12 | K49: MO
A50: CNRSE | B50: CNRSE UT | C50: Electrical | D50: Recurring Work | E50: C001 | F50: C001BU | G50: 1602000 | H50: 3.1 | I50: Operate Electrical Power Transmission and Distribution Systems | J50: 12 | K50: MO
A51: CNRSE | B51: CNRSE ST | C51: Electrical | D51: E/U/R Work Orders | E51: C001 | F51: C001BV | G51: 1602000 | H51: 3.2 | I51: Emergency, Urgent and Routine (E/U/R) Work | J51: 220 | K51: EA
A52: CNRSE | B52: CNRSE ST | C52: Electrical | D52: Recurring Work | E52: C001 | F52: C001BW | G52: 1602000 | H52: 3.3 | I52: Preventive Maintenance (PM) Program | J52: 12 | K52: MO
A53: CNRSE | B53: CNRSE UT | C53: Electrical | D53: Other Recurring Services Program | E53: C001 | F53: C001BX | G53: 1602000 | H53: 3.4 | I53: Other Recurring Services | J53: 12 | K53: MO
A54: CNRSE | B54: CNRSE UT | C54: Electrical | D54: Other Recurring Services Program | E54: C001 | F54: C001BY | G54: 1602000 | H54: 3.5 | I54: Utility Right of Way Clearance | J54: 12 | K54: MO
A55: CNRSE | B55: CNRSE TR | C55: Transportation | D55: Operations | E55: C001 | F55: C001BZ | G55: 1700000 | H55: 3.1.1 | I55: WHE/MHE/NTVE Services | J55: 12 | K55: MO
...

Sheet CLIN 0008 2nd Period Opt N-RW
B1: Attachment J-0200000-17
B2: Exhibit Line Item Numbers - NAVSTA Mayport
B3: Contract No.: N6945025R0003
B5: CLIN 0008 - Non-Recurring Work - Option Period 2
B6: Provide Prices for Recurring Work in accordance with Section C, Spec Item 4
B7: ELINs C700 through C718
A8: ELIN | B8: Product Name (120 Characters) | C8: Description Extended | D8: Estimated Quantity | E8: Unit of Measure | F8: Unit Price | G8: Extended Price
A9: C700 | B9: Unit Priced Labor Hour Work - MUST BE NEGOTIATED BY KO. | C9: The Contractor shall perform all UPL work in accordance with the scope and delivery schedule negotiated per each task order. Refer to: Section C, Annex 0200000 Managmenent and Administration, Specification Item 2.15.2 Unit Priced Labor (UPL)Work (Negotiated) for description of UPL Work. Refer to: Section J, Annex 0200000 Managmenent and Administration, Attachment J-0200000-01 Definitions and Acronyms for description of Unit Priced Labor (UPL) Hour and Universal Equipment. Task order completion times will be specified on each task order. For self-performed work: the unit price proposed for Sub-ELIN C700AA will be used to determine the labor cost to the Governent. For subcontracted labor: the FBR proposed for Sub-ELIN C700AB will be used to determine the labor cost to the Governmnet. The estimated quantity of each Sub-ELIN is used to establish the ELIN Extended Price. During administration the labor Sub-ELINs may be used in any combination and quantity provided the ELIN extended price is not exceeded. The contract will not be modified to re-allocate capacity among labor SLINs. | D9: =G10+G11 -> 0 | E9: DO | F9: 1
A10: C700AA | B10: Self-Performed Unit Priced Labor Hour Work - MUST BE NEGOTIATED BY KO. | C10: The Contractor shall self-perform all UPL work in accordance with the scope and delivery schedule negotiated per each task order. Refer to: Section C, Annex 0200000 Managmenent and Administration, Specification Item 2.15.2 Unit Priced Labor (UPL)Work (Negotiated) for description of UPL Work. Refer to: Section J, Annex 0200000 Managmenent and Administration, Attachment J-0200000-01 Definitions and Acronyms for description of Unit Priced Labor (UPL) Hour and Universal Equipment. | D10: ='CLIN 0002 Base Period N-RW'!D10 -> 16000 | E10: LH
A11: C700AB | B11: Subcontractor Labor (Fixed Burden Rate) - MUST BE NEGOTIATED BY KO. | C11: The Contractor shall perform management and oversight of subcontracted non-recurring work in accordance with the scope and delivery schedule negotiated per each task order. Refer to: Section C, Annex 0200000 Management and Administration, Specification Item 2.15.2.1.2 Subcontractor Requirements description of Sub. Refer to: Section J, Annex 0200000 Management and Administration, Attachment J-0200000-01 Definitions and Acronyms for definition of Sub-Contractor Fixed Burden Rate. The estimated quantity (in dollars) is provided. A Fixed Burdened Rate (FBR) shall be entered in the Unit Price column. The FBR shall include all direct and indirect factors for management and oversight of subcontracted non-recurring work. Similar to FBR example in J-0200000-01, if a 15% markup is the Contractor's proposed FBR, the Unit Price should be $1.15. During performance, if the lowest subcontractor labor proposal is $1,000.00 and the FBR is $1.15, the labor cost to the Government will be $1,150.00. (DO - Dollars). | D11: ='CLIN 0002 Base Period N-RW'!D11 -> 1600000 | E11: DO
A12: C701 | B12: Material and Equipment - MUST BE NEGOTIATED BY KO. | C12: Provide all materials and construction equipment to perform Unit Priced Labor work per the scope and delivery schedule specified in the order. Pre-expended bin supplies and materials will not be included in the list of materials since the cost for these items were included in the labor hour unit price bid. Material prices provided by the Contractor shall be the lowest price available considering the availability of materials and the time constraints of the job. The direct material price shall be adjusted by all discounts and rebates for core value or salvage value that accrue to the Contractor. Contractor owned equipment rental rates shall be based on calculations set forth in US Army Corp of Engineers “Construction Equipment Ownership and Operating Expense Schedule (EP 1110-1-8 (Vol. 11) July 03 or latest revision) Chapter 2. The estitmate quantity (in dollars) is provided. A Fixed burdened rate (FBR) shall be entered in the Unit Price column. The FBR shall include factors for ordering, handling, and stockpiling materials and repair parts. Similar to FBR example in J-0200000-01, if a 10% markup is the Contractor's proposed FBR, the Unit Price should be $1.10. When multiplying the proposed Unit Price by the Estimated Quantity, the Extended Price should be During administration, if the vendor's invoice on material is $1,000.00 and the unit price is $1.10, the cost of the material to the government will be $1,050.00. (DO - Dollars) | D12: 2000000 | E12: DO
A13: C702 | B13: Category I Calls - MUST BE NEGOTIATED BY KO. | C13: The Contractor shall perform Category I Calls to accomplish any work identified within the entire boundary of the installation and will include a wide variety of work. Category I Calls shall be completed within two weeks of receipt of call order, unless otherwise agreed to by the customer and contractor and annotated on the CAT call request. As part of the Category I Call, the Contractor has full responsibility for any work identified up to the Category I Call Threshold of $5,000 in direct labor and direct material, per Category I Call. A Blanket Task Order (BTO) may be issued on a DD Form 1155 with a Not To Exceed (NTE) quantity and value for Non-recurring Work Category Calls. | D13: 115 | E13: EA
A14: C703 | B14: Category II Calls - MUST BE NEGOTIATED BY KO. | C14: The Contractor shall perform Category II Calls to accomplish any work identified within the entire boundary of the installation and will include a wide variety of work. Category II Calls shall be completed within three weeks of receipt of call order, unless otherwise agreed to by the customer and contractor and annotated on the CAT call request. As part of the Category II Call, the Contractor has full responsibility for any work identified up to the Category II Call Threshold of $7,500 in direct labor and direct material, per Category II Call. A Blanket Task Order (BTO) may be issued on a DD Form 1155 with a Not To Exceed (NTE) quantity and value for Non-recurring Work Category Calls. | D14: 130 | E14: EA
A15: C704 | B15: Category III Calls - MUST BE NEGOTIATED BY KO. | C15: The Contractor shall perform Category III Calls to accomplish any work identified within the entire boundary of the installation and will include a wide variety of work. Category III Calls shall be completed within 30 days of receipt of call order, unless otherwise agreed to by the customer and contractor and annotated on the CAT call request. As part of the Category III Call, the Contractor has full responsibility for any work identified up to the Category III Call Threshold of $10,000 in direct labor and direct material, per Category III Call. A Blanket Task Order (BTO) may be issued on a DD Form 1155 with a Not To Exceed (NTE) quantity and value for Non-recurring Work Category Calls. | D15: 95 | E15: EA
A16: C705 | B16: Category IV Calls - MUST BE NEGOTIATED BY KO. | C16: The Contractor shall perform Category IV Calls to accomplish any work identified within the entire boundary of the installation and will include a wide variety of work. Category IV Calls shall be completed within 30 days of receipt of call order, unless otherwise agreed to by the customer and contractor and annotated on the CAT call request. As part of the Category IV Call, the Contractor has full responsibility for any work identified up to the Category IV Call Threshold of $12,500 in direct labor and direct material, per Category IV Call. A Blanket Task Order (BTO) may be issued on a DD Form 1155 with a Not To Exceed (NTE) quantity and value for Non-recurring Work Category Calls. | D16: 50 | E16: EA
A17: C706 | B17: Category V Calls - MUST BE NEGOTIATED BY KO. | C17: The Contractor shall perform Category V Calls to accomplish any work identified within the entire boundary of the installation and will include a wide variety of work. Category V Calls shall be completed within 30 days of receipt of call order, unless otherwise agreed to by the customer and contractor and annotated on the CAT call request. As part of the Category V Call, the Contractor has full responsibility for any work identified up to the Category V Call Threshold of $15,000 in direct labor and direct material, per Category V Call. A Blanket Task Order (BTO) may be issued on a DD Form 1155 with a Not To Exceed (NTE) quantity and value for Non-recurring Work Category Calls. | D17: 40 | E17: EA
